Workbook

Sheet AUM
A1: Date | B1: Total AUM | C1: #Accts | D1: MTD +/- | E1: YTD +/-
A2: 41274 | B2: ='Strategy&Account'!B2 -> 16097798 | C2: ='Strategy&Account'!C2 -> 2 | E2: =B2 -> 16097798
A3: 41305 | B3: ='Strategy&Account'!B3 -> 20591061 | C3: ='Strategy&Account'!C3 -> 2 | D3: =B3-B2 -> 4493263.1
A4: 41333 | B4: ='Strategy&Account'!B4 -> 25153160 | C4: ='Strategy&Account'!C4 -> 2 | D4: =B4-B3 -> 4562099.5
A5: 41364 | B5: ='Strategy&Account'!B5 -> 31870607 | C5: ='Strategy&Account'!C5 -> 2 | D5: =B5-B4 -> 6717447
A6: 41394 | B6: ='Strategy&Account'!B6 -> 43261752 | C6: ='Strategy&Account'!C6 -> 2 | D6: =B6-B5 -> 11391145
A7: 41425 | B7: ='Strategy&Account'!B7 -> 53175554 | C7: ='Strategy&Account'!C7 -> 2 | D7: =B7-B6 -> 9913801.9
A8: 41455 | B8: ='Strategy&Account'!B8 -> 59663773 | C8: ='Strategy&Account'!C8 -> 2 | D8: =B8-B7 -> 6488219.3
A9: 41486 | B9: ='Strategy&Account'!B9 -> 74569204 | C9: ='Strategy&Account'!C9 -> 2 | D9: =B9-B8 -> 14905430
A10: 41517 | B10: ='Strategy&Account'!B10 -> 85315152 | C10: ='Strategy&Account'!C10 -> 264 | D10: =B10-B9 -> 10745948
A11: 41547 | B11: ='Strategy&Account'!B11 -> 97529992 | C11: ='Strategy&Account'!C11 -> 301 | D11: =B11-B10 -> 12214840
A12: 41578 | B12: ='Strategy&Account'!B12 -> 1.1223885e+08 | C12: ='Strategy&Account'!C12 -> 361 | D12: =B12-B11 -> 14708854
A13: 41608 | B13: ='Strategy&Account'!B13 -> 1.2427645e+08 | C13: ='Strategy&Account'!C13 -> 398 | D13: =B13-B12 -> 12037600
A14: 41639 | B14: ='Strategy&Account'!B14 -> 1.3471577e+08 | C14: ='Strategy&Account'!C14 -> 439 | D14: =B14-B13 -> 10439320 | E14: =B14-B2 -> 1.1861797e+08
A15: 41670 | B15: ='Strategy&Account'!B15 -> 1.3781396e+08 | C15: ='Strategy&Account'!C15 -> 478 | D15: =B15-B14 -> 3098194.6
A16: 41698 | B16: ='Strategy&Account'!B16 -> 1.4693008e+08 | C16: ='Strategy&Account'!C16 -> 499 | D16: =B16-B15 -> 9116121
A17: 41729 | B17: ='Strategy&Account'!B17 -> 1.5554248e+08 | C17: ='Strategy&Account'!C17 -> 514 | D17: =B17-B16 -> 8612395.8
A18: 41759 | B18: ='Strategy&Account'!B18 -> 1.6240997e+08 | C18: ='Strategy&Account'!C18 -> 521 | D18: =B18-B17 -> 6867493.8
A19: 41790 | B19: ='Strategy&Account'!B19 -> 1.677813e+08 | C19: ='Strategy&Account'!C19 -> 566 | D19: =B19-B18 -> 5371334.1
A20: 41820 | B20: ='Strategy&Account'!B20 -> 1.7451183e+08 | C20: ='Strategy&Account'!C20 -> 584 | D20: =B20-B19 -> 6730526.1
A21: 41851 | B21: ='Strategy&Account'!B21 -> 1.768834e+08 | C21: ='Strategy&Account'!C21 -> 605 | D21: =B21-B20 -> 2371566.1
A22: 41882 | B22: ='Strategy&Account'!B22 -> 1.8671688e+08 | C22: ='Strategy&Account'!C22 -> 619 | D22: =B22-B$21 -> 9833482.6
A23: 41912 | B23: ='Strategy&Account'!B23 -> 1.8719638e+08 | C23: ='Strategy&Account'!C23 -> 632 | D23: =B23-B$22 -> 479495.48
A24: 41943 | B24: ='Strategy&Account'!B24 -> 1.984258e+08 | C24: ='Strategy&Account'!C24 -> 656 | D24: =B24-B$23 -> 11229423
A25: 41973 | B25: ='Strategy&Account'!B25 -> 2.1542342e+08 | C25: ='Strategy&Account'!C25 -> 670 | D25: =B25-B$24 -> 16997627
A26: 42004 | B26: ='Strategy&Account'!B26 -> 2.2268911e+08 | C26: ='Strategy&Account'!C26 -> 660 | D26: =B26-B$25 -> 7265681.8 | E26: =B26-B14 -> 87973341
A27: 42035 | B27: ='Strategy&Account'!B27 -> 2.3063648e+08 | C27: ='Strategy&Account'!C27 -> 697 | D27: =B27-B$26 -> 7947376.2
A28: 42063 | B28: ='Strategy&Account'!B28 -> 2.4880608e+08 | C28: ='Strategy&Account'!C28 -> 716 | D28: =B28-B$27 -> 18169596
A29: 42094 | B29: ='Strategy&Account'!B29 -> 2.6056483e+08 | C29: ='Strategy&Account'!C29 -> 743 | D29: =B29-B$28 -> 11758756
A30: 42124 | B30: ='Strategy&Account'!B30 -> 2.7059347e+08 | C30: ='Strategy&Account'!C30 -> 764 | D30: =B30-B$29 -> 10028634
A31: 42155 | B31: ='Strategy&Account'!B31 -> 2.8375676e+08 | C31: ='Strategy&Account'!C31 -> 765 | D31: =B31-B$30 -> 13163290
A32: 42185 | B32: ='Strategy&Account'!B32 -> 2.7979975e+08 | C32: ='Strategy&Account'!C32 -> 783 | D32: =B32-B$31 -> -3957004.1
A33: 42216 | B33: ='Strategy&Account'!B33 -> 3.0558192e+08 | C33: ='Strategy&Account'!C33 -> 795 | D33: =B33-B$32 -> 25782167
A34: 42247 | B34: ='Strategy&Account'!B34 -> 2.9712704e+08 | C34: ='Strategy&Account'!C34 -> 806 | D34: =B34-B$33 -> -8454884.5
A35: 42277 | B35: ='Strategy&Account'!B35 -> 3.0023612e+08 | C35: ='Strategy&Account'!C35 -> 810 | D35: =B35-B$34 -> 3109085.1
A36: 42308 | B36: ='Strategy&Account'!B36 -> 3.3097015e+08 | C36: ='Strategy&Account'!C36 -> 822 | D36: =B36-B$35 -> 30734031
A37: 42338 | B37: ='Strategy&Account'!B37 -> 3.3180873e+08 | C37: ='Strategy&Account'!C37 -> 812 | D37: =B37-B$36 -> 838577.69
A38: 42369 | B38: ='Strategy&Account'!B38 -> 3.3229184e+08 | C38: ='Strategy&Account'!C38 -> 807 | D38: =B38-B$37 -> 483112.53 | E38: =B38-B26 -> 1.0960274e+08
A39: 42400 | B39: ='Strategy&Account'!B39 -> 3.9631938e+08 | C39: ='Strategy&Account'!C39 -> 798 | D39: =B39-B$38 -> 64027538
A40: 42429 | B40: ='Strategy&Account'!B40 -> 4.3188242e+08 | C40: ='Strategy&Account'!C40 -> 796 | D40: =B40-B$39 -> 35563042
...

Sheet Strategy&Account
A1: Date | B1: Total AUM | C1: Accts | D1: Large Cap | E1: Accts | F1: Small Cap | G1: Accts | H1: Global | I1: Accts | J1: AA | K1: Accts | L1: Other | M1: Accts | O1: SILVX | P1: Accts | Q1: SGLIX | R1: Accts | S1: BOGIX | T1: Accts | U1: Funds of Funds | V1: Accts | W1: DYTA | X1: Accts | Y1: SGLC | Z1: Accts | AA1: GINX | AB1: Accts | AC1: USDX | AD1: Accts | AE1: QXQ | AF1: Accts | AG1: LDRX | AH1: Accts | AI1: Timpanogos | AJ1: Accts | AK1: Interactive Brokers | AL1: Accts | AM1: Schwab | AN1: Accts | AO1: Fidelity | AP1: Accts | AQ1: Empower | AR1: Accts | AS1: Betterment | AT1: Accts | AU1: GPB Capital | AV1: Accts | AW1: GS-Folio | AX1: Accts | AY1: ePlan | AZ1: Accts | BA1: TFA USLV | BB1: Accts | BC1: TFA CLV | BD1: Accts | BE1: TFA Tactical | BG1: UNC LC | BH1: Accts | BI1: Schwab LC | BJ1: Accts | BK1: American Funds | BL1: Accts | BM1: Empower 401k | BN1: Accts | BO1: Human Interest | BP1: Accts | BQ1: Paychex | BR1: Accts | BS1: Transamerica401k | BT1: Accts | BU1: Ascensus | BV1: Accts | BW1: Matrix/Mid-Atlantic | BX1: Accts | BY1: Nationwide | BZ1: Accts | CA1: TIAA | CB1: Accts | CC1: Fidelity Workplace Investing | CD1: Accts | CE1: Jackson | CF1: Accts | CG1: Betterment 401k | CH1: Accts | CI1: NC State | CJ1: Accts | CK1: Holiday Oil | CL1: Accts | CM1: SCLVX | CN1: Accts | CO1: Stifel | CP1: Accts | CQ1: TDA | CR1: Accts | CS1: UNC SC | CT1: Accts | CU1: Asbestos Workers | CV1: Accts | CW1: TUG | CX1: Accts | CY1: Cline | CZ1: Accts | DA1: Prudential | DB1: Accts | DC1: LACERA | DD1: Accts | DE1: Folio | DF1: Accts | DG1: Vanguard | DH1: Accts
A2: 41274 | B2: =O2+CM2+Q2+AM2+CQ2+AO2+DA2+BA2+BC2+CO2+BG2+CS2+BI2+CY2+CK2+DC2+DE2 -> 16097798 | C2: =P2+CN2+R2+AN2+CR2+AP2+DB2+BB2+BD2+CP2+BH2+CT2+BJ2+CZ2+CL2+DD2+DF2 -> 2 | D2: =O2+BA2+CO2+BG2+BI2+DC2 -> 15737148 | E2: =P2+BB2+CP2+BH2+BJ2+DD2 -> 2 | F2: =CM2+CS2 -> 0 | H2: =Q2+CY2 -> 0 | J2: =AM2+CQ2+AO2+DA2 -> 360649.55 | K2: =AN2+CR2+AP2+DB2 -> 0 | L2: =BC2+CK2+DE2 -> 0 | O2: =SILVX!B9 -> 9486552.3 | P2: =SILVX!G9 -> 1 | AO2: =Fidelity!P2 -> 360649.55 | AP2: =Fidelity!O2 -> 0 | BA2: ='TFA - Folio'!H7 -> 6250596 | BB2: ='TFA - Folio'!I2 -> 1
A3: 41305 | B3: =O3+CM3+Q3+AM3+CQ3+AO3+DA3+BA3+BC3+CO3+BG3+CS3+BI3+CY3+CK3+DC3+DE3 -> 20591061 | C3: =P3+CN3+R3+AN3+CR3+AP3+DB3+BB3+BD3+CP3+BH3+CT3+BJ3+CZ3+CL3+DD3+DF3 -> 2 | D3: =O3+BA3+CO3+BG3+BI3+DC3 -> 19854280 | E3: =P3+BB3+CP3+BH3+BJ3+DD3 -> 2 | F3: =CM3+CS3 -> 0 | H3: =Q3+CY3 -> 0 | J3: =AM3+CQ3+AO3+DA3 -> 736781.34 | K3: =AN3+CR3+AP3+DB3 -> 0 | L3: =BC3+CK3+DE3 -> 0 | O3: =SILVX!B10 -> 10810338 | P3: =SILVX!G10 -> 1 | AO3: =Fidelity!P3 -> 736781.34 | AP3: =Fidelity!O3 -> 0 | BA3: ='TFA - Folio'!H8 -> 9043941.1 | BB3: ='TFA - Folio'!I3 -> 1
A4: 41333 | B4: =O4+CM4+Q4+AM4+CQ4+AO4+DA4+BA4+BC4+CO4+BG4+CS4+BI4+CY4+CK4+DC4+DE4 -> 25153160 | C4: =P4+CN4+R4+AN4+CR4+AP4+DB4+BB4+BD4+CP4+BH4+CT4+BJ4+CZ4+CL4+DD4+DF4 -> 2 | D4: =O4+BA4+CO4+BG4+BI4+DC4 -> 24387901 | E4: =P4+BB4+CP4+BH4+BJ4+DD4 -> 2 | F4: =CM4+CS4 -> 0 | H4: =Q4+CY4 -> 0 | J4: =AM4+CQ4+AO4+DA4 -> 765259.8 | K4: =AN4+CR4+AP4+DB4 -> 0 | L4: =BC4+CK4+DE4 -> 0 | O4: =SILVX!B11 -> 11771288 | P4: =SILVX!G11 -> 1 | AO4: =Fidelity!P4 -> 765259.8 | AP4: =Fidelity!O4 -> 0 | BA4: ='TFA - Folio'!H9 -> 12616613 | BB4: ='TFA - Folio'!I4 -> 1
A5: 41364 | B5: =O5+CM5+Q5+AM5+CQ5+AO5+DA5+BA5+BC5+CO5+BG5+CS5+BI5+CY5+CK5+DC5+DE5 -> 31870607 | C5: =P5+CN5+R5+AN5+CR5+AP5+DB5+BB5+BD5+CP5+BH5+CT5+BJ5+CZ5+CL5+DD5+DF5 -> 2 | D5: =O5+BA5+CO5+BG5+BI5+DC5 -> 31059851 | E5: =P5+BB5+CP5+BH5+BJ5+DD5 -> 2 | F5: =CM5+CS5 -> 0 | H5: =Q5+CY5 -> 0 | J5: =AM5+CQ5+AO5+DA5 -> 810756.3 | K5: =AN5+CR5+AP5+DB5 -> 0 | L5: =BC5+CK5+DE5 -> 0 | O5: =SILVX!B12 -> 13089271 | P5: =SILVX!G12 -> 1 | AO5: =Fidelity!P5 -> 810756.3 | AP5: =Fidelity!O5 -> 0 | BA5: ='TFA - Folio'!H10 -> 17970580 | BB5: ='TFA - Folio'!I5 -> 1
A6: 41394 | B6: =O6+CM6+Q6+AM6+CQ6+AO6+DA6+BA6+BC6+CO6+BG6+CS6+BI6+CY6+CK6+DC6+DE6 -> 43261752 | C6: =P6+CN6+R6+AN6+CR6+AP6+DB6+BB6+BD6+CP6+BH6+CT6+BJ6+CZ6+CL6+DD6+DF6 -> 2 | D6: =O6+BA6+CO6+BG6+BI6+DC6 -> 42436074 | E6: =P6+BB6+CP6+BH6+BJ6+DD6 -> 2 | F6: =CM6+CS6 -> 0 | H6: =Q6+CY6 -> 0 | J6: =AM6+CQ6+AO6+DA6 -> 825678.33 | K6: =AN6+CR6+AP6+DB6 -> 0 | L6: =BC6+CK6+DE6 -> 0 | O6: =SILVX!B13 -> 16958369 | P6: =SILVX!G13 -> 1 | AO6: =Fidelity!P6 -> 825678.33 | AP6: =Fidelity!O6 -> 0 | BA6: ='TFA - Folio'!H11 -> 25477705 | BB6: ='TFA - Folio'!I6 -> 1
A7: 41425 | B7: =O7+CM7+Q7+AM7+CQ7+AO7+DA7+BA7+BC7+CO7+BG7+CS7+BI7+CY7+CK7+DC7+DE7 -> 53175554 | C7: =P7+CN7+R7+AN7+CR7+AP7+DB7+BB7+BD7+CP7+BH7+CT7+BJ7+CZ7+CL7+DD7+DF7 -> 2 | D7: =O7+BA7+CO7+BG7+BI7+DC7 -> 50925776 | E7: =P7+BB7+CP7+BH7+BJ7+DD7 -> 2 | F7: =CM7+CS7 -> 0 | H7: =Q7+CY7 -> 0 | J7: =AM7+CQ7+AO7+DA7 -> 2249778 | K7: =AN7+CR7+AP7+DB7 -> 0 | L7: =BC7+CK7+DE7 -> 0 | O7: =SILVX!B14 -> 17899655 | P7: =SILVX!G14 -> 1 | AM7: =Schwab!S2 -> 1398649.8 | AN7: =Schwab!Q2 -> 0 | AO7: =Fidelity!P7 -> 851128.19 | AP7: =Fidelity!O7 -> 0 | BA7: ='TFA - Folio'!H12 -> 33026121 | BB7: ='TFA - Folio'!I7 -> 1
A8: 41455 | B8: =O8+CM8+Q8+AM8+CQ8+AO8+DA8+BA8+BC8+CO8+BG8+CS8+BI8+CY8+CK8+DC8+DE8 -> 59663773 | C8: =P8+CN8+R8+AN8+CR8+AP8+DB8+BB8+BD8+CP8+BH8+CT8+BJ8+CZ8+CL8+DD8+DF8 -> 2 | D8: =O8+BA8+CO8+BG8+BI8+DC8 -> 56450118 | E8: =P8+BB8+CP8+BH8+BJ8+DD8 -> 2 | F8: =CM8+CS8 -> 0 | H8: =Q8+CY8 -> 0 | J8: =AM8+CQ8+AO8+DA8 -> 3213655.1 | K8: =AN8+CR8+AP8+DB8 -> 0 | L8: =BC8+CK8+DE8 -> 0 | O8: =SILVX!B15 -> 18417136 | P8: =SILVX!G15 -> 1 | AM8: =Schwab!S3 -> 2362526.9 | AN8: =Schwab!Q3 -> 0 | AO8: =Fidelity!P8 -> 851128.19 | AP8: =Fidelity!O8 -> 0 | BA8: ='TFA - Folio'!H13 -> 38032982 | BB8: ='TFA - Folio'!I8 -> 1
A9: 41486 | B9: =O9+CM9+Q9+AM9+CQ9+AO9+DA9+BA9+BC9+CO9+BG9+CS9+BI9+CY9+CK9+DC9+DE9 -> 74569204 | C9: =P9+CN9+R9+AN9+CR9+AP9+DB9+BB9+BD9+CP9+BH9+CT9+BJ9+CZ9+CL9+DD9+DF9 -> 2 | D9: =O9+BA9+CO9+BG9+BI9+DC9 -> 66850098 | E9: =P9+BB9+CP9+BH9+BJ9+DD9 -> 2 | F9: =CM9+CS9 -> 0 | H9: =Q9+CY9 -> 0 | J9: =AM9+CQ9+AO9+DA9 -> 7719105.8 | K9: =AN9+CR9+AP9+DB9 -> 0 | L9: =BC9+CK9+DE9 -> 0 | O9: =SILVX!B16 -> 23781673 | P9: =SILVX!G16 -> 1 | AM9: =Schwab!S4 -> 6867977.6 | AN9: =Schwab!Q4 -> 0 | AO9: =Fidelity!P9 -> 851128.19 | AP9: =Fidelity!O9 -> 0 | BA9: ='TFA - Folio'!H14 -> 43068425 | BB9: ='TFA - Folio'!I9 -> 1
A10: 41517 | B10: =O10+CM10+Q10+AM10+CQ10+AO10+DA10+BA10+BC10+CO10+BG10+CS10+BI10+CY10+CK10+DC10+DE10 -> 85315152 | C10: =P10+CN10+R10+AN10+CR10+AP10+DB10+BB10+BD10+CP10+BH10+CT10+BJ10+CZ10+CL10+DD10+DF10 -> 264 | D10: =O10+BA10+CO10+BG10+BI10+DC10 -> 74606688 | E10: =P10+BB10+CP10+BH10+BJ10+DD10 -> 2 | F10: =CM10+CS10 -> 0 | H10: =Q10+CY10 -> 0 | J10: =AM10+CQ10+AO10+DA10 -> 10708464 | K10: =AN10+CR10+AP10+DB10 -> 262 | L10: =BC10+CK10+DE10 -> 0 | O10: =SILVX!B17 -> 25620949 | P10: =SILVX!G17 -> 1 | AM10: =Schwab!S5 -> 9857335.7 | AN10: =Schwab!Q5 -> 262 | AO10: =Fidelity!P10 -> 851128.19 | AP10: =Fidelity!O10 -> 0 | BA10: ='TFA - Folio'!H15 -> 48985739 | BB10: ='TFA - Folio'!I10 -> 1
A11: 41547 | B11: =O11+CM11+Q11+AM11+CQ11+AO11+DA11+BA11+BC11+CO11+BG11+CS11+BI11+CY11+CK11+DC11+DE11 -> 97529992 | C11: =P11+CN11+R11+AN11+CR11+AP11+DB11+BB11+BD11+CP11+BH11+CT11+BJ11+CZ11+CL11+DD11+DF11 -> 301 | D11: =O11+BA11+CO11+BG11+BI11+DC11 -> 85851808 | E11: =P11+BB11+CP11+BH11+BJ11+DD11 -> 2 | F11: =CM11+CS11 -> 0 | H11: =Q11+CY11 -> 0 | J11: =AM11+CQ11+AO11+DA11 -> 11678184 | K11: =AN11+CR11+AP11+DB11 -> 299 | L11: =BC11+CK11+DE11 -> 0 | O11: =SILVX!B18 -> 30750157 | P11: =SILVX!G18 -> 1 | AM11: =Schwab!S6 -> 10474450 | AN11: =Schwab!Q6 -> 299 | AO11: =Fidelity!P11 -> 1203734.2 | AP11: =Fidelity!O11 -> 0 | BA11: ='TFA - Folio'!H16 -> 55101650 | BB11: ='TFA - Folio'!I11 -> 1
A12: 41578 | B12: =O12+CM12+Q12+AM12+CQ12+AO12+DA12+BA12+BC12+CO12+BG12+CS12+BI12+CY12+CK12+DC12+DE12 -> 1.1223885e+08 | C12: =P12+CN12+R12+AN12+CR12+AP12+DB12+BB12+BD12+CP12+BH12+CT12+BJ12+CZ12+CL12+DD12+DF12 -> 361 | D12: =O12+BA12+CO12+BG12+BI12+DC12 -> 98338071 | E12: =P12+BB12+CP12+BH12+BJ12+DD12 -> 2 | F12: =CM12+CS12 -> 0 | H12: =Q12+CY12 -> 0 | J12: =AM12+CQ12+AO12+DA12 -> 13900775 | K12: =AN12+CR12+AP12+DB12 -> 359 | L12: =BC12+CK12+DE12 -> 0 | O12: =SILVX!B19 -> 34983487 | P12: =SILVX!G19 -> 1 | AM12: =Schwab!S7 -> 12624431 | AN12: =Schwab!Q7 -> 358 | AO12: =Fidelity!P12 -> 1247725.3 | AP12: =Fidelity!O12 -> 0 | BA12: ='TFA - Folio'!H17 -> 63354584 | BB12: ='TFA - Folio'!I12 -> 1 | CQ12: =TDA!O2 -> 28618.9 | CR12: =TDA!N2 -> 1
A13: 41608 | B13: =O13+CM13+Q13+AM13+CQ13+AO13+DA13+BA13+BC13+CO13+BG13+CS13+BI13+CY13+CK13+DC13+DE13 -> 1.2427645e+08 | C13: =P13+CN13+R13+AN13+CR13+AP13+DB13+BB13+BD13+CP13+BH13+CT13+BJ13+CZ13+CL13+DD13+DF13 -> 398 | D13: =O13+BA13+CO13+BG13+BI13+DC13 -> 1.0879169e+08 | E13: =P13+BB13+CP13+BH13+BJ13+DD13 -> 2 | F13: =CM13+CS13 -> 0 | H13: =Q13+CY13 -> 0 | J13: =AM13+CQ13+AO13+DA13 -> 15484753 | K13: =AN13+CR13+AP13+DB13 -> 396 | L13: =BC13+CK13+DE13 -> 0 | O13: =SILVX!B20 -> 38040703 | P13: =SILVX!G20 -> 1 | AM13: =Schwab!S8 -> 13896473 | AN13: =Schwab!Q8 -> 395 | AO13: =Fidelity!P13 -> 1559660.7 | AP13: =Fidelity!O13 -> 0 | BA13: ='TFA - Folio'!H18 -> 70750990 | BB13: ='TFA - Folio'!I13 -> 1 | CQ13: =TDA!O3 -> 28618.9 | CR13: =TDA!N3 -> 1
A14: 41639 | B14: =O14+CM14+Q14+AM14+CQ14+AO14+DA14+BA14+BC14+CO14+BG14+CS14+BI14+CY14+CK14+DC14+DE14 -> 1.3471577e+08 | C14: =P14+CN14+R14+AN14+CR14+AP14+DB14+BB14+BD14+CP14+BH14+CT14+BJ14+CZ14+CL14+DD14+DF14 -> 439 | D14: =O14+BA14+CO14+BG14+BI14+DC14 -> 1.1750897e+08 | E14: =P14+BB14+CP14+BH14+BJ14+DD14 -> 2 | F14: =CM14+CS14 -> 0 | H14: =Q14+CY14 -> 0 | J14: =AM14+CQ14+AO14+DA14 -> 17206800 | K14: =AN14+CR14+AP14+DB14 -> 437 | L14: =BC14+CK14+DE14 -> 0 | O14: =SILVX!B21 -> 40565492 | P14: =SILVX!G21 -> 1 | AM14: =Schwab!S9 -> 15885894 | AN14: =Schwab!Q9 -> 436 | AO14: =Fidelity!P14 -> 1293301.8 | AP14: =Fidelity!O14 -> 0 | BA14: ='TFA - Folio'!H19 -> 76943473 | BB14: ='TFA - Folio'!I14 -> 1 | CQ14: =TDA!O4 -> 27604.99 | CR14: =TDA!N4 -> 1
A15: 41670 | B15: =O15+CM15+Q15+AM15+CQ15+AO15+DA15+BA15+BC15+CO15+BG15+CS15+BI15+CY15+CK15+DC15+DE15 -> 1.3781396e+08 | C15: =P15+CN15+R15+AN15+CR15+AP15+DB15+BB15+BD15+CP15+BH15+CT15+BJ15+CZ15+CL15+DD15+DF15 -> 478 | D15: =O15+BA15+CO15+BG15+BI15+DC15 -> 1.2258792e+08 | E15: =P15+BB15+CP15+BH15+BJ15+DD15 -> 2 | F15: =CM15+CS15 -> 0 | H15: =Q15+CY15 -> 0 | J15: =AM15+CQ15+AO15+DA15 -> 15226041 | K15: =AN15+CR15+AP15+DB15 -> 476 | L15: =BC15+CK15+DE15 -> 0 | O15: =SILVX!B22 -> 44164273 | P15: =SILVX!G22 -> 1 | AM15: =Schwab!S10 -> 13704419 | AN15: =Schwab!Q10 -> 473 | AO15: =Fidelity!P15 -> 1302130.3 | AP15: =Fidelity!O15 -> 0 | BA15: ='TFA - Folio'!H20 -> 78423646 | BB15: ='TFA - Folio'!I15 -> 1 | CQ15: =TDA!O5 -> 219492.31 | CR15: =TDA!N5 -> 3
A16: 41698 | B16: =O16+CM16+Q16+AM16+CQ16+AO16+DA16+BA16+BC16+CO16+BG16+CS16+BI16+CY16+CK16+DC16+DE16 -> 1.4693008e+08 | C16: =P16+CN16+R16+AN16+CR16+AP16+DB16+BB16+BD16+CP16+BH16+CT16+BJ16+CZ16+CL16+DD16+DF16 -> 499 | D16: =O16+BA16+CO16+BG16+BI16+DC16 -> 1.3129856e+08 | E16: =P16+BB16+CP16+BH16+BJ16+DD16 -> 2 | F16: =CM16+CS16 -> 0 | H16: =Q16+CY16 -> 0 | J16: =AM16+CQ16+AO16+DA16 -> 15631522 | K16: =AN16+CR16+AP16+DB16 -> 497 | L16: =BC16+CK16+DE16 -> 0 | O16: =SILVX!B23 -> 48302398 | P16: =SILVX!G23 -> 1 | AM16: =Schwab!S11 -> 13936786 | AN16: =Schwab!Q11 -> 492 | AO16: =Fidelity!P16 -> 1356520.3 | AP16: =Fidelity!O16 -> 0 | BA16: ='TFA - Folio'!H21 -> 82996161 | BB16: ='TFA - Folio'!I16 -> 1 | CQ16: =TDA!O6 -> 338215.8 | CR16: =TDA!N6 -> 5
A17: 41729 | B17: =O17+CM17+Q17+AM17+CQ17+AO17+DA17+BA17+BC17+CO17+BG17+CS17+BI17+CY17+CK17+DC17+DE17 -> 1.5554248e+08 | C17: =P17+CN17+R17+AN17+CR17+AP17+DB17+BB17+BD17+CP17+BH17+CT17+BJ17+CZ17+CL17+DD17+DF17 -> 514 | D17: =O17+BA17+CO17+BG17+BI17+DC17 -> 1.3979722e+08 | E17: =P17+BB17+CP17+BH17+BJ17+DD17 -> 2 | F17: =CM17+CS17 -> 0 | H17: =Q17+CY17 -> 0 | J17: =AM17+CQ17+AO17+DA17 -> 15745262 | K17: =AN17+CR17+AP17+DB17 -> 512 | L17: =BC17+CK17+DE17 -> 0 | O17: =SILVX!B24 -> 50613401 | P17: =SILVX!G24 -> 1 | AM17: =Schwab!S12 -> 14063159 | AN17: =Schwab!Q12 -> 507 | AO17: =Fidelity!P17 -> 1526939.8 | AP17: =Fidelity!O17 -> 0 | BA17: ='TFA - Folio'!H22 -> 89183815 | BB17: ='TFA - Folio'!I17 -> 1 | CQ17: =TDA!O7 -> 155162.64 | CR17: =TDA!N7 -> 5
A18: 41759 | B18: =O18+CM18+Q18+AM18+CQ18+AO18+DA18+BA18+BC18+CO18+BG18+CS18+BI18+CY18+CK18+DC18+DE18 -> 1.6240997e+08 | C18: =P18+CN18+R18+AN18+CR18+AP18+DB18+BB18+BD18+CP18+BH18+CT18+BJ18+CZ18+CL18+DD18+DF18 -> 521 | D18: =O18+BA18+CO18+BG18+BI18+DC18 -> 1.4557765e+08 | E18: =P18+BB18+CP18+BH18+BJ18+DD18 -> 2 | F18: =CM18+CS18 -> 0 | H18: =Q18+CY18 -> 0 | J18: =AM18+CQ18+AO18+DA18 -> 16832319 | K18: =AN18+CR18+AP18+DB18 -> 519 | L18: =BC18+CK18+DE18 -> 0 | O18: =SILVX!B25 -> 52180096 | P18: =SILVX!G25 -> 1 | AM18: =Schwab!S13 -> 15019029 | AN18: =Schwab!Q13 -> 514 | AO18: =Fidelity!P18 -> 1671651.6 | AP18: =Fidelity!O18 -> 0 | BA18: ='TFA - Folio'!H23 -> 93397556 | BB18: ='TFA - Folio'!I18 -> 1 | CQ18: =TDA!O8 -> 141637.82 | CR18: =TDA!N8 -> 5
A19: 41790 | B19: =O19+CM19+Q19+AM19+CQ19+AO19+DA19+BA19+BC19+CO19+BG19+CS19+BI19+CY19+CK19+DC19+DE19 -> 1.677813e+08 | C19: =P19+CN19+R19+AN19+CR19+AP19+DB19+BB19+BD19+CP19+BH19+CT19+BJ19+CZ19+CL19+DD19+DF19 -> 566 | D19: =O19+BA19+CO19+BG19+BI19+DC19 -> 1.5032794e+08 | E19: =P19+BB19+CP19+BH19+BJ19+DD19 -> 2 | F19: =CM19+CS19 -> 0 | H19: =Q19+CY19 -> 0 | J19: =AM19+CQ19+AO19+DA19 -> 17453360 | K19: =AN19+CR19+AP19+DB19 -> 564 | L19: =BC19+CK19+DE19 -> 0 | O19: =SILVX!B26 -> 53150044 | P19: =SILVX!G26 -> 1 | AM19: =Schwab!S14 -> 15039826 | AN19: =Schwab!Q14 -> 525 | AO19: =Fidelity!P19 -> 1633634.5 | AP19: =Fidelity!O19 -> 0 | BA19: ='TFA - Folio'!H24 -> 97177900 | BB19: ='TFA - Folio'!I19 -> 1 | CQ19: =TDA!O9 -> 779900.08 | CR19: =TDA!N9 -> 39
A20: 41820 | B20: =O20+CM20+Q20+AM20+CQ20+AO20+DA20+BA20+BC20+CO20+BG20+CS20+BI20+CY20+CK20+DC20+DE20 -> 1.7451183e+08 | C20: =P20+CN20+R20+AN20+CR20+AP20+DB20+BB20+BD20+CP20+BH20+CT20+BJ20+CZ20+CL20+DD20+DF20 -> 584 | D20: =O20+BA20+CO20+BG20+BI20+DC20 -> 1.5642297e+08 | E20: =P20+BB20+CP20+BH20+BJ20+DD20 -> 2 | F20: =CM20+CS20 -> 0 | H20: =Q20+CY20 -> 0 | J20: =AM20+CQ20+AO20+DA20 -> 18088858 | K20: =AN20+CR20+AP20+DB20 -> 582 | L20: =BC20+CK20+DE20 -> 0 | O20: =SILVX!B27 -> 55639070 | P20: =SILVX!G27 -> 1 | AM20: =Schwab!S15 -> 15728815 | AN20: =Schwab!Q15 -> 516 | AO20: =Fidelity!P20 -> 1554074.6 | AP20: =Fidelity!O20 -> 27 | BA20: ='TFA - Folio'!H25 -> 1.007839e+08 | BB20: ='TFA - Folio'!I20 -> 1 | CQ20: =TDA!O10 -> 805967.89 | CR20: =TDA!N10 -> 39
A21: 41851 | B21: =O21+CM21+Q21+AM21+CQ21+AO21+DA21+BA21+BC21+CO21+BG21+CS21+BI21+CY21+CK21+DC21+DE21 -> 1.768834e+08 | C21: =P21+CN21+R21+AN21+CR21+AP21+DB21+BB21+BD21+CP21+BH21+CT21+BJ21+CZ21+CL21+DD21+DF21 -> 605 | D21: =O21+BA21+CO21+BG21+BI21+DC21 -> 1.5938824e+08 | E21: =P21+BB21+CP21+BH21+BJ21+DD21 -> 2 | F21: =CM21+CS21 -> 0 | H21: =Q21+CY21 -> 0 | J21: =AM21+CQ21+AO21+DA21 -> 17495160 | K21: =AN21+CR21+AP21+DB21 -> 603 | L21: =BC21+CK21+DE21 -> 0 | O21: =SILVX!B28 -> 57860065 | P21: =SILVX!G28 -> 1 | AM21: =Schwab!S16 -> 15182148 | AN21: =Schwab!Q16 -> 533 | AO21: =Fidelity!P21 -> 1547908.6 | AP21: =Fidelity!O21 -> 32 | BA21: ='TFA - Folio'!H26 -> 1.0152817e+08 | BB21: ='TFA - Folio'!I21 -> 1 | CQ21: =TDA!O11 -> 765104.15 | CR21: =TDA!N11 -> 38
A22: 41882 | B22: =O22+CM22+Q22+AM22+CQ22+AO22+DA22+BA22+BC22+CO22+BG22+CS22+BI22+CY22+CK22+DC22+DE22 -> 1.8671688e+08 | C22: =P22+CN22+R22+AN22+CR22+AP22+DB22+BB22+BD22+CP22+BH22+CT22+BJ22+CZ22+CL22+DD22+DF22 -> 619 | D22: =O22+BA22+CO22+BG22+BI22+DC22 -> 1.677052e+08 | E22: =P22+BB22+CP22+BH22+BJ22+DD22 -> 2 | F22: =CM22+CS22 -> 0 | H22: =Q22+CY22 -> 0 | J22: =AM22+CQ22+AO22+DA22 -> 19011682 | K22: =AN22+CR22+AP22+DB22 -> 617 | L22: =BC22+CK22+DE22 -> 0 | O22: =SILVX!B29 -> 60275807 | P22: =SILVX!G29 -> 1 | AM22: =Schwab!S17 -> 16414264 | AN22: =Schwab!Q17 -> 546 | AO22: =Fidelity!P22 -> 1874144.3 | AP22: =Fidelity!O22 -> 33 | BA22: ='TFA - Folio'!H27 -> 1.0742939e+08 | BB22: ='TFA - Folio'!I22 -> 1 | CQ22: =TDA!O12 -> 723273.51 | CR22: =TDA!N12 -> 38
A23: 41912 | B23: =O23+CM23+Q23+AM23+CQ23+AO23+DA23+BA23+BC23+CO23+BG23+CS23+BI23+CY23+CK23+DC23+DE23 -> 1.8719638e+08 | C23: =P23+CN23+R23+AN23+CR23+AP23+DB23+BB23+BD23+CP23+BH23+CT23+BJ23+CZ23+CL23+DD23+DF23 -> 632 | D23: =O23+BA23+CO23+BG23+BI23+DC23 -> 1.6852857e+08 | E23: =P23+BB23+CP23+BH23+BJ23+DD23 -> 2 | F23: =CM23+CS23 -> 0 | H23: =Q23+CY23 -> 0 | J23: =AM23+CQ23+AO23+DA23 -> 18667800 | K23: =AN23+CR23+AP23+DB23 -> 630 | L23: =BC23+CK23+DE23 -> 0 | O23: =SILVX!B30 -> 59967277 | P23: =SILVX!G30 -> 1 | AM23: =Schwab!S18 -> 15775027 | AN23: =Schwab!Q18 -> 554 | AO23: =Fidelity!P23 -> 2054813 | AP23: =Fidelity!O23 -> 34 | BA23: ='TFA - Folio'!H28 -> 1.085613e+08 | BB23: ='TFA - Folio'!I23 -> 1 | CQ23: =TDA!O13 -> 837959.96 | CR23: =TDA!N13 -> 42
... A27: 42035 | B27: =O27+CM27+Q27+AM27+CQ27+AO27+DA27+BA27+BC27+CO27+BG27+CS27+BI27+CY27+CK27+DC27+DE27 -> 2.3063648e+08 | C27: =P27+CN27+R27+AN27+CR27+AP27+DB27+BB27+BD27+CP27+BH27+CT27+BJ27+CZ27+CL27+DD27+DF27 -> 697 | D27: =O27+BA27+CO27+BG27+BI27+DC27 -> 2.0454237e+08 | E27: =P27+BB27+CP27+BH27+BJ27+DD27 -> 2 | F27: =CM27+CS27 -> 0 | H27: =Q27+CY27 -> 0 | J27: =AM27+CQ27+AO27+DA27 -> 26094108 | K27: =AN27+CR27+AP27+DB27 -> 695 | L27: =BC27+CK27+DE27 -> 0 | O27: =SILVX!B34 -> 66896741 | P27: =SILVX!G34 -> 1 | AM27: =Schwab!S22 -> 22619568 | AN27: =Schwab!Q22 -> 605 | AO27: =Fidelity!P27 -> 2363912.3 | AP27: =Fidelity!O27 -> 40 | BA27: ='TFA - Folio'!H32 -> 1.3764563e+08 | BB27: ='TFA - Folio'!I27 -> 1 | CQ27: =TDA!O17 -> 1110627 | CR27: =TDA!N17 -> 50
A28: 42063 | B28: =O28+CM28+Q28+AM28+CQ28+AO28+DA28+BA28+BC28+CO28+BG28+CS28+BI28+CY28+CK28+DC28+DE28 -> 2.4880608e+08 | C28: =P28+CN28+R28+AN28+CR28+AP28+DB28+BB28+BD28+CP28+BH28+CT28+BJ28+CZ28+CL28+DD28+DF28 -> 716 | D28: =O28+BA28+CO28+BG28+BI28+DC28 -> 2.2340973e+08 | E28: =P28+BB28+CP28+BH28+BJ28+DD28 -> 3 | F28: =CM28+CS28 -> 0 | H28: =Q28+CY28 -> 0 | J28: =AM28+CQ28+AO28+DA28 -> 25396345 | K28: =AN28+CR28+AP28+DB28 -> 713 | L28: =BC28+CK28+DE28 -> 0 | O28: =SILVX!B35 -> 69872904 | P28: =SILVX!G35 -> 1 | AM28: =Schwab!S23 -> 21747082 | AN28: =Schwab!Q23 -> 626 | AO28: =Fidelity!P28 -> 2400679.4 | AP28: =Fidelity!O28 -> 38 | BA28: ='TFA - Folio'!H33 -> 1.5303516e+08 | BB28: ='TFA - Folio'!I28 -> 1 | CO28: =Stifel!B2 -> 501672.76 | CP28: =Stifel!K2 -> 1 | CQ28: =TDA!O18 -> 1133295.8 | CR28: =TDA!N18 -> 48 | DA28: =Prudential!E2 -> 115287.29 | DB28: =Prudential!D2 -> 1
A29: 42094 | B29: =O29+CM29+Q29+AM29+CQ29+AO29+DA29+BA29+BC29+CO29+BG29+CS29+BI29+CY29+CK29+DC29+DE29 -> 2.6056483e+08 | C29: =P29+CN29+R29+AN29+CR29+AP29+DB29+BB29+BD29+CP29+BH29+CT29+BJ29+CZ29+CL29+DD29+DF29 -> 743 | D29: =O29+BA29+CO29+BG29+BI29+DC29 -> 2.3344826e+08 | E29: =P29+BB29+CP29+BH29+BJ29+DD29 -> 3 | F29: =CM29+CS29 -> 0 | H29: =Q29+CY29 -> 0 | J29: =AM29+CQ29+AO29+DA29 -> 27116574 | K29: =AN29+CR29+AP29+DB29 -> 740 | L29: =BC29+CK29+DE29 -> 0 | O29: =SILVX!B36 -> 71575874 | P29: =SILVX!G36 -> 1 | AM29: =Schwab!S24 -> 23436501 | AN29: =Schwab!Q24 -> 651 | AO29: =Fidelity!P29 -> 2417360.4 | AP29: =Fidelity!O29 -> 38 | BA29: ='TFA - Folio'!H34 -> 1.6137072e+08 | BB29: ='TFA - Folio'!I29 -> 1 | CO29: =Stifel!B3 -> 501670.61 | CP29: =Stifel!K3 -> 1 | CQ29: =TDA!O19 -> 1147289.8 | CR29: =TDA!N19 -> 50 | DA29: =Prudential!E3 -> 115422.93 | DB29: =Prudential!D3 -> 1
A30: 42124 | B30: =O30+CM30+Q30+AM30+CQ30+AO30+DA30+BA30+BC30+CO30+BG30+CS30+BI30+CY30+CK30+DC30+DE30 -> 2.7059347e+08 | C30: =P30+CN30+R30+AN30+CR30+AP30+DB30+BB30+BD30+CP30+BH30+CT30+BJ30+CZ30+CL30+DD30+DF30 -> 764 | D30: =O30+BA30+CO30+BG30+BI30+DC30 -> 2.3754686e+08 | E30: =P30+BB30+CP30+BH30+BJ30+DD30 -> 3 | F30: =CM30+CS30 -> 0 | H30: =Q30+CY30 -> 0 | J30: =AM30+CQ30+AO30+DA30 -> 27602800 | K30: =AN30+CR30+AP30+DB30 -> 760 | L30: =BC30+CK30+DE30 -> 5443804 | M30: =BD30+CL30+DF30 -> 1 | O30: =SILVX!B37 -> 71483082 | P30: =SILVX!G37 -> 1 | AM30: =Schwab!S25 -> 23895032 | AN30: =Schwab!Q25 -> 671 | AO30: =Fidelity!P30 -> 2454965 | AP30: =Fidelity!O30 -> 38 | BA30: ='TFA - Folio'!H35 -> 1.6557246e+08 | BB30: ='TFA - Folio'!I30 -> 1 | BC30: ='TFA - Folio'!K35 -> 5443804 | BD30: ='TFA - Folio'!N35 -> 1 | CO30: =Stifel!B4 -> 491317.13 | CP30: =Stifel!K4 -> 1 | CQ30: =TDA!O20 -> 1139169.9 | CR30: =TDA!N20 -> 50 | DA30: =Prudential!E4 -> 113633.13 | DB30: =Prudential!D4 -> 1
A31: 42155 | B31: =O31+CM31+Q31+AM31+CQ31+AO31+DA31+BA31+BC31+CO31+BG31+CS31+BI31+CY31+CK31+DC31+DE31 -> 2.8375676e+08 | C31: =P31+CN31+R31+AN31+CR31+AP31+DB31+BB31+BD31+CP31+BH31+CT31+BJ31+CZ31+CL31+DD31+DF31 -> 765 | D31: =O31+BA31+CO31+BG31+BI31+DC31 -> 2.4373243e+08 | E31: =P31+BB31+CP31+BH31+BJ31+DD31 -> 3 | F31: =CM31+CS31 -> 0 | H31: =Q31+CY31 -> 0 | J31: =AM31+CQ31+AO31+DA31 -> 28854710 | K31: =AN31+CR31+AP31+DB31 -> 761 | L31: =BC31+CK31+DE31 -> 11169615 | M31: =BD31+CL31+DF31 -> 1 | O31: =SILVX!B38 -> 72089141 | P31: =SILVX!G38 -> 1 | AM31: =Schwab!S26 -> 25130832 | AN31: =Schwab!Q26 -> 671 | AO31: =Fidelity!P31 -> 2465735.6 | AP31: =Fidelity!O31 -> 39 | BA31: ='TFA - Folio'!H36 -> 171145806 | BB31: ='TFA - Folio'!I31 -> 1 | BC31: ='TFA - Folio'!K36 -> 11169615 | BD31: ='TFA - Folio'!N36 -> 1 | CO31: =Stifel!B5 -> 497485.88 | CP31: =Stifel!K5 -> 1 | CQ31: =TDA!O21 -> 1144996.6 | CR31: =TDA!N21 -> 50 | DA31: =Prudential!E5 -> 113146.36 | DB31: =Prudential!D5 -> 1
A32: 42185 | B32: =O32+CM32+Q32+AM32+CQ32+AO32+DA32+BA32+BC32+CO32+BG32+CS32+BI32+CY32+CK32+DC32+DE32 -> 2.7979975e+08 | C32: =P32+CN32+R32+AN32+CR32+AP32+DB32+BB32+BD32+CP32+BH32+CT32+BJ32+CZ32+CL32+DD32+DF32 -> 783 | D32: =O32+BA32+CO32+BG32+BI32+DC32 -> 2.386637e+08 | E32: =P32+BB32+CP32+BH32+BJ32+DD32 -> 3 | F32: =CM32+CS32 -> 0 | H32: =Q32+CY32 -> 0 | J32: =AM32+CQ32+AO32+DA32 -> 27147640 | K32: =AN32+CR32+AP32+DB32 -> 779 | L32: =BC32+CK32+DE32 -> 13988418 | M32: =BD32+CL32+DF32 -> 1 | O32: =SILVX!B39 -> 71051329 | P32: =SILVX!G39 -> 1 | AM32: =Schwab!S27 -> 23346862 | AN32: =Schwab!Q27 -> 688 | AO32: =Fidelity!P32 -> 2421279.6 | AP32: =Fidelity!O32 -> 40 | BA32: ='TFA - Folio'!H37 -> 1.6712556e+08 | BB32: ='TFA - Folio'!I32 -> 1 | BC32: ='TFA - Folio'!K37 -> 13988418 | BD32: ='TFA - Folio'!N37 -> 1 | CO32: =Stifel!B6 -> 486805.53 | CP32: =Stifel!K6 -> 1 | CQ32: =TDA!O22 -> 1269038.9 | CR32: =TDA!N22 -> 50 | DA32: =Prudential!E6 -> 110459.19 | DB32: =Prudential!D6 -> 1
A33: 42216 | B33: =O33+CM33+Q33+AM33+CQ33+AO33+DA33+BA33+BC33+CO33+BG33+CS33+BI33+CY33+CK33+DC33+DE33 -> 3.0558192e+08 | C33: =P33+CN33+R33+AN33+CR33+AP33+DB33+BB33+BD33+CP33+BH33+CT33+BJ33+CZ33+CL33+DD33+DF33 -> 795 | D33: =O33+BA33+CO33+BG33+BI33+DC33 -> 2.5640275e+08 | E33: =P33+BB33+CP33+BH33+BJ33+DD33 -> 3 | F33: =CM33+CS33 -> 0 | H33: =Q33+CY33 -> 0 | J33: =AM33+CQ33+AO33+DA33 -> 29844049 | K33: =AN33+CR33+AP33+DB33 -> 791 | L33: =BC33+CK33+DE33 -> 19335117 | M33: =BD33+CL33+DF33 -> 1 | O33: =SILVX!B40 -> 75409202 | P33: =SILVX!G40 -> 1 | AM33: =Schwab!S28 -> 25984135 | AN33: =Schwab!Q28 -> 703 | AO33: =Fidelity!P33 -> 2464372.9 | AP33: =Fidelity!O33 -> 37 | BA33: ='TFA - Folio'!H38 -> 1.804826e+08 | BB33: ='TFA - Folio'!I33 -> 1 | BC33: ='TFA - Folio'!K38 -> 19335117 | BD33: ='TFA - Folio'!N38 -> 1 | CO33: =Stifel!B7 -> 510948.34 | CP33: =Stifel!K7 -> 1 | CQ33: =TDA!O23 -> 1285511.9 | CR33: =TDA!N23 -> 50 | DA33: =Prudential!E7 -> 110029.88 | DB33: =Prudential!D7 -> 1
A34: 42247 | B34: =O34+CM34+Q34+AM34+CQ34+AO34+DA34+BA34+BC34+CO34+BG34+CS34+BI34+CY34+CK34+DC34+DE34 -> 2.9712704e+08 | C34: =P34+CN34+R34+AN34+CR34+AP34+DB34+BB34+BD34+CP34+BH34+CT34+BJ34+CZ34+CL34+DD34+DF34 -> 806 | D34: =O34+BA34+CO34+BG34+BI34+DC34 -> 2.4511105e+08 | E34: =P34+BB34+CP34+BH34+BJ34+DD34 -> 3 | F34: =CM34+CS34 -> 0 | H34: =Q34+CY34 -> 0 | J34: =AM34+CQ34+AO34+DA34 -> 30642172 | K34: =AN34+CR34+AP34+DB34 -> 802 | L34: =BC34+CK34+DE34 -> 21373816 | M34: =BD34+CL34+DF34 -> 1 | O34: =SILVX!B41 -> 72553876 | P34: =SILVX!G41 -> 1 | AM34: =Schwab!S29 -> 26503267 | AN34: =Schwab!Q29 -> 711 | AO34: =Fidelity!P34 -> 2740839.8 | AP34: =Fidelity!O34 -> 39 | BA34: ='TFA - Folio'!H39 -> 1.7207041e+08 | BB34: ='TFA - Folio'!I34 -> 1 | BC34: ='TFA - Folio'!K39 -> 21373816 | BD34: ='TFA - Folio'!N39 -> 1 | CO34: =Stifel!B8 -> 486766.64 | CP34: =Stifel!K8 -> 1 | CQ34: =TDA!O24 -> 1288767.5 | CR34: =TDA!N24 -> 51 | DA34: =Prudential!E8 -> 109297.71 | DB34: =Prudential!D8 -> 1
A35: 42277 | B35: =O35+CM35+Q35+AM35+CQ35+AO35+DA35+BA35+BC35+CO35+BG35+CS35+BI35+CY35+CK35+DC35+DE35 -> 3.0023612e+08 | C35: =P35+CN35+R35+AN35+CR35+AP35+DB35+BB35+BD35+CP35+BH35+CT35+BJ35+CZ35+CL35+DD35+DF35 -> 810 | D35: =O35+BA35+CO35+BG35+BI35+DC35 -> 2.4800922e+08 | E35: =P35+BB35+CP35+BH35+BJ35+DD35 -> 3 | F35: =CM35+CS35 -> 0 | H35: =Q35+CY35 -> 0 | J35: =AM35+CQ35+AO35+DA35 -> 29796249 | K35: =AN35+CR35+AP35+DB35 -> 806 | L35: =BC35+CK35+DE35 -> 22430654 | M35: =BD35+CL35+DF35 -> 1 | O35: =SILVX!B42 -> 72933072 | P35: =SILVX!G42 -> 1 | AM35: =Schwab!S30 -> 25911677 | AN35: =Schwab!Q30 -> 715 | AO35: =Fidelity!P35 -> 2459675.1 | AP35: =Fidelity!O35 -> 39 | BA35: ='TFA - Folio'!H40 -> 1.745868e+08 | BB35: ='TFA - Folio'!I35 -> 1 | BC35: ='TFA - Folio'!K40 -> 22430654 | BD35: ='TFA - Folio'!N40 -> 1 | CO35: =Stifel!B9 -> 489346.34 | CP35: =Stifel!K9 -> 1 | CQ35: =TDA!O25 -> 1317738 | CR35: =TDA!N25 -> 51 | DA35: =Prudential!E9 -> 107158.79 | DB35: =Prudential!D9 -> 1
A36: 42308 | B36: =O36+CM36+Q36+AM36+CQ36+AO36+DA36+BA36+BC36+CO36+BG36+CS36+BI36+CY36+CK36+DC36+DE36 -> 3.3097015e+08 | C36: =P36+CN36+R36+AN36+CR36+AP36+DB36+BB36+BD36+CP36+BH36+CT36+BJ36+CZ36+CL36+DD36+DF36 -> 822 | D36: =O36+BA36+CO36+BG36+BI36+DC36 -> 2.7357862e+08 | E36: =P36+BB36+CP36+BH36+BJ36+DD36 -> 3 | F36: =CM36+CS36 -> 0 | H36: =Q36+CY36 -> 0 | J36: =AM36+CQ36+AO36+DA36 -> 32098575 | K36: =AN36+CR36+AP36+DB36 -> 813 | L36: =BC36+CK36+DE36 -> 25292959 | M36: =BD36+CL36+DF36 -> 6 | O36: =SILVX!B43 -> 81294138 | P36: =SILVX!G43 -> 1 | AM36: =Schwab!S31 -> 27604223 | AN36: =Schwab!Q31 -> 719 | AO36: =Fidelity!P36 -> 2773930.8 | AP36: =Fidelity!O36 -> 39 | BA36: ='TFA - Folio'!H41 -> 1.9176278e+08 | BB36: ='TFA - Folio'!I36 -> 1 | BC36: ='TFA - Folio'!K41 -> 24691379 | BD36: ='TFA - Folio'!N41 -> 1 | CO36: =Stifel!B10 -> 521704.76 | CP36: =Stifel!K10 -> 1 | CQ36: =TDA!O26 -> 1610256.2 | CR36: =TDA!N26 -> 54 | DA36: =Prudential!E10 -> 110164.2 | DB36: =Prudential!D10 -> 1 | DE36: =Folio!B2 -> 601579.94 | DF36: =Folio!C2 -> 5
A37: 42338 | B37: =O37+CM37+Q37+AM37+CQ37+AO37+DA37+BA37+BC37+CO37+BG37+CS37+BI37+CY37+CK37+DC37+DE37 -> 3.3180873e+08 | C37: =P37+CN37+R37+AN37+CR37+AP37+DB37+BB37+BD37+CP37+BH37+CT37+BJ37+CZ37+CL37+DD37+DF37 -> 812 | D37: =O37+BA37+CO37+BG37+BI37+DC37 -> 2.7323413e+08 | E37: =P37+BB37+CP37+BH37+BJ37+DD37 -> 3 | F37: =CM37+CS37 -> 0 | H37: =Q37+CY37 -> 0 | J37: =AM37+CQ37+AO37+DA37 -> 32634033 | K37: =AN37+CR37+AP37+DB37 -> 803 | L37: =BC37+CK37+DE37 -> 25940571 | M37: =BD37+CL37+DF37 -> 6 | O37: =SILVX!B44 -> 80390280 | P37: =SILVX!G44 -> 1 | AM37: =Schwab!S32 -> 28237672 | AN37: =Schwab!Q32 -> 708 | AO37: =Fidelity!P37 -> 2731964.8 | AP37: =Fidelity!O37 -> 38 | BA37: ='TFA - Folio'!H42 -> 1.9232183e+08 | BB37: ='TFA - Folio'!I37 -> 1 | BC37: ='TFA - Folio'!K42 -> 25345002 | BD37: ='TFA - Folio'!N42 -> 1 | CO37: =Stifel!B11 -> 522017.14 | CP37: =Stifel!K11 -> 1 | CQ37: =TDA!O27 -> 1555557.5 | CR37: =TDA!N27 -> 56 | DA37: =Prudential!E11 -> 108839.34 | DB37: =Prudential!D11 -> 1 | DE37: =Folio!B3 -> 595568.38 | DF37: =Folio!C3 -> 5
A38: 42369 | B38: =O38+CM38+Q38+AM38+CQ38+AO38+DA38+BA38+BC38+CO38+BG38+CS38+BI38+CY38+CK38+DC38+DE38 -> 3.3229184e+08 | C38: =P38+CN38+R38+AN38+CR38+AP38+DB38+BB38+BD38+CP38+BH38+CT38+BJ38+CZ38+CL38+DD38+DF38 -> 807 | D38: =O38+BA38+CO38+BG38+BI38+DC38 -> 2.7481298e+08 | E38: =P38+BB38+CP38+BH38+BJ38+DD38 -> 3 | F38: =CM38+CS38 -> 0 | H38: =Q38+CY38 -> 0 | J38: =AM38+CQ38+AO38+DA38 -> 31523436 | K38: =AN38+CR38+AP38+DB38 -> 798 | L38: =BC38+CK38+DE38 -> 25955429 | M38: =BD38+CL38+DF38 -> 6 | O38: =SILVX!B45 -> 80182147 | P38: =SILVX!G45 -> 1 | AM38: =Schwab!S33 -> 27097924 | AN38: =Schwab!Q33 -> 701 | AO38: =Fidelity!P38 -> 2746597.6 | AP38: =Fidelity!O38 -> 38 | BA38: ='TFA - Folio'!H43 -> 1.941075e+08 | BB38: ='TFA - Folio'!I38 -> 1 | BC38: ='TFA - Folio'!K43 -> 25368789 | BD38: ='TFA - Folio'!N43 -> 1 | CO38: =Stifel!B12 -> 523327.45 | CP38: =Stifel!K12 -> 1 | CQ38: =TDA!O28 -> 1570764.8 | CR38: =TDA!N28 -> 58 | DA38: =Prudential!E12 -> 108149.1 | DB38: =Prudential!D12 -> 1 | DE38: =Folio!B4 -> 586639.56 | DF38: =Folio!C4 -> 5
A39: 42400 | B39: =O39+CM39+Q39+AM39+CQ39+AO39+DA39+BA39+BC39+CO39+BG39+CS39+BI39+CY39+CK39+DC39+DE39 -> 3.9631938e+08 | C39: =P39+CN39+R39+AN39+CR39+AP39+DB39+BB39+BD39+CP39+BH39+CT39+BJ39+CZ39+CL39+DD39+DF39 -> 798 | D39: =O39+BA39+CO39+BG39+BI39+DC39 -> 3.3656558e+08 | E39: =P39+BB39+CP39+BH39+BJ39+DD39 -> 4 | F39: =CM39+CS39 -> 0 | H39: =Q39+CY39 -> 0 | J39: =AM39+CQ39+AO39+DA39 -> 29267067 | K39: =AN39+CR39+AP39+DB39 -> 788 | L39: =BC39+CK39+DE39 -> 30486730 | M39: =BD39+CL39+DF39 -> 6 | O39: =SILVX!B46 -> 79613453 | P39: =SILVX!G46 -> 1 | AM39: =Schwab!S34 -> 24725092 | AN39: =Schwab!Q34 -> 691 | AO39: =Fidelity!P39 -> 2625482.4 | AP39: =Fidelity!O39 -> 38 | BA39: ='TFA - Folio'!H44 -> 1.959236e+08 | BB39: ='TFA - Folio'!I39 -> 1 | BC39: ='TFA - Folio'!K44 -> 29896321 | BD39: ='TFA - Folio'!N44 -> 1 | BG39: =UNC!B2 -> 60512888 | BH39: =UNC!C2 -> 1 | CO39: =Stifel!B13 -> 515644.95 | CP39: =Stifel!K13 -> 1 | CQ39: =TDA!O29 -> 1809504.4 | CR39: =TDA!N29 -> 58 | DA39: =Prudential!E13 -> 106987.57 | DB39: =Prudential!D13 -> 1 | DE39: =Folio!B5 -> 590409.06 | DF39: =Folio!C5 -> 5
A40: 42429 | B40: =O40+CM40+Q40+AM40+CQ40+AO40+DA40+BA40+BC40+CO40+BG40+CS40+BI40+CY40+CK40+DC40+DE40 -> 4.3188242e+08 | C40: =P40+CN40+R40+AN40+CR40+AP40+DB40+BB40+BD40+CP40+BH40+CT40+BJ40+CZ40+CL40+DD40+DF40 -> 796 | D40: =O40+BA40+CO40+BG40+BI40+DC40 -> 3.6594404e+08 | E40: =P40+BB40+CP40+BH40+BJ40+DD40 -> 6 | F40: =CM40+CS40 -> 0 | H40: =Q40+CY40 -> 0 | J40: =AM40+CQ40+AO40+DA40 -> 31268321 | K40: =AN40+CR40+AP40+DB40 -> 784 | L40: =BC40+CK40+DE40 -> 34670059 | M40: =BD40+CL40+DF40 -> 6 | O40: =SILVX!B47 -> 92880465 | P40: =SILVX!G47 -> 1 | AM40: =Schwab!S35 -> 26838836 | AN40: =Schwab!Q35 -> 696 | AO40: =Fidelity!P40 -> 2775074.7 | AP40: =Fidelity!O40 -> 33 | BA40: ='TFA - Folio'!H45 -> 2.0881877e+08 | BB40: ='TFA - Folio'!I40 -> 1 | BC40: ='TFA - Folio'!K45 -> 34079650 | BD40: ='TFA - Folio'!N45 -> 1 | BG40: =UNC!B3 -> 61869873 | BH40: =UNC!C3 -> 1 | CO40: =Stifel!B14 -> 2374938.7 | CP40: =Stifel!K14 -> 3 | CQ40: =TDA!O30 -> 1546479.5 | CR40: =TDA!N30 -> 54 | DA40: =Prudential!E14 -> 107931.44 | DB40: =Prudential!D14 -> 1 | DE40: =Folio!B6 -> 590409.06 | DF40: =Folio!C6 -> 5
A41: 42460 | B41: =O41+CM41+Q41+AM41+CQ41+AO41+DA41+BA41+BC41+CO41+BG41+CS41+BI41+CY41+CK41+DC41+DE41 -> 5.5371888e+08 | C41: =P41+CN41+R41+AN41+CR41+AP41+DB41+BB41+BD41+CP41+BH41+CT41+BJ41+CZ41+CL41+DD41+DF41 -> 813 | D41: =O41+BA41+CO41+BG41+BI41+DC41 -> 4.4960782e+08 | E41: =P41+BB41+CP41+BH41+BJ41+DD41 -> 6 | F41: =CM41+CS41 -> 26636105 | G41: =CN41+CT41 -> 1 | H41: =Q41+CY41 -> 0 | J41: =AM41+CQ41+AO41+DA41 -> 33214194 | K41: =AN41+CR41+AP41+DB41 -> 800 | L41: =BC41+CK41+DE41 -> 44260767 | M41: =BD41+CL41+DF41 -> 6 | O41: =SILVX!B48 -> 1.015352e+08 | P41: =SILVX!G48 -> 1 | AM41: =Schwab!S36 -> 28589054 | AN41: =Schwab!Q36 -> 712 | AO41: =Fidelity!P41 -> 2878941.7 | AP41: =Fidelity!O41 -> 33 | BA41: ='TFA - Folio'!H46 -> 2.4314565e+08 | BB41: ='TFA - Folio'!I41 -> 1 | BC41: ='TFA - Folio'!K46 -> 43670358 | BD41: ='TFA - Folio'!N46 -> 1 | BG41: =UNC!B4 -> 1.024606e+08 | BH41: =UNC!C4 -> 1 | CO41: =Stifel!B15 -> 2466364.9 | CP41: =Stifel!K15 -> 3 | CQ41: =TDA!O31 -> 1634301.8 | CR41: =TDA!N31 -> 54 | CS41: =UNC!D4 -> 26636105 | CT41: =UNC!E4 -> 1 | DA41: =Prudential!E15 -> 111896.92 | DB41: =Prudential!D15 -> 1 | DE41: =Folio!B7 -> 590409.06 | DF41: =Folio!C7 -> 5
A42: 42490 | B42: =O42+CM42+Q42+AM42+CQ42+AO42+DA42+BA42+BC42+CO42+BG42+CS42+BI42+CY42+CK42+DC42+DE42 -> 5.6409047e+08 | C42: =P42+CN42+R42+AN42+CR42+AP42+DB42+BB42+BD42+CP42+BH42+CT42+BJ42+CZ42+CL42+DD42+DF42 -> 824 | D42: =O42+BA42+CO42+BG42+BI42+DC42 -> 4.5566241e+08 | E42: =P42+BB42+CP42+BH42+BJ42+DD42 -> 7 | F42: =CM42+CS42 -> 26649522 | G42: =CN42+CT42 -> 2 | H42: =Q42+CY42 -> 0 | J42: =AM42+CQ42+AO42+DA42 -> 32794993 | K42: =AN42+CR42+AP42+DB42 -> 809 | L42: =BC42+CK42+DE42 -> 48983553 | M42: =BD42+CL42+DF42 -> 6 | O42: =SILVX!B49 -> 1.021536e+08 | P42: =SILVX!G49 -> 1 | AM42: =Schwab!S37 -> 28212576 | AN42: =Schwab!Q37 -> 721 | AO42: =Fidelity!P42 -> 2879856.7 | AP42: =Fidelity!O42 -> 33 | BA42: ='TFA - Folio'!H47 -> 2.4912137e+08 | BB42: ='TFA - Folio'!I42 -> 1 | BC42: ='TFA - Folio'!K47 -> 48393144 | BD42: ='TFA - Folio'!N47 -> 1 | BG42: =UNC!B5 -> 1.0099205e+08 | BH42: =UNC!C5 -> 1 | BI42: ='Schwab LC'!D2 -> 983504.05 | BJ42: ='Schwab LC'!E2 -> 1 | CM42: =SCLVX!B3 -> 292845.33 | CN42: =SCLVX!G3 -> 1 | CO42: =Stifel!B16 -> 2411877.3 | CP42: =Stifel!K16 -> 3 | CQ42: =TDA!O32 -> 1590409.4 | CR42: =TDA!N32 -> 54 | CS42: =UNC!D5 -> 26356677 | CT42: =UNC!E5 -> 1 | DA42: =Prudential!E16 -> 112150.66 | DB42: =Prudential!D16 -> 1 | DE42: =Folio!B8 -> 590409.06 | DF42: =Folio!C8 -> 5
A43: 42521 | B43: =O43+CM43+Q43+AM43+CQ43+AO43+DA43+BA43+BC43+CO43+BG43+CS43+BI43+CY43+CK43+DC43+DE43 -> 5.8791184e+08 | C43: =P43+CN43+R43+AN43+CR43+AP43+DB43+BB43+BD43+CP43+BH43+CT43+BJ43+CZ43+CL43+DD43+DF43 -> 807 | D43: =O43+BA43+CO43+BG43+BI43+DC43 -> 4.7744573e+08 | E43: =P43+BB43+CP43+BH43+BJ43+DD43 -> 11 | F43: =CM43+CS43 -> 38203241 | G43: =CN43+CT43 -> 2 | H43: =Q43+CY43 -> 0 | J43: =AM43+CQ43+AO43+DA43 -> 19983210 | K43: =AN43+CR43+AP43+DB43 -> 788 | L43: =BC43+CK43+DE43 -> 52279655 | M43: =BD43+CL43+DF43 -> 6 | O43: =SILVX!B50 -> 1.1000237e+08 | P43: =SILVX!G50 -> 1 | AM43: =Schwab!S38 -> 15694541 | AN43: =Schwab!Q38 -> 699 | AO43: =Fidelity!P43 -> 2861990.1 | AP43: =Fidelity!O43 -> 32 | BA43: ='TFA - Folio'!H48 -> 2.59697e+08 | BB43: ='TFA - Folio'!I43 -> 1 | BC43: ='TFA - Folio'!K48 -> 51689246 | BD43: ='TFA - Folio'!N48 -> 1 | BG43: =UNC!B6 -> 102949466 | BH43: =UNC!C6 -> 1 | BI43: ='Schwab LC'!D3 -> 1505135.9 | BJ43: ='Schwab LC'!E3 -> 2 | CM43: =SCLVX!B4 -> 11273789 | CN43: =SCLVX!G4 -> 1 | CO43: =Stifel!B17 -> 3291756.5 | CP43: =Stifel!K17 -> 6 | CQ43: =TDA!O33 -> 1315648.9 | CR43: =TDA!N33 -> 56 | CS43: =UNC!D6 -> 26929452 | CT43: =UNC!E6 -> 1 | DA43: =Prudential!E17 -> 111030.35 | DB43: =Prudential!D17 -> 1 | DE43: =Folio!B9 -> 590409.06 | DF43: =Folio!C9 -> 5
...

Sheet SILVX
A1: Date | B1: $$$ | C1: Ret % | D1: Ret $$ | E1: Contribution +/- | F1: Total | G1: Accts | H1: SILVX Nav | K1: Avg. Assets
A2: 41060 | B2: 3126485.8 | G2: 1 | J2: 2012 | K2: =AVERAGE(B2:B9) -> 5189635
A3: 41090 | B3: 2325832.7 | G3: 1 | J3: 2013 | K3: =AVERAGE(B10:B21) -> 23557376
A4: 41121 | B4: 3567730.7 | G4: 1 | J4: 2014 | K4: =AVERAGE(B22:B33) -> 56651692
A5: 41152 | B5: 3561857.1 | G5: 1 | J5: 2015 | K5: =AVERAGE(B34:B45) -> 73810982
A6: 41182 | B6: 5001232.2 | G6: 1 | J6: 2016 | K6: =AVERAGE(B46:B57) -> 1.1044701e+08
A7: 41213 | B7: 6130044.1 | G7: 1 | J7: 2017 | K7: =AVERAGE(B58:B69) -> 1.127141e+08
A8: 41243 | B8: 8317344.8 | G8: 1 | J8: 2018
A9: 41274 | B9: 9486552.3 | G9: 1 | J9: 2019
A10: 41305 | B10: 10810338 | C10: 0.048 | D10: =SUM(C10*B9) -> 455354.51 | E10: =B10-(B9+D10) -> 868431.64 | F10: =D10+E10 -> 1323786.1 | G10: 1 | J10: 2020
A11: =AUM!A4 -> 41333 | B11: 11771288 | C11: 0.0384 | D11: =SUM(C11*B10) -> 415117 | E11: =B11-(B10+D11) -> 545832.17 | F11: =D11+E11 -> 960949.17 | G11: 1
A12: =AUM!A5 -> 41364 | B12: 13089271 | C12: 0.0432 | D12: =SUM(C12*B11) -> 508519.63 | E12: =B12-(B11+D12) -> 809463.9 | F12: =D12+E12 -> 1317983.5 | G12: 1
A13: =AUM!A6 -> 41394 | B13: 16958369 | C13: 0.025 | D13: =SUM(C13*B12) -> 327231.78 | E13: =B13-(B12+D13) -> 3541865.6 | F13: =D13+E13 -> 3869097.4 | G13: 1
A14: =AUM!A7 -> 41425 | B14: 17899655 | C14: -0.0135 | D14: =SUM(C14*B13) -> -228937.98 | E14: =B14-(B13+D14) -> 1170224.8 | F14: =D14+E14 -> 941286.84 | G14: 1
A15: =AUM!A8 -> 41455 | B15: 18417136 | C15: 0.0043 | D15: =SUM(C15*B14) -> 76968.518 | E15: =B15-(B14+D15) -> 440512.32 | F15: =D15+E15 -> 517480.84 | G15: 1
A16: =AUM!A9 -> 41486 | B16: 23781673 | C16: 0.0451 | D16: =SUM(C16*B15) -> 830612.84 | E16: =B16-(B15+D16) -> 4533923.5 | F16: =D16+E16 -> 5364536.4 | G16: 1
A17: =AUM!A10 -> 41517 | B17: 25620949 | C17: -0.0358 | D17: =SUM(C17*B16) -> -851383.88 | E17: =B17-(B16+D17) -> 2690660.1 | F17: =D17+E17 -> 1839276.2 | G17: 1
A18: =AUM!A11 -> 41547 | B18: 30750157 | C18: 0.0203 | D18: =SUM(C18*B17) -> 520105.26 | E18: =B18-(B17+D18) -> 4609103.1 | F18: =D18+E18 -> 5129208.4 | G18: 1
A19: =AUM!A12 -> 41578 | B19: 34983487 | C19: 0.0372 | D19: =SUM(C19*B18) -> 1143905.8 | E19: =B19-(B18+D19) -> 3089423.9 | F19: =D19+E19 -> 4233329.7 | G19: 1
A20: =AUM!A13 -> 41608 | B20: 38040703 | C20: 0.0183 | D20: =SUM(C20*B19) -> 640197.81 | E20: =B20-(B19+D20) -> 2417018 | F20: =D20+E20 -> 3057215.8 | G20: 1
A21: =AUM!A14 -> 41639 | B21: 40565492 | C21: 0.0201 | D21: =SUM(C21*B20) -> 764618.12 | E21: =B21-(B20+D21) -> 1760171.2 | F21: =D21+E21 -> 2524789.4 | G21: 1
A22: =AUM!A15 -> 41670 | B22: 44164273 | C22: -0.033 | D22: =SUM(C22*B21) -> -1338661.2 | E22: =B22-(B21+D22) -> 4937441.8 | F22: =D22+E22 -> 3598780.5 | G22: 1
... A33: =AUM!A26 -> 42004 | B33: 67662864 | C33: 0 | D33: =SUM(C33*B32) -> 0 | E33: =B33-(B32+D33) -> 164978.8 | F33: =D33+E33 -> 164978.8 | G33: 1
A34: =AUM!A27 -> 42035 | B34: 66896741 | C34: -0.0121 | D34: =SUM(C34*B33) -> -818720.65 | E34: =B34-(B33+D34) -> 52598.072 | F34: =D34+E34 -> -766122.58 | G34: 1 | H34: 13.84
A35: =AUM!A28 -> 42063 | B35: 69872904 | C35: 0.0303 | D35: =SUM(C35*B34) -> 2026971.3 | E35: =B35-(B34+D35) -> 949191.73 | F35: =D35+E35 -> 2976163 | G35: 1 | H35: 14.26
A36: =AUM!A29 -> 42094 | B36: 71575874 | C36: -0.007 | D36: =SUM(C36*B35) -> -489110.33 | E36: =B36-(B35+D36) -> 2192079.9 | F36: =D36+E36 -> 1702969.6 | G36: 1 | H36: 14.16
A37: =AUM!A30 -> 42124 | B37: 71483082 | C37: -0.0141 | D37: =SUM(C37*B36) -> -1009219.8 | E37: =B37-(B36+D37) -> 916428.2 | F37: =D37+E37 -> -92791.62 | G37: 1 | H37: 13.96
A38: =AUM!A31 -> 42155 | B38: 72089141 | C38: 0.01 | D38: =SUM(C38*B37) -> 714830.82 | E38: =B38-(B37+D38) -> -108772.02 | F38: =D38+E38 -> 606058.8 | G38: 1 | H38: 14.1
A39: 42185 | B39: 71051329 | C39: -0.0191 | D39: =SUM(C39*B38) -> -1376902.6 | E39: =B39-(B38+D39) -> 339090.27 | F39: =D39+E39 -> -1037812.3 | G39: 1 | H39: 13.83
A40: 42216 | B40: 75409202 | C40: 0.0463 | D40: =SUM(C40*B39) -> 3289676.5 | E40: =B40-(B39+D40) -> 1068196.6 | F40: =D40+E40 -> 4357873.2 | G40: 1 | H40: 14.47
A41: 42247 | B41: 72553876 | C41: -0.0477 | D41: =SUM(C41*B40) -> -3597018.9 | E41: =B41-(B40+D41) -> 741692.87 | F41: =D41+E41 -> -2855326.1 | G41: 1 | H41: 13.78
A42: 42277 | B42: 72933072 | C42: 0.0036 | D42: =SUM(C42*B41) -> 261193.95 | E42: =B42-(B41+D42) -> 118002.15 | F42: =D42+E42 -> 379196.1 | G42: 1 | H42: 13.83
A43: 42307 | B43: 81294138 | C43: 0.0578 | D43: =SUM(C43*B42) -> 4215531.6 | E43: =B43-(B42+D43) -> 4145534.5 | F43: =D43+E43 -> 8361066.1 | G43: 1 | H43: 14.63
A44: 42338 | B44: 80390280 | C44: -0.0055 | D44: =SUM(C44*B43) -> -447117.76 | E44: =B44-(B43+D44) -> -456740.43 | F44: =D44+E44 -> -903858.19 | G44: 1 | H44: 14.55
A45: 42369 | B45: 80182147 | C45: -0.0028 | D45: =SUM(C45*B44) -> -225092.78 | E45: =B45-(B44+D45) -> 16959.963 | F45: =D45+E45 -> -208132.82 | G45: 1 | H45: 13.58
A46: 42398 | B46: 79613453 | C46: -0.0251 | D46: =SUM(C46*B45) -> -2012571.9 | E46: =B46-(B45+D46) -> 1443878.4 | F46: =D46+E46 -> -568693.45 | G46: 1 | H46: 13.23
A47: 42429 | B47: 92880465 | C47: 0.0189 | D47: =SUM(C47*B46) -> 1504694.3 | E47: =B47-(B46+D47) -> 11762317 | F47: =D47+E47 -> 13267011 | G47: 1 | H47: 13.49
A48: 42460 | B48: 1.015352e+08 | C48: 0.0608 | D48: =SUM(C48*B47) -> 5647132.3 | E48: =B48-(B47+D48) -> 3007598.4 | F48: =D48+E48 -> 8654730.6 | G48: 1 | H48: 14.3
A49: 42489 | B49: =11507772.06+112941.2+90532889.13 -> 1.021536e+08 | C49: -0.014 | D49: =SUM(C49*B48) -> -1421492.7 | E49: =B49-(B48+D49) -> 2039899.7 | F49: =D49+E49 -> 618407 | G49: 1 | H49: 14.1
A50: 42521 | B50: =17765427.26+171062.43+92065880.89 -> 1.1000237e+08 | C50: 0.0191 | D50: =SUM(C50*B49) -> 1951133.8 | E50: =B50-(B49+D50) -> 5897634.4 | F50: =D50+E50 -> 7848768.2 | G50: 1 | H50: 14.37
...

Sheet SGLIX
A1: Date | B1: $$$ | C1: Ret % | D1: Ret $$ | E1: Contribution +/- | F1: Total | G1: Accts | H1: SGLIX NAV | J1: SGLIX | K1: Avg. Assets
J2: 2012 | K2: 0
A3: 42766 | B3: 26074095 | C3: 0.0489 | D3: =SUM(C3*B3) -> 1275023.3 | E3: =B3-(B2+D3) -> 24799072 | F3: =IF(E3>0,E3,E3+D3) -> 24799072 | G3: 1 | H3: 24.26 | J3: 2013 | K3: 0
A4: 42794 | B4: 24556813 | C4: 0.0367 | D4: =SUM(C4*B3) -> 956919.29 | E4: =B4-(B3+D4) -> -2474201.1 | F4: =IF(E4>0,E4,E4+D4) -> -1517281.8 | G4: 1 | H4: 25.15 | J4: 2014 | K4: 0
A5: 42825 | B5: 23502174 | C5: 0.0151 | D5: =SUM(C5*B4) -> 370807.88 | E5: =B5-(B4+D5) -> -1425447.7 | F5: =IF(E5>0,E5,E5+D5) -> -1054639.8 | G5: 1 | J5: 2015 | K5: 0
A6: 42855 | B6: 22855948 | C6: 0.0098 | D6: =SUM(C6*B5) -> 230321.3 | E6: =B6-(B5+D6) -> -876546.54 | F6: =IF(E6>0,E6,E6+D6) -> -646225.24 | G6: 1 | H6: 25.93 | J6: 2016 | K6: 0
A7: 42886 | B7: 22435710 | C7: 0.0275 | D7: =SUM(C7*B6) -> 628538.58 | E7: =B7-(B6+D7) -> -1048776.7 | F7: =IF(E7>0,E7,E7+D7) -> -420238.08 | G7: 1 | H7: 26.49 | J7: 2017 | K7: =AVERAGE(B3:B14) -> 23077221
A8: 42916 | B8: 22484295 | C8: -0.003 | D8: =SUM(C8*B7) -> -67307.131 | E8: =B8-(B7+D8) -> 115891.73 | F8: =IF(E8>0,E8,E8+D8) -> 115891.73 | G8: 1 | H8: 27.05 | J8: 2018
A9: 42947 | B9: 22532879 | C9: 0.011 | D9: =SUM(C9*B8) -> 247327.24 | E9: =B9-(B8+D9) -> -198742.64 | F9: =IF(E9>0,E9,E9+D9) -> 48584.6 | G9: 1 | H9: 27.61 | J9: 2019
A10: 42978 | B10: 22786318 | C10: 0.0191 | D10: =SUM(C10*B9) -> 430378 | E10: =B10-(B9+D10) -> -176938.97 | F10: =IF(E10>0,E10,E10+D10) -> 253439.03 | G10: 1 | H10: 27.21 | J10: 2020
A11: 43008 | B11: 22416582 | C11: 0.0129 | D11: =SUM(C11*B10) -> 293943.51 | E11: =B11-(B10+D11) -> -663679.78 | F11: =IF(E11>0,E11,E11+D11) -> -369736.27 | G11: 1 | H11: 27.56
A12: 43039 | B12: 22155044 | C12: 0.0134 | D12: =SUM(C12*B11) -> 300382.2 | E12: =B12-(B11+D12) -> -561920.47 | F12: =IF(E12>0,E12,E12+D12) -> -261538.27 | G12: 1 | H12: 27.93
A13: 43069 | B13: 22545615 | C13: 0.024 | D13: =SUM(C13*B12) -> 531721.05 | E13: =B13-(B12+D13) -> -141150.18 | F13: =IF(E13>0,E13,E13+D13) -> 390570.87 | G13: 1 | H13: 28.6
A14: 43100 | B14: =22581175.32 -> 22581175 | C14: 0.0077 | D14: =SUM(C14*B13) -> 173601.23 | E14: =B14-(B13+D14) -> -138040.66 | F14: =IF(E14>0,E14,E14+D14) -> 35560.57 | G14: 1 | H14: 29.27
A15: 43131 | B15: 22567923 | C15: 0.0399 | D15: =SUM(C15*B14) -> 900988.9 | E15: =B15-(B14+D15) -> -914241.34 | F15: =IF(E15>0,E15,E15+D15) -> -13252.44 | G15: 1
A16: 43159 | B16: 21278277 | C16: -0.0374 | D16: =SUM(C16*B15) -> -844040.32 | E16: =B16-(B15+D16) -> -445605.57 | F16: =IF(E16>0,E16,E16+D16) -> -1289645.9 | G16: 1
A17: 43190 | B17: 20822421 | C17: -0.0042 | D17: =SUM(C17*B16) -> -89368.763 | E17: =B17-(B16+D17) -> -366487.56 | F17: =IF(E17>0,E17,E17+D17) -> -455856.32 | G17: 1 | H17: 28.73
A18: 43220 | B18: 20159723 | C18: -0.009 | D18: =SUM(C18*B17) -> -187401.79 | E18: =B18-(B17+D18) -> -475295.93 | F18: =IF(E18>0,E18,E18+D18) -> -662697.72 | G18: 1
A19: 43251 | B19: 19672503 | C19: 0.0126 | D19: =SUM(C19*B18) -> 254012.51 | E19: =B19-(B18+D19) -> -741232.86 | F19: =IF(E19>0,E19,E19+D19) -> -487220.35 | G19: 1
A20: 43281 | B20: 19437260 | C20: -0.0007 | D20: =SUM(C20*B19) -> -13770.752 | E20: =B20-(B19+D20) -> -221471.8 | F20: =IF(E20>0,E20,E20+D20) -> -235242.55 | G20: 1
A21: 43312 | B21: 19910036 | C21: 0.0364 | D21: =SUM(C21*B20) -> 707516.27 | E21: =B21-(B20+D21) -> -234740.4 | F21: =IF(E21>0,E21,E21+D21) -> 472775.87 | G21: 1
A22: 43343 | B22: 19561940 | C22: 0.0147 | D22: =SUM(C22*B21) -> 292677.53 | E22: =B22-(B21+D22) -> -640773.67 | F22: =IF(E22>0,E22,E22+D22) -> -348096.14 | G22: 1
A23: 43373 | B23: 19452300 | C23: 0.0142 | D23: =SUM(C23*B22) -> 277779.54 | E23: =B23-(B22+D23) -> -387419.27 | F23: =IF(E23>0,E23,E23+D23) -> -109639.73 | G23: 1
A24: 43404 | B24: 18322540 | C24: -0.0576 | D24: =SUM(C24*B23) -> -1120452.5 | E24: =B24-(B23+D24) -> -9307.7671 | F24: =IF(E24>0,E24,E24+D24) -> -1129760.3 | G24: 1
A25: 43434 | B25: 19092665 | C25: 0.0383 | D25: =SUM(C25*B24) -> 701753.27 | E25: =B25-(B24+D25) -> 68371.976 | F25: =IF(E25>0,E25,E25+D25) -> 68371.976 | G25: 1
A26: 43465 | B26: 17632438 | C26: -0.0688 | D26: =SUM(C26*B25) -> -1313575.4 | E26: =B26-(B25+D26) -> -146651.86 | F26: =IF(E26>0,E26,E26+D26) -> -1460227.2 | G26: 1
A27: 43496 | B27: 18474074 | C27: 0.0554 | D27: =SUM(C27*B26) -> 976837.06 | E27: =B27-(B26+D27) -> -135200.39 | F27: =IF(E27>0,E27,E27+D27) -> 841636.67 | G27: 1
A28: 43524 | B28: 19109488 | C28: 0.0391 | D28: =SUM(C28*B27) -> 722336.31 | E28: =B28-(B27+D28) -> -86922.473 | F28: =IF(E28>0,E28,E28+D28) -> 635413.84 | G28: 1
A29: 43555 | B29: 19789283 | C29: 0.0175 | D29: =SUM(C29*B28) -> 334416.05 | E29: =B29-(B28+D29) -> 345378.84 | F29: =IF(E29>0,E29,E29+D29) -> 345378.84 | G29: 1
... A104: 45838 | B104: 95504246 | C104: 0.0105 | D104: =SUM(C104*B103) -> 998130.33 | E104: =B104-(B103+D104) -> -553916.15 | F104: =IF(E104>0,E104,E104+D104) -> 444214.18 | G104: 1
B106: =B104-B101 -> 2159767.9
B107: =B104-B98 -> -8389674.3

Sheet BOGIX
A1: Date | B1: $$$ | C1: Ret % | D1: Ret $$ | E1: Contribution +/- | F1: Total | G1: Accts
A2: 44286 | B2: 85117891 | C2: 0.0214 | G2: 1
A3: 44316 | B3: 86420239 | C3: 0.0244 | D3: =SUM(C3*B2) -> 2076876.5 | E3: =B3-(B2+D3) -> -774529.21 | F3: =IF(E3>0,E3,E3+D3) -> 1302347.3 | G3: 1
A4: 44347 | B4: 86603054 | C4: 0.0153 | D4: =SUM(C4*B3) -> 1322229.7 | E4: =B4-(B3+D4) -> -1139414.6 | F4: =IF(E4>0,E4,E4+D4) -> 182815.03 | G4: 1
A5: 44377 | B5: 86616881 | C5: 0.0107 | D5: =SUM(C5*B4) -> 926652.67 | E5: =B5-(B4+D5) -> -912825.76 | F5: =IF(E5>0,E5,E5+D5) -> 13826.91 | G5: 1
A6: 44408 | B6: 97188135 | C6: -0.0197 | D6: =SUM(C6*B5) -> -1706352.5 | E6: =B6-(B5+D6) -> 12277607 | F6: =IF(E6>0,E6,E6+D6) -> 12277607 | G6: 1
A7: 44439 | B7: 97514328 | C7: -0.0036 | D7: =SUM(C7*B6) -> -349877.29 | E7: =B7-(B6+D7) -> 676070.02 | F7: =IF(E7>0,E7,E7+D7) -> 676070.02 | G7: 1
A8: 44469 | B8: 95675494 | C8: -0.0264 | D8: =SUM(C8*B7) -> -2574378.3 | E8: =B8-(B7+D8) -> 735544.54 | F8: =IF(E8>0,E8,E8+D8) -> 735544.54 | G8: 1
A9: 44500 | B9: 97868978 | C9: 0.0303 | D9: =SUM(C9*B8) -> 2898967.5 | E9: =B9-(B8+D9) -> -705483.21 | F9: =IF(E9>0,E9,E9+D9) -> 2193484.3 | G9: 1
A10: 44530 | B10: 92770074 | C10: -0.0441 | D10: =SUM(C10*B9) -> -4316021.9 | E10: =B10-(B9+D10) -> -782882.57 | F10: =IF(E10>0,E10,E10+D10) -> -5098904.5 | G10: 1
A11: 44561 | B11: 98433397 | C11: 0.0516 | D11: =SUM(C11*B10) -> 4786935.8 | E11: =B11-(B10+D11) -> 876386.85 | F11: =IF(E11>0,E11,E11+D11) -> 876386.85 | G11: 1
A12: 44592 | B12: 91685412 | C12: -0.0703 | D12: =SUM(C12*B11) -> -6919867.8 | E12: =B12-(B11+D12) -> 171882.99 | F12: =IF(E12>0,E12,E12+D12) -> 171882.99 | G12: 1
A13: 44620 | B13: 92340241 | C13: 0.0079 | D13: =SUM(C13*B12) -> 724314.75 | E13: =B13-(B12+D13) -> -69485.213 | F13: =IF(E13>0,E13,E13+D13) -> 654829.54 | G13: 1
A14: 44651 | B14: 94464974 | C14: 0.0007 | D14: =SUM(C14*B13) -> 64638.169 | E14: =B14-(B13+D14) -> 2060094.9 | F14: =IF(E14>0,E14,E14+D14) -> 2060094.9 | G14: 1
... A53: 45838 | B53: 1.1195512e+08 | C53: 0.04 | D53: =SUM(C53*B52) -> 4309629.3 | E53: =B53-(B52+D53) -> -95239.332 | F53: =IF(E53>0,E53,E53+D53) -> 4214389.9 | G53: 1
B55: =B53-B50 -> 6889851.7
B56: =B53-B47 -> -10346092

Sheet FoF
B1: SGPKX | C1: SILVX | D1: SCLVX | E1: SGLIX | F1: BOGIX | G1: DYTA | H1: SGLC | I1: GINX | J1: USDX | K1: QXQ | L1: SGPGX | M1: SILVX | N1: SCLVX | O1: SGLIX | P1: BOGIX | Q1: DYTA | R1: SGLC | S1: GINX | T1: USDX | U1: SGCIX | V1: SILVX | W1: SCLVX | X1: SGLIX | Y1: BOGIX | Z1: DYTA | AA1: SGLC | AB1: Total FoF | AC1: Total SGI Funds | AD1: Total Net SGI Funds | AE1: Accts
A2: 44012 | B2: 5243507.9 | C2: 1362773.2 | D2: 1469657.7 | E2: 1449838.3 | L2: 3665913.1 | M2: 653372.63 | N2: 515529.78 | O2: 729663.35 | U2: 1185811.9 | V2: 77558.35 | W2: 31207.12 | AB2: =B2+L2+U2 -> 10095233 | AC2: =C2+D2+E2+M2+N2+O2+V2+W2 -> 6289600.5 | AD2: =AB2-AC2 -> 3805632.4 | AE2: =COUNT(B2,L2,U2) -> 3
A3: 44043 | B3: 6430391.7 | C3: 1694414.8 | D3: 1795688.9 | E3: 1783764.4 | L3: 5161737 | M3: 930729.03 | N3: 722132.57 | O3: 1029667 | U3: 1250974.7 | V3: 82631.649 | W3: 32718.909 | AB3: =B3+L3+U3 -> 12843103 | AC3: =C3+D3+E3+M3+N3+O3+V3+W3 -> 8071747.2 | AD3: =AB3-AC3 -> 4771356.2 | AE3: =COUNT(B3,L3,U3) -> 3
A4: 44074 | B4: 7260919.2 | C4: 1913578.6 | D4: 1988481 | E4: 2043807.3 | L4: 6401093.8 | M4: 1161698 | N4: 866569.2 | O4: 1306141 | U4: 640961.44 | V4: 42588.346 | W4: 16440.153 | AB4: =B4+L4+U4 -> 14302974 | AC4: =C4+D4+E4+M4+N4+O4+V4+W4 -> 9339303.6 | AD4: =AB4-AC4 -> 4963670.9 | AE4: =COUNT(B4,L4,U4) -> 3
A5: 44104 | B5: 7331031.6 | C5: 1924541 | D5: 2036376.6 | E5: 2030019.6 | L5: 7026846.9 | M5: 1256263.1 | N5: 973394.07 | O5: 1392519.8 | U5: 926236.68 | V5: 60172.49 | W5: 23853.49 | AB5: =B5+L5+U5 -> 15284115 | AC5: =C5+D5+E5+M5+N5+O5+V5+W5 -> 9697140.1 | AD5: =AB5-AC5 -> 5586975.1 | AE5: =COUNT(B5,L5,U5) -> 3
A6: 44135 | B6: 7304706.6 | C6: 1885078.8 | D6: 2063724.6 | E6: 1966067 | L6: 7138324.3 | M6: 1240070.7 | N6: 988286.21 | O6: 1386732.3 | U6: 1366741.2 | V6: 84400.66 | W6: 34307.53 | AB6: =B6+L6+U6 -> 15809772 | AC6: =C6+D6+E6+M6+N6+O6+V6+W6 -> 9648667.7 | AD6: =AB6-AC6 -> 6161104.4 | AE6: =COUNT(B6,L6,U6) -> 3
A7: 44165 | B7: 7204151.6 | C7: 1893515.8 | D7: 1935551.4 | E7: 2047175.6 | L7: 7805988.9 | M7: 1335349.9 | N7: 1030266.5 | O7: 1488754.2 | U7: 1418227.7 | V7: 90335.44 | W7: 35986.19 | AB7: =B7+L7+U7 -> 16428368 | AC7: =C7+D7+E7+M7+N7+O7+V7+W7 -> 9856935.1 | AD7: =AB7-AC7 -> 6571433 | AE7: =COUNT(B7,L7,U7) -> 3
A8: 44196 | B8: 8544130.6 | C8: 2206942.6 | D8: 2336271.7 | E8: 2362829.1 | L8: 8614549.3 | M8: 1534414.6 | N8: 1189503.2 | O8: 1726295.2 | U8: 1344354.6 | V8: 86831.25 | W8: 34332.83 | AB8: =B8+L8+U8 -> 18503035 | AC8: =C8+D8+E8+M8+N8+O8+V8+W8 -> 11477420 | AD8: =AB8-AC8 -> 7025614.1 | AE8: =COUNT(B8,L8,U8) -> 3
A9: 44227 | B9: 8619101 | C9: 2246121.9 | D9: 2410294.5 | E9: 2412384.5 | L9: 8111499.6 | M9: 1425043.1 | N9: 1126825.1 | O9: 1615473 | U9: 1584122.6 | V9: 100688.21 | W9: 40032.2 | AB9: =B9+L9+U9 -> 18314723 | AC9: =C9+D9+E9+M9+N9+O9+V9+W9 -> 11376863 | AD9: =AB9-AC9 -> 6937860.6 | AE9: =COUNT(B9,L9,U9) -> 3
A10: 44255 | B10: 9141695.2 | C10: 1353591.7 | D10: 989603.13 | E10: 2713415.9 | L10: 8473254.7 | M10: 1026227.9 | N10: 617619.86 | O10: 2037470.7 | U10: 1510702.9 | V10: 65514.62 | W10: 14651.07 | X10: 58602.48 | AB10: =B10+L10+U10 -> 19125653 | AC10: =C10+D10+E10+M10+N10+O10+V10+W10+X10 -> 8876697.4 | AD10: =AB10-AC10 -> 10248955 | AE10: =COUNT(B10,L10,U10) -> 3
A11: 44286 | B11: 10276972 | C11: 1539766 | D11: 1120731.1 | E11: 3065599.7 | F11: 1656309.7 | L11: 8696344.2 | M11: 1060929.9 | N11: 623642.75 | O11: 2080365.5 | P11: 522477.8 | U11: 1203612.8 | V11: 55159.95 | W11: 12105.49 | X11: 48266.96 | AB11: =B11+L11+U11 -> 20176929 | AC11: =C11+D11+E11+F11+M11+N11+O11+P11+V11+W11+X11 -> 11785355 | AD11: =AB11-AC11 -> 8391573.7 | AE11: =COUNT(B11,L11,U11) -> 3
A12: 44316 | B12: 11040922 | C12: 1654404.2 | D12: 1212905.3 | E12: 3314103 | F12: 1757284.9 | L12: 9373686.5 | M12: 1121181.7 | N12: 677462.21 | O12: 2222109 | P12: 556752.59 | U12: 1323153.7 | V12: 59129.874 | W12: 13165.306 | X12: 52653.756 | AB12: =B12+L12+U12 -> 21737762 | AC12: =C12+D12+E12+F12+M12+N12+O12+P12+V12+W12+X12 -> 12641152 | AD12: =AB12-AC12 -> 9096610 | AE12: =COUNT(B12,L12,U12) -> 3
A13: 44347 | B13: 10124497 | C13: 1825297.4 | D13: 1113878.5 | E13: 3044178.5 | F13: 1614484.7 | L13: 10519326 | M13: 1263361.4 | N13: 762523.67 | O13: 2501914.4 | P13: 628870.99 | U13: 1331510.5 | V13: 59864.574 | W13: 13108.851 | X13: 53235.907 | AB13: =B13+L13+U13 -> 21975334 | AC13: =C13+D13+E13+F13+M13+N13+O13+P13+V13+W13+X13 -> 12880719 | AD13: =AB13-AC13 -> 9094614.9 | AE13: =COUNT(B13,L13,U13) -> 3
A14: 44377 | B14: 10400682 | C14: 1893872.5 | D14: 1125890.6 | E14: 3096158.2 | F14: 1647734.6 | L14: 10798986 | M14: 1311288.7 | N14: 782327.21 | O14: 2565593 | P14: 655967.3 | U14: 1360338.8 | V14: 61794.85 | W14: 13131.39 | X14: 54145.03 | AB14: =B14+L14+U14 -> 22560006 | AC14: =C14+D14+E14+F14+M14+N14+O14+P14+V14+W14+X14 -> 13207903 | AD14: =AB14-AC14 -> 9352103 | AE14: =COUNT(B14,L14,U14) -> 3
A15: 44408 | B15: 11061990 | C15: 1993064.5 | D15: 675341.23 | E15: 3304396.9 | F15: 2335345.5 | L15: 10745081 | M15: 1294526 | N15: 433960.01 | O15: 2444869.4 | P15: 997235.38 | U15: 1282966.3 | V15: 58114.32 | W15: 0 | X15: 51333.92 | Y15: 12742.41 | AB15: =B15+L15+U15 -> 23090037 | AC15: =C15+D15+E15+F15+M15+N15+O15+P15+V15+W15+X15+Y15 -> 13600930 | AD15: =AB15-AC15 -> 9489107.2 | AE15: =COUNT(B15,L15,U15) -> 3
A16: 44439 | B16: 10960830 | C16: 1969949 | D16: 659773.57 | E16: 3286721.6 | F16: 2304649.1 | L16: 10826797 | M16: 1311872.4 | N16: 436894.65 | O16: 2459759.2 | P16: 1022574.5 | U16: 1408210.9 | V16: 64708.25 | W16: 0 | X16: 56913.15 | Y16: 14581.07 | AB16: =B16+L16+U16 -> 23195838 | AC16: =C16+D16+E16+F16+M16+N16+O16+P16+V16+W16+X16+Y16 -> 13588396 | AD16: =AB16-AC16 -> 9607441.5 | AE16: =COUNT(B16,L16,U16) -> 3
A17: 44469 | B17: 11087050 | C17: 1970257 | D17: 671477.41 | E17: 3313336 | F17: 2380178.4 | L17: 10626489 | M17: 1261188.9 | N17: 431235.67 | O17: 2411288.9 | P17: 1005570.9 | U17: 1311339.3 | V17: 57310.02 | W17: 0 | X17: 51654.5 | Y17: 13226.85 | AB17: =B17+L17+U17 -> 23024878 | AC17: =C17+D17+E17+F17+M17+N17+O17+P17+V17+W17+X17+Y17 -> 13566725 | AD17: =AB17-AC17 -> 9458152.8 | AE17: =COUNT(B17,L17,U17) -> 3
A18: 44500 | B18: 12180601 | C18: 2208110.4 | D18: 728146.89 | E18: 3669031.1 | F18: 2534513 | L18: 11307250 | M18: 1364183.2 | N18: 449535.42 | O18: 2576950.2 | P18: 1033323.6 | U18: 1344280.7 | V18: 62455.91 | W18: 0 | X18: 54423.79 | Y18: 13627.67 | AB18: =B18+L18+U18 -> 24832132 | AC18: =C18+D18+E18+F18+M18+N18+O18+P18+V18+W18+X18+Y18 -> 14694301 | AD18: =AB18-AC18 -> 10137831 | AE18: =COUNT(B18,L18,U18) -> 3
A19: 44530 | B19: 11478437 | C19: 2125484.5 | D19: 704409.88 | E19: 3553492.5 | F19: 2448169.2 | L19: 11377837 | M19: 1432655.2 | N19: 475071.64 | O19: 2723871.8 | P19: 1090552.7 | U19: 1345512.7 | V19: 58520.18 | W19: 0 | X19: 52082.54 | Y19: 13026.45 | AB19: =B19+L19+U19 -> 24201787 | AC19: =C19+D19+E19+F19+M19+N19+O19+P19+V19+W19+X19+Y19 -> 14677337 | AD19: =AB19-AC19 -> 9524450 | AE19: =COUNT(B19,L19,U19) -> 3
A20: 44561 | B20: 13159973 | C20: 2402335.1 | D20: 804201.74 | E20: 3995142.2 | F20: 2811758.6 | L20: 12634564 | M20: 1531414.2 | N20: 517972.09 | O20: 2893751.4 | P20: 1202690.7 | U20: 13237.54 | V20: 0 | W20: 0 | X20: 0 | Y20: 0 | AB20: =B20+L20+U20 -> 25807775 | AC20: =C20+D20+E20+F20+M20+N20+O20+P20+V20+W20+X20+Y20 -> 16159266 | AD20: =AB20-AC20 -> 9648508.5 | AE20: =COUNT(B20,L20,U20) -> 3
