Workbook
Name XTOT_CURRENCY_CHOICES: '[1]Total Return Settings'!$N$7:$N$18
Name XTOT_DIVIDEND_TYPE: '[1]Total Return Settings'!$T$15:$T$16
Name XTOT_DIVIDEND_TYPE_TABLE: '[1]Total Return Settings'!$T$15:$U$16
Name XTOT_END_DATE_CHOICES: '[1]Total Return Settings'!$I$7
Name XTOT_OVERRIDE_FIELDS: #REF!
Name XTOT_OVERRIDE_FIELDS: #REF!
Name XTOT_OVERRIDE_FIELDS: #REF!
Name XTOT_OVERRIDE_FIELDS: #REF!
Name XTOT_OVERRIDE_FIELDS: #REF!
Name XTOT_OVERRIDE_FIELDS: #REF!
Name XTOT_OVERRIDE_FIELDS: #REF!
Name XTOT_OVERRIDE_FIELDS: #REF!
Name XTOT_RETURN_PERIODS_LIST: '[1]Total Return Settings'!$T$7:$T$8
Name XTOT_RETURN_PERIODS_TABLE: '[1]Total Return Settings'!$T$7:$U$8
Name XTOT_START_DATE_CHOICES: '[1]Total Return Settings'!$D$7:$D$18
Name XTOT_START_DATE_TABLE: '[1]Total Return Settings'!$D$7:$E$18
Name XTOT_TICKER: '[1]Total Return Settings'!$U$4

Sheet ChartAdvisorTempSheet

Sheet Returns
A1: Summit Global Investments' Low Volatility Portfolios | H1: Summit Global Investments' Low Volatility Portfolios
A2: ="Performance ending "&MONTH(MAX('LC (Gross)'!A:A))&"/"&DAY(MAX('LC (Gross)'!A:A))&"/"&YEAR(MAX('LC (Gross)'!A:A)) -> Performance ending 12/31/2025 | H2: ="Performance ending "&MONTH(MAX('LC (Gross)'!A:A))&"/"&DAY(MAX('LC (Gross)'!A:A))&"/"&YEAR(MAX('LC (Gross)'!A:A)) -> Performance ending 12/31/2025
A4: =MAX('LC (Gross)'!A:A) -> 46022 | B4: SGI | C4: Bench | D4: Rel | E4: Capture | H4: ="Performance on "&MONTH($A$4)&"/"&DAY($A$4)&"/"&YEAR($A$4) -> Performance on 12/31/2025 | I4: MTD | J4: QTD | K4: YTD | L4: 1 Year | M4: 3 Year | N4: 5 Year | O4: Inception*
A5: US LV (SPX) | B5: =VLOOKUP($A$4,'LC (Gross)'!A:D,4,0) -> -0.050948327 | C5: =VLOOKUP($A$4,'LC (Gross)'!J:K,2,0) -> 0.05917608 | D5: =B5-C5 -> -0.11012441 | E5: =B5/C5 -> -0.8609615 | H5: SGI US Low Volatility Equity | I5: =B5 -> -0.050948327 | J5: =B13 -> 3.6945085 | K5: =B21 -> 9.8795519 | L5: =B29 -> 9.8795519 | M5: =B37 -> 13.639609 | N5: =B45 -> 9.084744 | O5: =B53 -> 12.725923
A6: US LV (RusDef) | B6: =VLOOKUP($A$4,'LC (Gross)'!A:D,4,0) -> -0.050948327 | C6: =VLOOKUP($A$4,'LC (Gross)'!P:Q,2,0) -> -0.8506307 | D6: =B6-C6 -> 0.79968237 | E6: =B6/C6 -> 0.059894766 | H6: S&P 500 Index | I6: =C5 -> 0.05917608 | J6: =C13 -> 2.6529335 | K6: =C21 -> 17.859984 | L6: =C29 -> 17.859984 | M6: =C37 -> 22.982389 | N6: =C45 -> 14.400236 | O6: =C53 -> 13.954857
A7: GLV (ACWI) | B7: =VLOOKUP($A$4,'Global (Gross)'!A:D,4,0) -> 0.357371 | C7: =VLOOKUP($A$4,'Global (Gross)'!J:K,2,0) -> 1.0703 | D7: =B7-C7 -> -0.712929 | E7: =B7/C7 -> 0.33389797 | H7: Value Added | I7: =I5-I6 -> -0.11012441 | J7: =J5-J6 -> 1.041575 | K7: =K5-K6 -> -7.980432 | L7: =L5-L6 -> -7.980432 | M7: =M5-M6 -> -9.3427795 | N7: =N5-N6 -> -5.3154916 | O7: =O5-O6 -> -1.2289342
A8: SCLV (R2000) | B8: =VLOOKUP($A$4,'SC (Gross)'!A:D,4,0) -> #N/A | C8: =VLOOKUP($A$4,'SC (Gross)'!J:K,2,0) -> #N/A | D8: =B8-C8 -> #N/A | E8: =B8/C8 -> #N/A | H8: *Inception date for the SGI Low Volatility Equity composite was February 1, 2011
A9: ITL LV (ACWIxUS) | B9: =VLOOKUP($A$4,ITL!A:D,4,0) -> #N/A | C9: =VLOOKUP($A$4,ITL!J:K,2,0) -> #N/A | D9: =B9-C9 -> #N/A | E9: =B9/C9 -> #N/A
H10: ="Performance on "&MONTH($A$4)&"/"&DAY($A$4)&"/"&YEAR($A$4) -> Performance on 12/31/2025 | I10: MTD | J10: QTD | K10: YTD | L10: 1 Year | M10: 3 Year | N10: 5 Year | O10: Inception*
H11: SGI Global Low Volatility Equity | I11: =B7 -> 0.357371 | J11: =B15 -> 1.486825 | K11: =B23 -> 12.65947 | L11: =B31 -> 12.65947 | M11: =B39 -> 12.376696 | N11: =B47 -> 7.7968755 | O11: =B55 -> 10.047428
A12: QTD | B12: SGI | C12: Bench | D12: Rel | E12: Capture | H12: MSCI ACWI | I12: =C7 -> 1.0703 | J12: =C15 -> 3.3691709 | K12: =C23 -> 22.892597 | L12: =C31 -> 22.892597 | M12: =C39 -> 21.21063 | N12: =C47 -> 11.708136 | O12: =C55 -> 11.033473
A13: US LV (SPX) | B13: =VLOOKUP($A$4,'LC (Gross)'!A:H,7,0) -> 3.6945085 | C13: =VLOOKUP($A$4,'LC (Gross)'!J:N,5,0) -> 2.6529335 | D13: =B13-C13 -> 1.041575 | E13: =B13/C13 -> 1.3926126 | H13: Value Added | I13: =I11-I12 -> -0.712929 | J13: =J11-J12 -> -1.8823459 | K13: =K11-K12 -> -10.233127 | L13: =L11-L12 -> -10.233127 | M13: =M11-M12 -> -8.8339343 | N13: =N11-N12 -> -3.9112605 | O13: =O11-O12 -> -0.98604571
A14: US LV (RusDef) | B14: =VLOOKUP($A$4,'LC (Gross)'!A:H,7,0) -> 3.6945085 | C14: =VLOOKUP($A$4,'LC (Gross)'!P:T,5,0) -> 2.3658665 | D14: =B14-C14 -> 1.3286421 | E14: =B14/C14 -> 1.5615879 | H14: *Inception date for the SGI Global Low Volatility Equity composite was March 1, 2012
A15: GLV (ACWI) | B15: =VLOOKUP($A$4,'Global (Gross)'!A:H,7,0) -> 1.486825 | C15: =VLOOKUP($A$4,'Global (Gross)'!J:N,5,0) -> 3.3691709 | D15: =B15-C15 -> -1.8823459 | E15: =B15/C15 -> 0.44130293
A16: SCLV (R2000) | B16: =VLOOKUP($A$4,'SC (Gross)'!A:H,7,0) -> #N/A | C16: =VLOOKUP($A$4,'SC (Gross)'!J:N,5,0) -> #N/A | D16: =B16-C16 -> #N/A | E16: =B16/C16 -> #N/A | H16: ="Performance on "&MONTH($A$4)&"/"&DAY($A$4)&"/"&YEAR($A$4) -> Performance on 12/31/2025 | I16: MTD | J16: QTD | K16: YTD | L16: 1 Year | M16: 3 Year | N16: 5 Year | O16: Inception*
A17: ITL LV (ACWIxUS) | B17: =VLOOKUP($A$4,ITL!A:H,7,0) -> #N/A | C17: =VLOOKUP($A$4,ITL!J:N,5,0) -> #N/A | D17: =B17-C17 -> #N/A | E17: =B17/C17 -> #N/A | H17: SGI Small Cap Low Volatility Equity | I17: =B8 -> #N/A | J17: =B16 -> #N/A | K17: =B24 -> N/A | L17: =B32 -> 0 | M17: =B40 -> 0.40159714 | N17: =B48 -> 1.530695 | O17: =B56 -> 7.3796506
H18: Russell 2000 | I18: =C8 -> #N/A | J18: =C16 -> #N/A | K18: =C24 -> N/A | L18: =C32 -> 11.526909 | M18: =C40 -> 1.212514 | N18: =C48 -> 7.3756287 | O18: =C56 -> 7.8616628
H19: Value Added | I19: =I17-I18 -> #N/A | J19: =J17-J18 -> #N/A | K19: =K17-K18 -> #VALUE! | L19: =L17-L18 -> -11.526909 | M19: =M17-M18 -> -0.81091681 | N19: =N17-N18 -> -5.8449336 | O19: =O17-O18 -> -0.48201228
A20: YTD | B20: SGI | C20: Bench | D20: Rel | E20: Capture | H20: *Inception date for the SGI Small Cap Low Volatility Equity composite was February 1, 2014
A21: US LV (SPX) | B21: ='LC (Gross)'!D$5 -> 9.8795519 | C21: ='LC (Gross)'!K$5 -> 17.859984 | D21: =B21-C21 -> -7.980432 | E21: =B21/C21 -> 0.5531669
A22: US LV (RusDef) | B22: ='LC (Gross)'!D$5 -> 9.8795519 | C22: ='LC (Gross)'!Q$5 -> 12.246788 | D22: =B22-C22 -> -2.3672359 | E22: =B22/C22 -> 0.80670557 | H22: ="Performance on "&MONTH($A$4)&"/"&DAY($A$4)&"/"&YEAR($A$4) -> Performance on 12/31/2025 | I22: MTD | J22: QTD | K22: YTD | L22: 1 Year | M22: 3 Year | N22: 5 Year | O22: Inception*
A23: GLV (ACWI) | B23: ='Global (Gross)'!D$5 -> 12.65947 | C23: ='Global (Gross)'!K$5 -> 22.892597 | D23: =B23-C23 -> -10.233127 | E23: =B23/C23 -> 0.55299407 | H23: SGI International Low Volatility Equity | I23: =B9 -> #N/A | J23: =B17 -> #N/A | K23: =B25 -> N/A | L23: =B33 -> 0 | M23: =B41 -> 0.32472839 | N23: =B49 -> 3.1715374 | O23: =B57 -> 2.3495971
A24: SCLV (R2000) | B24: ='SC (Gross)'!D$5 -> N/A | C24: ='SC (Gross)'!K$5 -> N/A | D24: =B24-C24 -> #VALUE! | E24: =B24/C24 -> #VALUE! | H24: MSCI ACWIxUS | I24: =C9 -> #N/A | J24: =C17 -> #N/A | K24: =C25 -> N/A | L24: =C33 -> 8.8385128 | M24: =C41 -> 11.230079 | N24: =C49 -> 9.5274798 | O24: =C57 -> 6.5002383
A25: ITL LV (ACWIxUS) | B25: =ITL!D$5 -> N/A | C25: =ITL!K$5 -> N/A | D25: =B25-C25 -> #VALUE! | E25: =B25/C25 -> #VALUE! | H25: Value Added | I25: =I23-I24 -> #N/A | J25: =J23-J24 -> #N/A | K25: =K23-K24 -> #VALUE! | L25: =L23-L24 -> -8.8385128 | M25: =M23-M24 -> -10.905351 | N25: =N23-N24 -> -6.3559424 | O25: =O23-O24 -> -4.1506412
H26: *Inception date for the SGI International Low Volatility Equity composite was March 1, 2015
A28: 1 Year | B28: SGI | C28: Bench | D28: Rel | E28: Capture | H28: Live Data Linked with Model Data
A29: US LV (SPX) | B29: ='LC (Gross)'!D$6 -> 9.8795519 | C29: ='LC (Gross)'!K$6 -> 17.859984 | D29: =B29-C29 -> -7.980432 | E29: =B29/C29 -> 0.5531669
A30: US LV (RusDef) | B30: ='LC (Gross)'!D$6 -> 9.8795519 | C30: ='LC (Gross)'!Q$6 -> 12.246788 | D30: =B30-C30 -> -2.3672359 | E30: =B30/C30 -> 0.80670557
A31: GLV (ACWI) | B31: ='Global (Gross)'!D$6 -> 12.65947 | C31: ='Global (Gross)'!K$6 -> 22.892597 | D31: =B31-C31 -> -10.233127 | E31: =B31/C31 -> 0.55299407
A32: SCLV (R2000) | B32: ='SC (Gross)'!D$6 -> 0 | C32: ='SC (Gross)'!K$6 -> 11.526909 | D32: =B32-C32 -> -11.526909 | E32: =B32/C32 -> 0
A33: ITL LV (ACWIxUS) | B33: =ITL!D$6 -> 0 | C33: =ITL!K$6 -> 8.8385128 | D33: =B33-C33 -> -8.8385128 | E33: =B33/C33 -> 0
A36: 3 Year | B36: SGI | C36: Bench | D36: Rel | E36: Capture
A37: US LV (SPX) | B37: ='LC (Gross)'!D$8 -> 13.639609 | C37: ='LC (Gross)'!K$8 -> 22.982389 | D37: =B37-C37 -> -9.3427795 | E37: =B37/C37 -> 0.59348092
A38: US LV (RusDef) | B38: ='LC (Gross)'!D$8 -> 13.639609 | C38: ='LC (Gross)'!Q$8 -> 16.938916 | D38: =B38-C38 -> -3.2993063 | E38: =B38/C38 -> 0.80522329
A39: GLV (ACWI) | B39: ='Global (Gross)'!D$8 -> 12.376696 | C39: ='Global (Gross)'!K$8 -> 21.21063 | D39: =B39-C39 -> -8.8339343 | E39: =B39/C39 -> 0.58351383
A40: SCLV (R2000) | B40: ='SC (Gross)'!D$8 -> 0.40159714 | C40: ='SC (Gross)'!K$8 -> 1.212514 | D40: =B40-C40 -> -0.81091681 | E40: =B40/C40 -> 0.33121033
A41: ITL LV (ACWIxUS) | B41: =ITL!D$8 -> 0.32472839 | C41: =ITL!K$8 -> 11.230079 | D41: =B41-C41 -> -10.905351 | E41: =B41/C41 -> 0.028915948
A44: 5 Year | B44: SGI | C44: Bench | D44: Rel | E44: Capture
A45: US LV (SPX) | B45: ='LC (Gross)'!D$10 -> 9.084744 | C45: ='LC (Gross)'!K$10 -> 14.400236 | D45: =B45-C45 -> -5.3154916 | E45: =B45/C45 -> 0.63087468
A46: US LV (RusDef) | B46: ='LC (Gross)'!D$10 -> 9.084744 | C46: ='LC (Gross)'!Q$10 -> 11.138063 | D46: =B46-C46 -> -2.0533193 | E46: =B46/C46 -> 0.81564845
...

Sheet LC (Gross)
C1: Large Cap (Gross) | J1: S&P 500® Index | P1: Russell Defensive® Index | W1: S&P 500 Low Volatility Total Return Index
D4: Return | E4: Relative Return | F4: Beta | G4: Alpha | H4: stdevp | K4: Return | L4: Beta | M4: stdevp | Q4: Return | R4: Relative Return | S4: Beta | T4: Alpha | U4: stdevp | X4: Return | Y4: Relative Return | Z4: Beta | AA4: stdevp
B5: 12 | C5: YTD | D5: {=IFERROR((GEOMEAN(1+OFFSET(D$16,MAX($B$16:$B$506)-$B$5+1,0,$B$5,1)/100)^$B$5-1)*100,"N/A")} -> 9.8795519 | E5: =IFERROR(D5-$K5,"N/A") -> -7.980432 | F5: =IFERROR(SLOPE(OFFSET(D$16,MAX($B$16:$B$506)-$B$5+1,0,$B$5,1),OFFSET($K$16,MAX($B$16:$B$506)-$B$5+1,0,$B$5,1)),"N/A") -> 0.30043818 | G5: {=IFERROR(INTERCEPT(OFFSET(D$16,MAX($B$16:$B$506)-$B$5+1,0,$B$5,1),OFFSET($K$16,MAX($B$16:$B$506)-$B$5+1,0,$B$5,1))*12,"N/A")} -> 4.5432835 | H5: =IFERROR(STDEVP(OFFSET(D$16,MAX($B$16:$B$506)-$B$5+1,0,$B$5,1))*SQRT(12),"N/A") -> 6.7090947 | J5: YTD | K5: {=IFERROR((GEOMEAN(1+OFFSET(K$16,MAX($B$16:$B$506)-$B$5+1,0,$B$5,1)/100)^$B$5-1)*100,"N/A")} -> 17.859984 | L5: =IFERROR(SLOPE(OFFSET(K$16,MAX($B$16:$B$506)-$B$5+1,0,$B$5,1),OFFSET($K$16,MAX($B$16:$B$506)-$B$5+1,0,$B$5,1)),"N/A") -> 1 | M5: =IFERROR(STDEVP(OFFSET(K$16,MAX($B$16:$B$506)-$B$5+1,0,$B$5,1))*SQRT(12),"N/A") -> 10.521019 | P5: YTD | Q5: {=IFERROR((GEOMEAN(1+OFFSET(Q$16,MAX($B$16:$B$506)-$B$5+1,0,$B$5,1)/100)^$B$5-1)*100,"N/A")} -> 12.246788 | R5: =IFERROR(Q5-$K5,"N/A") -> -5.6131961 | S5: =IFERROR(SLOPE(OFFSET(Q$16,MAX($B$16:$B$506)-$B$5+1,0,$B$5,1),OFFSET($K$16,MAX($B$16:$B$506)-$B$5+1,0,$B$5,1)),"N/A") -> 0.57084148 | T5: {=IFERROR(INTERCEPT(OFFSET(Q$16,MAX($B$16:$B$506)-$B$5+1,0,$B$5,1),OFFSET($K$16,MAX($B$16:$B$506)-$B$5+1,0,$B$5,1))*12,"N/A")} -> 2.1012202 | U5: =IFERROR(STDEVP(OFFSET(Q$16,MAX($B$16:$B$506)-$B$5+1,0,$B$5,1))*SQRT(12),"N/A") -> 7.1053408 | W5: YTD | X5: {=IFERROR((GEOMEAN(1+OFFSET(X$16,MAX($B$16:$B$506)-$B$5+1,0,$B$5,1)/100)^$B$5-1)*100,"N/A")} -> 4.3575279 | Y5: =IFERROR(X5-$K6,"N/A") -> -13.502456 | Z5: =IFERROR(SLOPE(OFFSET(X$16,MAX($B$16:$B$506)-$B$5+1,0,$B$5,1),OFFSET($K$16,MAX($B$16:$B$506)-$B$5+1,0,$B$5,1)),"N/A") -> -0.080393747 | AA5: =IFERROR(STDEVP(OFFSET(X$16,MAX($B$16:$B$506)-$B$5+1,0,$B$5,1))*SQRT(12),"N/A") -> 8.2295016
C6: One Year | D6: {=IFERROR((GEOMEAN(1+OFFSET(D$16,MAX($B$16:$B$506)-11,0,12,1)/100)^12-1)*100,"N/A")} -> 9.8795519 | E6: =IFERROR(D6-$K6,"N/A") -> -7.980432 | F6: =IFERROR(SLOPE(OFFSET(D$16,MAX($B$16:$B$506)-11,0,12,1),OFFSET($K$16,MAX($B$16:$B$506)-11,0,12,1)),"N/A") -> 0.30043818 | G6: =IFERROR(INTERCEPT(OFFSET(D$16,MAX($B$16:$B$506)-11,0,12,1),OFFSET($K$16,MAX($B$16:$B$506)-11,0,12,1))*12,"N/A") -> 4.5432835 | H6: =IFERROR(STDEVP(OFFSET(D$16,MAX($B$16:$B$506)-11,0,12,1))*SQRT(12),"N/A") -> 6.7090947 | J6: One Year | K6: {=IFERROR((GEOMEAN(1+OFFSET(K$16,MAX($B$16:$B$506)-11,0,12,1)/100)^12-1)*100,"N/A")} -> 17.859984 | L6: =IFERROR(SLOPE(OFFSET(K$16,MAX($B$16:$B$506)-11,0,12,1),OFFSET($K$16,MAX($B$16:$B$506)-11,0,12,1)),"N/A") -> 1 | M6: =IFERROR(STDEVP(OFFSET(K$16,MAX($B$16:$B$506)-11,0,12,1))*SQRT(12),"N/A") -> 10.521019 | P6: One Year | Q6: {=IFERROR((GEOMEAN(1+OFFSET(Q$16,MAX($B$16:$B$506)-11,0,12,1)/100)^12-1)*100,"N/A")} -> 12.246788 | R6: =IFERROR(Q6-$K6,"N/A") -> -5.6131961 | S6: =IFERROR(SLOPE(OFFSET(Q$16,MAX($B$16:$B$506)-11,0,12,1),OFFSET($K$16,MAX($B$16:$B$506)-11,0,12,1)),"N/A") -> 0.57084148 | T6: =IFERROR(INTERCEPT(OFFSET(Q$16,MAX($B$16:$B$506)-11,0,12,1),OFFSET($K$16,MAX($B$16:$B$506)-11,0,12,1))*12,"N/A") -> 2.1012202 | U6: =IFERROR(STDEVP(OFFSET(Q$16,MAX($B$16:$B$506)-11,0,12,1))*SQRT(12),"N/A") -> 7.1053408 | W6: One Year | X6: {=IFERROR((GEOMEAN(1+OFFSET(X$16,MAX($B$16:$B$506)-11,0,12,1)/100)^12-1)*100,"N/A")} -> 4.3575279 | Y6: =IFERROR(X6-$K7,"N/A") -> -17.018744 | Z6: =IFERROR(SLOPE(OFFSET(X$16,MAX($B$16:$B$506)-11,0,12,1),OFFSET($K$16,MAX($B$16:$B$506)-11,0,12,1)),"N/A") -> -0.080393747 | AA6: =IFERROR(STDEVP(OFFSET(X$16,MAX($B$16:$B$506)-11,0,12,1))*SQRT(12),"N/A") -> 8.2295016
C7: Two Year | D7: {=IFERROR((GEOMEAN(1+OFFSET(D$16,MAX($B$16:$B$506)-23,0,24,1)/100)^12-1)*100,"N/A")} -> 14.743645 | E7: =IFERROR(D7-$K7,"N/A") -> -6.6326273 | F7: =IFERROR(SLOPE(OFFSET(D$16,MAX($B$16:$B$506)-23,0,24,1),OFFSET($K$16,MAX($B$16:$B$506)-23,0,24,1)),"N/A") -> 0.67719662 | G7: =IFERROR(INTERCEPT(OFFSET(D$16,MAX($B$16:$B$506)-23,0,24,1),OFFSET($K$16,MAX($B$16:$B$506)-23,0,24,1))*12,"N/A") -> 0.7309049 | H7: =IFERROR(STDEVP(OFFSET(D$16,MAX($B$16:$B$506)-23,0,24,1))*SQRT(12),"N/A") -> 9.9331019 | J7: Two Year | K7: {=IFERROR((GEOMEAN(1+OFFSET(K$16,MAX($B$16:$B$506)-23,0,24,1)/100)^12-1)*100,"N/A")} -> 21.376272 | L7: =IFERROR(SLOPE(OFFSET(K$16,MAX($B$16:$B$506)-23,0,24,1),OFFSET($K$16,MAX($B$16:$B$506)-23,0,24,1)),"N/A") -> 1 | M7: =IFERROR(STDEVP(OFFSET(K$16,MAX($B$16:$B$506)-23,0,24,1))*SQRT(12),"N/A") -> 10.408855 | P7: Two Year | Q7: {=IFERROR((GEOMEAN(1+OFFSET(Q$16,MAX($B$16:$B$506)-23,0,24,1)/100)^12-1)*100,"N/A")} -> 15.342648 | R7: =IFERROR(Q7-$K7,"N/A") -> -6.0336236 | S7: =IFERROR(SLOPE(OFFSET(Q$16,MAX($B$16:$B$506)-23,0,24,1),OFFSET($K$16,MAX($B$16:$B$506)-23,0,24,1)),"N/A") -> 0.70297198 | T7: =IFERROR(INTERCEPT(OFFSET(Q$16,MAX($B$16:$B$506)-23,0,24,1),OFFSET($K$16,MAX($B$16:$B$506)-23,0,24,1))*12,"N/A") -> 0.58014032 | U7: =IFERROR(STDEVP(OFFSET(Q$16,MAX($B$16:$B$506)-23,0,24,1))*SQRT(12),"N/A") -> 8.1174348 | W7: Two Year | X7: {=IFERROR((GEOMEAN(1+OFFSET(X$16,MAX($B$16:$B$506)-23,0,24,1)/100)^12-1)*100,"N/A")} -> 9.1946034 | Y7: =IFERROR(X7-$K8,"N/A") -> -13.787786 | Z7: =IFERROR(SLOPE(OFFSET(X$16,MAX($B$16:$B$506)-23,0,24,1),OFFSET($K$16,MAX($B$16:$B$506)-23,0,24,1)),"N/A") -> 0.36734111 | AA7: =IFERROR(STDEVP(OFFSET(X$16,MAX($B$16:$B$506)-23,0,24,1))*SQRT(12),"N/A") -> 10.053997
C8: Three Year | D8: {=IFERROR((GEOMEAN(1+OFFSET(D$16,MAX($B$16:$B$506)-35,0,36,1)/100)^12-1)*100,"N/A")} -> 13.639609 | E8: =IFERROR(D8-$K8,"N/A") -> -9.3427795 | F8: =IFERROR(SLOPE(OFFSET(D$16,MAX($B$16:$B$506)-35,0,36,1),OFFSET($K$16,MAX($B$16:$B$506)-35,0,36,1)),"N/A") -> 0.68543853 | G8: =IFERROR(INTERCEPT(OFFSET(D$16,MAX($B$16:$B$506)-35,0,36,1),OFFSET($K$16,MAX($B$16:$B$506)-35,0,36,1))*12,"N/A") -> -1.4054295 | H8: =IFERROR(STDEVP(OFFSET(D$16,MAX($B$16:$B$506)-35,0,36,1))*SQRT(12),"N/A") -> 10.184179 | J8: Three Year | K8: {=IFERROR((GEOMEAN(1+OFFSET(K$16,MAX($B$16:$B$506)-35,0,36,1)/100)^12-1)*100,"N/A")} -> 22.982389 | L8: =IFERROR(SLOPE(OFFSET(K$16,MAX($B$16:$B$506)-35,0,36,1),OFFSET($K$16,MAX($B$16:$B$506)-35,0,36,1)),"N/A") -> 1 | M8: =IFERROR(STDEVP(OFFSET(K$16,MAX($B$16:$B$506)-35,0,36,1))*SQRT(12),"N/A") -> 11.787719 | P8: Three Year | Q8: {=IFERROR((GEOMEAN(1+OFFSET(Q$16,MAX($B$16:$B$506)-35,0,36,1)/100)^12-1)*100,"N/A")} -> 16.938916 | R8: =IFERROR(Q8-$K8,"N/A") -> -6.0434732 | S8: =IFERROR(SLOPE(OFFSET(Q$16,MAX($B$16:$B$506)-35,0,36,1),OFFSET($K$16,MAX($B$16:$B$506)-35,0,36,1)),"N/A") -> 0.74561056 | T8: =IFERROR(INTERCEPT(OFFSET(Q$16,MAX($B$16:$B$506)-35,0,36,1),OFFSET($K$16,MAX($B$16:$B$506)-35,0,36,1))*12,"N/A") -> 0.12908565 | U8: =IFERROR(STDEVP(OFFSET(Q$16,MAX($B$16:$B$506)-35,0,36,1))*SQRT(12),"N/A") -> 9.5089491 | W8: Three Year | X8: {=IFERROR((GEOMEAN(1+OFFSET(X$16,MAX($B$16:$B$506)-35,0,36,1)/100)^12-1)*100,"N/A")} -> 6.2917988 | Y8: =IFERROR(X8-$K9,"N/A") -> -4.7936672 | Z8: =IFERROR(SLOPE(OFFSET(X$16,MAX($B$16:$B$506)-35,0,36,1),OFFSET($K$16,MAX($B$16:$B$506)-35,0,36,1)),"N/A") -> 0.48989091 | AA8: =IFERROR(STDEVP(OFFSET(X$16,MAX($B$16:$B$506)-35,0,36,1))*SQRT(12),"N/A") -> 10.468154
C9: Four Year | D9: {=IFERROR((GEOMEAN(1+OFFSET(D$16,MAX($B$16:$B$506)-47,0,48,1)/100)^12-1)*100,"N/A")} -> 6.8430999 | E9: =IFERROR(D9-$K9,"N/A") -> -4.2423661 | F9: =IFERROR(SLOPE(OFFSET(D$16,MAX($B$16:$B$506)-47,0,48,1),OFFSET($K$16,MAX($B$16:$B$506)-47,0,48,1)),"N/A") -> 0.74040922 | G9: =IFERROR(INTERCEPT(OFFSET(D$16,MAX($B$16:$B$506)-47,0,48,1),OFFSET($K$16,MAX($B$16:$B$506)-47,0,48,1))*12,"N/A") -> -1.2109496 | H9: =IFERROR(STDEVP(OFFSET(D$16,MAX($B$16:$B$506)-47,0,48,1))*SQRT(12),"N/A") -> 13.413597 | J9: Four Year | K9: {=IFERROR((GEOMEAN(1+OFFSET(K$16,MAX($B$16:$B$506)-47,0,48,1)/100)^12-1)*100,"N/A")} -> 11.085466 | L9: =IFERROR(SLOPE(OFFSET(K$16,MAX($B$16:$B$506)-47,0,48,1),OFFSET($K$16,MAX($B$16:$B$506)-47,0,48,1)),"N/A") -> 1 | M9: =IFERROR(STDEVP(OFFSET(K$16,MAX($B$16:$B$506)-47,0,48,1))*SQRT(12),"N/A") -> 15.787972 | P9: Four Year | Q9: {=IFERROR((GEOMEAN(1+OFFSET(Q$16,MAX($B$16:$B$506)-47,0,48,1)/100)^12-1)*100,"N/A")} -> 7.5142335 | R9: =IFERROR(Q9-$K9,"N/A") -> -3.5712325 | S9: =IFERROR(SLOPE(OFFSET(Q$16,MAX($B$16:$B$506)-47,0,48,1),OFFSET($K$16,MAX($B$16:$B$506)-47,0,48,1)),"N/A") -> 0.81284932 | T9: =IFERROR(INTERCEPT(OFFSET(Q$16,MAX($B$16:$B$506)-47,0,48,1),OFFSET($K$16,MAX($B$16:$B$506)-47,0,48,1))*12,"N/A") -> -1.4322126 | U9: =IFERROR(STDEVP(OFFSET(Q$16,MAX($B$16:$B$506)-47,0,48,1))*SQRT(12),"N/A") -> 13.386429 | W9: Four Year | X9: {=IFERROR((GEOMEAN(1+OFFSET(X$16,MAX($B$16:$B$506)-47,0,48,1)/100)^12-1)*100,"N/A")} -> 3.4615128 | Y9: =IFERROR(X9-$K10,"N/A") -> -10.938723 | Z9: =IFERROR(SLOPE(OFFSET(X$16,MAX($B$16:$B$506)-47,0,48,1),OFFSET($K$16,MAX($B$16:$B$506)-47,0,48,1)),"N/A") -> 0.55345764 | AA9: =IFERROR(STDEVP(OFFSET(X$16,MAX($B$16:$B$506)-47,0,48,1))*SQRT(12),"N/A") -> 12.138203
C10: Five Year | D10: {=IFERROR((GEOMEAN(1+OFFSET(D$16,MAX($B$16:$B$506)-59,0,60,1)/100)^12-1)*100,"N/A")} -> 9.084744 | E10: =IFERROR(D10-$K10,"N/A") -> -5.3154916 | F10: =IFERROR(SLOPE(OFFSET(D$16,MAX($B$16:$B$506)-59,0,60,1),OFFSET($K$16,MAX($B$16:$B$506)-59,0,60,1)),"N/A") -> 0.779603 | G10: =IFERROR(INTERCEPT(OFFSET(D$16,MAX($B$16:$B$506)-59,0,60,1),OFFSET($K$16,MAX($B$16:$B$506)-59,0,60,1))*12,"N/A") -> -1.8182154 | H10: =IFERROR(STDEVP(OFFSET(D$16,MAX($B$16:$B$506)-59,0,60,1))*SQRT(12),"N/A") -> 13.297042 | J10: Five Year | K10: {=IFERROR((GEOMEAN(1+OFFSET(K$16,MAX($B$16:$B$506)-59,0,60,1)/100)^12-1)*100,"N/A")} -> 14.400236 | L10: =IFERROR(SLOPE(OFFSET(K$16,MAX($B$16:$B$506)-59,0,60,1),OFFSET($K$16,MAX($B$16:$B$506)-59,0,60,1)),"N/A") -> 1 | M10: =IFERROR(STDEVP(OFFSET(K$16,MAX($B$16:$B$506)-59,0,60,1))*SQRT(12),"N/A") -> 14.98254 | P10: Five Year | Q10: {=IFERROR((GEOMEAN(1+OFFSET(Q$16,MAX($B$16:$B$506)-59,0,60,1)/100)^12-1)*100,"N/A")} -> 11.138063 | R10: =IFERROR(Q10-$K10,"N/A") -> -3.2621723 | S10: =IFERROR(SLOPE(OFFSET(Q$16,MAX($B$16:$B$506)-59,0,60,1),OFFSET($K$16,MAX($B$16:$B$506)-59,0,60,1)),"N/A") -> 0.84847872 | T10: =IFERROR(INTERCEPT(OFFSET(Q$16,MAX($B$16:$B$506)-59,0,60,1),OFFSET($K$16,MAX($B$16:$B$506)-59,0,60,1))*12,"N/A") -> -0.93936988 | U10: =IFERROR(STDEVP(OFFSET(Q$16,MAX($B$16:$B$506)-59,0,60,1))*SQRT(12),"N/A") -> 13.30768 | W10: Five Year | X10: {=IFERROR((GEOMEAN(1+OFFSET(X$16,MAX($B$16:$B$506)-59,0,60,1)/100)^12-1)*100,"N/A")} -> 7.349583 | Y10: =IFERROR(X10-$K11,"N/A") -> -7.4537143 | Z10: =IFERROR(SLOPE(OFFSET(X$16,MAX($B$16:$B$506)-59,0,60,1),OFFSET($K$16,MAX($B$16:$B$506)-59,0,60,1)),"N/A") -> 0.61101938 | AA10: =IFERROR(STDEVP(OFFSET(X$16,MAX($B$16:$B$506)-59,0,60,1))*SQRT(12),"N/A") -> 12.625094
C11: Ten Year | D11: {=IFERROR((GEOMEAN(1+OFFSET(D$16,MAX($B$16:$B$506)-119,0,120,1)/100)^12-1)*100,"N/A")} -> 11.300724 | E11: =IFERROR(D11-$K11,"N/A") -> -3.5025738 | F11: =IFERROR(SLOPE(OFFSET(D$16,MAX($B$16:$B$506)-119,0,120,1),OFFSET($K$16,MAX($B$16:$B$506)-119,0,120,1)),"N/A") -> 0.79918135 | G11: =IFERROR(INTERCEPT(OFFSET(D$16,MAX($B$16:$B$506)-119,0,120,1),OFFSET($K$16,MAX($B$16:$B$506)-119,0,120,1))*12,"N/A") -> -0.37666802 | H11: =IFERROR(STDEVP(OFFSET(D$16,MAX($B$16:$B$506)-119,0,120,1))*SQRT(12),"N/A") -> 13.193883 | J11: Ten Year | K11: {=IFERROR((GEOMEAN(1+OFFSET(K$16,MAX($B$16:$B$506)-119,0,120,1)/100)^12-1)*100,"N/A")} -> 14.803297 | L11: =IFERROR(SLOPE(OFFSET(K$16,MAX($B$16:$B$506)-119,0,120,1),OFFSET($K$16,MAX($B$16:$B$506)-119,0,120,1)),"N/A") -> 1 | M11: =IFERROR(STDEVP(OFFSET(K$16,MAX($B$16:$B$506)-119,0,120,1))*SQRT(12),"N/A") -> 15.056111 | P11: Ten Year | Q11: {=IFERROR((GEOMEAN(1+OFFSET(Q$16,MAX($B$16:$B$506)-119,0,120,1)/100)^12-1)*100,"N/A")} -> 12.825832 | R11: =IFERROR(Q11-$K11,"N/A") -> -1.9774654 | S11: =IFERROR(SLOPE(OFFSET(Q$16,MAX($B$16:$B$506)-119,0,120,1),OFFSET($K$16,MAX($B$16:$B$506)-119,0,120,1)),"N/A") -> 0.85660272 | T11: =IFERROR(INTERCEPT(OFFSET(Q$16,MAX($B$16:$B$506)-119,0,120,1),OFFSET($K$16,MAX($B$16:$B$506)-119,0,120,1))*12,"N/A") -> 0.15423806 | U11: =IFERROR(STDEVP(OFFSET(Q$16,MAX($B$16:$B$506)-119,0,120,1))*SQRT(12),"N/A") -> 13.350051 | W11: Ten Year | X11: {=IFERROR((GEOMEAN(1+OFFSET(X$16,MAX($B$16:$B$506)-119,0,120,1)/100)^12-1)*100,"N/A")} -> 8.9173184 | Y11: =IFERROR(X11-$K12,"N/A") -> 0.85041593 | Z11: =IF(P12="N/A","N/A",IFERROR(SLOPE(OFFSET(X$16,MAX($B$16:$B$506)-119,0,120,1),OFFSET($K$16,MAX($B$16:$B$506)-119,0,120,1)),"N/A")) -> 0.6470853 | AA11: =IFERROR(STDEVP(OFFSET(X$16,MAX($B$16:$B$506)-119,0,120,1))*SQRT(12),"N/A") -> 12.473098
C12: Model Incep. | D12: {=IFERROR((GEOMEAN(1+OFFSET(D$16,1,0,MAX($B$16:$B$506),1)/100)^12-1)*100,"N/A")} -> 11.898457 | E12: =IFERROR(D12-$K12,"N/A") -> 3.8315542 | F12: =IFERROR(SLOPE(OFFSET(D$16,1,0,MAX($B$16:$B$506),1),OFFSET($K$16,1,0,MAX($B$16:$B$506),1)),"N/A") -> 0.65366306 | G12: =IFERROR(INTERCEPT(OFFSET(D$16,1,0,MAX($B$16:$B$506),1),OFFSET($K$16,1,0,MAX($B$16:$B$506),1))*12,"N/A") -> 6.1814839 | H12: =IFERROR(STDEVP(OFFSET(D$16,1,0,MAX($B$16:$B$506),1))*SQRT(12),"N/A") -> 12.037363 | J12: Inception | K12: {=IFERROR((GEOMEAN(1+OFFSET(K$16,1,0,MAX($B$16:$B$506),1)/100)^12-1)*100,"N/A")} -> 8.0669024 | L12: =IFERROR(SLOPE(OFFSET(K$16,1,0,MAX($B$16:$B$506),1),OFFSET($K$16,1,0,MAX($B$16:$B$506),1)),"N/A") -> 1 | M12: =IFERROR(STDEVP(OFFSET(K$16,1,0,MAX($B$16:$B$506),1))*SQRT(12),"N/A") -> 15.141943 | P12: Model Incep. | Q12: {=IFERROR((GEOMEAN(1+OFFSET(Q$16,1,0,MAX($B$16:$B$506),1)/100)^12-1)*100,"N/A")} -> 7.1818795 | R12: =IFERROR(Q12-$K12,"N/A") -> -0.88502295 | S12: =IFERROR(SLOPE(OFFSET(Q$16,1,0,MAX($B$16:$B$506),1),OFFSET($K$16,1,0,MAX($B$16:$B$506),1)),"N/A") -> 0.80660002 | T12: =IFERROR(INTERCEPT(OFFSET(Q$16,1,0,MAX($B$16:$B$506),1),OFFSET($K$16,1,0,MAX($B$16:$B$506),1))*12,"N/A") -> 0.56007074 | U12: =IFERROR(STDEVP(OFFSET(Q$16,1,0,MAX($B$16:$B$506),1))*SQRT(12),"N/A") -> 12.724272 | W12: Model Incep. | X12: {=IFERROR((GEOMEAN(1+OFFSET(X$16,1,0,MAX($B$16:$B$506),1)/100)^12-1)*100,"N/A")} -> 9.3867894 | Y12: =IFERROR(X12-$K13,"N/A") -> -4.5680677 | Z12: =IFERROR(SLOPE(OFFSET(X$16,1,0,MAX($B$16:$B$506),1),OFFSET($K$16,1,0,MAX($B$16:$B$506),1)),"N/A") -> 0.58320267 | AA12: =IFERROR(STDEVP(OFFSET(X$16,1,0,MAX($B$16:$B$506),1))*SQRT(12),"N/A") -> 11.687065
C13: Feb'11 Incep. | D13: {=IFERROR((GEOMEAN(1+OFFSET(D$149,1,0,MAX($B$16:$B$506)-133,1)/100)^(MIN(COUNTA(OFFSET(D$149,1,0,MAX($B$16:$B$506)-133,1)),12))-1)*100,"N/A")} -> 12.725923 | E13: =IFERROR(D13-$K13,"N/A") -> -1.2289342 | F13: =IFERROR(SLOPE(OFFSET(D$149,1,0,MAX($B$16:$B$506)-133,1),OFFSET($K$149,1,0,MAX($B$16:$B$506)-133,1)),"N/A") -> 0.72821754 | G13: =IFERROR(INTERCEPT(OFFSET(D$149,1,0,MAX($B$16:$B$506)-133,1),OFFSET($K$149,1,0,MAX($B$16:$B$506)-133,1))*12,"N/A") -> 2.4433103 | H13: =IFERROR(STDEVP(OFFSET(D$149,1,0,MAX($B$16:$B$506)-133,1))*SQRT(12),"N/A") -> 11.705171 | J13: Feb'11 Incep. | K13: {=IFERROR((GEOMEAN(1+OFFSET(K$149,1,0,MAX($B$16:$B$506)-133,1)/100)^(MIN(COUNTA(OFFSET(K$149,1,0,MAX($B$16:$B$506)-133,1)),12))-1)*100,"N/A")} -> 13.954857 | L13: =IFERROR(SLOPE(OFFSET(K$149,1,0,MAX($B$16:$B$506)-133,1),OFFSET($K$149,1,0,MAX($B$16:$B$506)-133,1)),"N/A") -> 1 | M13: =IFERROR(STDEVP(OFFSET(K$149,1,0,MAX($B$16:$B$506)-133,1))*SQRT(12),"N/A") -> 14.03842 | P13: Feb'11 Incep. | Q13: {=IFERROR((GEOMEAN(1+OFFSET(Q$149,1,0,MAX($B$16:$B$506)-133,1)/100)^(MIN(COUNTA(OFFSET(Q$149,1,0,MAX($B$16:$B$506)-133,1)),12))-1)*100,"N/A")} -> 12.932305 | R13: =IFERROR(Q13-$K13,"N/A") -> -1.0225522 | S13: =IFERROR(SLOPE(OFFSET(Q$149,1,0,MAX($B$16:$B$506)-133,1),OFFSET($K$149,1,0,MAX($B$16:$B$506)-133,1)),"N/A") -> 0.84675574 | T13: =IFERROR(INTERCEPT(OFFSET(Q$149,1,0,MAX($B$16:$B$506)-133,1),OFFSET($K$149,1,0,MAX($B$16:$B$506)-133,1))*12,"N/A") -> 1.0242804 | U13: =IFERROR(STDEVP(OFFSET(Q$149,1,0,MAX($B$16:$B$506)-133,1))*SQRT(12),"N/A") -> 12.304197 | W13: Feb'11 Incep. | X13: {=IFERROR((GEOMEAN(1+OFFSET(X$149,1,0,MAX($B$16:$B$506)-133,1)/100)^(MIN(COUNTA(OFFSET(X$149,1,0,MAX($B$16:$B$506)-133,1)),12))-1)*100,"N/A")} -> 10.642852 | Y13: =IFERROR(X13-$K14,"N/A") -> 10.642852 | Z13: =IFERROR(SLOPE(OFFSET(X$102,1,0,MAX($B$16:$B$506)-86,1),OFFSET($K$102,1,0,MAX($B$16:$B$506)-86,1)),"N/A") -> 0.63650071 | AA13: =IFERROR(STDEVP(OFFSET(X$102,1,0,MAX($B$16:$B$506)-86,1))*SQRT(12),"N/A") -> 12.022481 | AC13: Composite Performance
AC14: SILVX | AE14: UNC LC | AG14: Asbestos | AI14: BHI Senior Living (26761461) | AK14: Cynthia Simon-Skjodt (32056582) | AM14: Sisters of St Benedict (42547037) | AO14: French Capital Investors (46872499) | AQ14: St Paul Hermitage (57304051) | AS14: Tony Cercy (79114916) | AU14: Leonardo Locascio (44175471) | AW14: Walter Miller (66237513) | AY14: Composite
A15: Date | B15: # | C15: Porfolio | D15: Gross Return | E15: Growth | F15: Annual | G15: Quarterly | J15: Date | K15: Return | L15: Growth | M15: Annual | N15: Quarterly | P15: Date | Q15: Return | R15: Growth | S15: Annual | T15: Quarterly | AC15: Return | AD15: AUM | AE15: Return | AF15: AUM | AG15: Return | AH15: AUM | AI15: Return | AJ15: AUM | AK15: Return | AL15: AUM | AM15: Return | AN15: AUM | AO15: Return | AP15: AUM | AQ15: Return | AR15: AUM | AS15: Return | AT15: AUM | AU15: Return | AV15: AUM | AW15: Return | AX15: AUM | AY15: Return | AZ15: AUM
A16: 36525 | B16: 0 | E16: 1000000 | J16: =$A16 -> 36525 | L16: 1000000 | P16: =$A16 -> 36525 | R16: 1000000 | W16: =$A16 -> 36525 | Y16: 1000000
A17: 36556 | B17: =IF(A17>A16,1+B16,"-") -> 1 | C17: Model | D17: -4.22 | E17: =E16*D17/100+E16 -> 957800 | J17: =$A17 -> 36556 | K17: -5.0242437 | L17: =L16*K17/100+L16 -> 949757.56 | P17: =$A17 -> 36556 | Q17: -3.7996474 | R17: =R16*Q17/100+R16 -> 962003.53 | W17: =$A17 -> 36556 | X17: -3.5109291 | Y17: =Y16*X17/100+Y16 -> 964890.71
A18: 36585 | B18: =IF(A18>A17,1+B17,"-") -> 2 | C18: Model | D18: -7.58 | E18: =E17*D18/100+E17 -> 885198.76 | J18: =$A18 -> 36585 | K18: -1.8937944 | L18: =L17*K18/100+L17 -> 931771.11 | P18: =$A18 -> 36585 | Q18: -6.7517383 | R18: =R17*Q18/100+R17 -> 897051.57 | W18: =$A18 -> 36585 | X18: -10.51414 | Y18: =Y17*X18/100+Y17 -> 863440.75
A19: 36616 | B19: =IF(A19>A18,1+B18,"-") -> 3 | C19: Model | D19: 13.21 | E19: =E18*D19/100+E18 -> 1002133.5 | G19: =(E19/E16-1)*100 -> 0.21335162 | J19: =$A19 -> 36616 | K19: 9.7830709 | L19: =L18*K19/100+L18 -> 1022926.9 | N19: =(L19/L16-1)*100 -> 2.2926936 | P19: =$A19 -> 36616 | Q19: 10.20982 | R19: =R18*Q19/100+R18 -> 988638.92 | T19: =(R19/R16-1)*100 -> -1.1361085 | W19: =$A19 -> 36616 | X19: 9.3534453 | Y19: =Y18*X19/100+Y18 -> 944202.21 | AA19: =(Y19/Y16-1)*100 -> -5.5797794
A20: 36646 | B20: =IF(A20>A19,1+B19,"-") -> 4 | C20: Model | D20: 3.05 | E20: =E19*D20/100+E19 -> 1032698.6 | J20: =$A20 -> 36646 | K20: -3.0091713 | L20: =L19*K20/100+L19 -> 992145.31 | P20: =$A20 -> 36646 | Q20: -1.0985094 | R20: =R19*Q20/100+R19 -> 977778.62 | W20: =$A20 -> 36646 | X20: 4.7344924 | Y20: =Y19*X20/100+Y19 -> 988905.39
A21: 36677 | B21: =IF(A21>A20,1+B20,"-") -> 5 | C21: Model | D21: 0.28 | E21: =E20*D21/100+E20 -> 1035590.1 | J21: =$A21 -> 36677 | K21: -2.0522676 | L21: =L20*K21/100+L20 -> 971783.84 | P21: =$A21 -> 36677 | Q21: 1.2422987 | R21: =R20*Q21/100+R20 -> 989925.55 | W21: =$A21 -> 36677 | X21: 4.9107001 | Y21: =Y20*X21/100+Y20 -> 1037467.6
A22: 36707 | B22: =IF(A22>A21,1+B21,"-") -> 6 | C22: Model | D22: -0.53 | E22: =E21*D22/100+E21 -> 1030101.5 | G22: =(E22/E19-1)*100 -> 2.7908457 | J22: =$A22 -> 36707 | K22: 2.4652586 | L22: =L21*K22/100+L21 -> 995740.82 | N22: =(L22/L19-1)*100 -> -2.6576791 | P22: =$A22 -> 36707 | Q22: 1.7420177 | R22: =R21*Q22/100+R21 -> 1007170.2 | T22: =(R22/R19-1)*100 -> 1.8744273 | W22: =$A22 -> 36707 | X22: -4.1760746 | Y22: =Y21*X22/100+Y21 -> 994142.15 | AA22: =(Y22/Y19-1)*100 -> 5.2891149
A23: 36738 | B23: =IF(A23>A22,1+B22,"-") -> 7 | C23: Model | D23: -0.47 | E23: =E22*D23/100+E22 -> 1025260 | J23: =$A23 -> 36738 | K23: -1.5573152 | L23: =L22*K23/100+L22 -> 980234 | P23: =$A23 -> 36738 | Q23: -1.0405934 | R23: =R22*Q23/100+R22 -> 996689.69 | W23: =$A23 -> 36738 | X23: 1.3630468 | Y23: =Y22*X23/100+Y22 -> 1007692.8
A24: 36769 | B24: =IF(A24>A23,1+B23,"-") -> 8 | C24: Model | D24: 0.2 | E24: =E23*D24/100+E23 -> 1027310.6 | J24: =$A24 -> 36769 | K24: 6.2114813 | L24: =L23*K24/100+L23 -> 1041121 | P24: =$A24 -> 36769 | Q24: 4.1027128 | R24: =R23*Q24/100+R23 -> 1037581 | W24: =$A24 -> 36769 | X24: 7.4544539 | Y24: =Y23*X24/100+Y23 -> 1082810.8
A25: 36799 | B25: =IF(A25>A24,1+B24,"-") -> 9 | C25: Model | D25: 4.74 | E25: =E24*D25/100+E24 -> 1076005.1 | G25: =(E25/E22-1)*100 -> 4.4562174 | J25: =$A25 -> 36799 | K25: -5.2795736 | L25: =L24*K25/100+L24 -> 986154.3 | N25: =(L25/L22-1)*100 -> -0.96275291 | P25: =$A25 -> 36799 | Q25: -2.4192023 | R25: =R24*Q25/100+R24 -> 1012479.8 | T25: =(R25/R22-1)*100 -> 0.52717843 | W25: =$A25 -> 36799 | X25: 3.158566 | Y25: =Y24*X25/100+Y24 -> 1117012.1 | AA25: =(Y25/Y22-1)*100 -> 12.35939
A26: 36830 | B26: =IF(A26>A25,1+B25,"-") -> 10 | C26: Model | D26: 1.04 | E26: =E25*D26/100+E25 -> 1087195.5 | J26: =$A26 -> 36830 | K26: -0.42330523 | L26: =L25*K26/100+L25 -> 981979.85 | P26: =$A26 -> 36830 | Q26: 2.9561552 | R26: =R25*Q26/100+R25 -> 1042410.3 | W26: =$A26 -> 36830 | X26: 2.3517126 | Y26: =Y25*X26/100+Y25 -> 1143281
A27: 36860 | B27: =IF(A27>A26,1+B26,"-") -> 11 | C27: Model | D27: 0.83 | E27: =E26*D27/100+E26 -> 1096219.3 | J27: =$A27 -> 36860 | K27: -7.8835014 | L27: =L26*K27/100+L26 -> 904565.46 | P27: =$A27 -> 36860 | Q27: -3.6785295 | R27: =R26*Q27/100+R26 -> 1004064.9 | W27: =$A27 -> 36860 | X27: 1.7025759 | Y27: =Y26*X27/100+Y26 -> 1162746.2
A28: 36891 | B28: =IF(A28>A27,1+B27,"-") -> 12 | C28: Model | D28: 6.43 | E28: =E27*D28/100+E27 -> 1166706.2 | F28: =(E28-E16)/E16*100 -> 16.670615 | G28: =(E28/E25-1)*100 -> 8.429428 | J28: =$A28 -> 36891 | K28: 0.48873135 | L28: =L27*K28/100+L27 -> 908986.35 | M28: =(L28-L16)/L16*100 -> -9.1013646 | N28: =(L28/L25-1)*100 -> -7.8251388 | P28: =$A28 -> 36891 | Q28: -0.62846487 | R28: =R27*Q28/100+R27 -> 997754.73 | S28: =(R28-R16)/R16*100 -> -0.22452737 | T28: =(R28/R25-1)*100 -> -1.4543589 | W28: =$A28 -> 36891 | X28: 7.5325175 | Y28: =Y27*X28/100+Y27 -> 1250330.3 | AA28: =(Y28/Y25-1)*100 -> 11.935252
A29: 36922 | B29: =IF(A29>A28,1+B28,"-") -> 13 | C29: Model | D29: -0.62 | E29: =E28*D29/100+E28 -> 1159472.6 | J29: =$A29 -> 36922 | K29: 3.5478697 | L29: =L28*K29/100+L28 -> 941236 | P29: =$A29 -> 36922 | Q29: -0.34175608 | R29: =R28*Q29/100+R28 -> 994344.84 | W29: =$A29 -> 36922 | X29: -4.3133685 | Y29: =Y28*X29/100+Y28 -> 1196398.9
A30: 36950 | B30: =IF(A30>A29,1+B29,"-") -> 14 | C30: Model | D30: 2.02 | E30: =E29*D30/100+E29 -> 1182893.9 | J30: =$A30 -> 36950 | K30: -9.1189455 | L30: =L29*K30/100+L29 -> 855405.21 | P30: =$A30 -> 36950 | Q30: -4.5916623 | R30: =R29*Q30/100+R29 -> 948687.88 | W30: =$A30 -> 36950 | X30: 2.8779234 | Y30: =Y29*X30/100+Y29 -> 1230830.3
A31: 36981 | B31: =IF(A31>A30,1+B30,"-") -> 15 | C31: Model | D31: -2.11 | E31: =E30*D31/100+E30 -> 1157934.9 | G31: =(E31/E28-1)*100 -> -0.75179974 | J31: =$A31 -> 36981 | K31: -6.334973 | L31: =L30*K31/100+L30 -> 801215.52 | N31: =(L31/L28-1)*100 -> -11.856155 | P31: =$A31 -> 36981 | Q31: -5.3831855 | R31: =R30*Q31/100+R30 -> 897618.25 | T31: =(R31/R28-1)*100 -> -10.036181 | W31: =$A31 -> 36981 | X31: -1.2489882 | Y31: =Y30*X31/100+Y30 -> 1215457.4 | AA31: =(Y31/Y28-1)*100 -> -2.7890897
A32: 37011 | B32: =IF(A32>A31,1+B31,"-") -> 16 | C32: Model | D32: 6.72 | E32: =E31*D32/100+E31 -> 1235748.1 | J32: =$A32 -> 37011 | K32: 7.7701831 | L32: =L31*K32/100+L31 -> 863471.43 | P32: =$A32 -> 37011 | Q32: 6.6005994 | R32: =R31*Q32/100+R31 -> 956866.44 | W32: =$A32 -> 37011 | X32: 5.2440859 | Y32: =Y31*X32/100+Y31 -> 1279197.1
A33: 37042 | B33: =IF(A33>A32,1+B32,"-") -> 17 | C33: Model | D33: 3.17 | E33: =E32*D33/100+E32 -> 1274921.3 | J33: =$A33 -> 37042 | K33: 0.66989034 | L33: =L32*K33/100+L32 -> 869255.74 | P33: =$A33 -> 37042 | Q33: 0.99856242 | R33: =R32*Q33/100+R32 -> 966421.35 | W33: =$A33 -> 37042 | X33: 3.6247619 | Y33: =Y32*X33/100+Y32 -> 1325564.9
A34: 37072 | B34: =IF(A34>A33,1+B33,"-") -> 18 | C34: Model | D34: 0.07 | E34: =E33*D34/100+E33 -> 1275813.7 | G34: =(E34/E31-1)*100 -> 10.180096 | J34: =$A34 -> 37072 | K34: -2.4345302 | L34: =L33*K34/100+L33 -> 848093.45 | N34: =(L34/L31-1)*100 -> 5.8508516 | P34: =$A34 -> 37072 | Q34: -2.5146445 | R34: =R33*Q34/100+R33 -> 942119.28 | T34: =(R34/R31-1)*100 -> 4.957679 | W34: =$A34 -> 37072 | X34: -2.4726242 | Y34: =Y33*X34/100+Y33 -> 1292788.7 | AA34: =(Y34/Y31-1)*100 -> 6.3623158
A35: 37103 | B35: =IF(A35>A34,1+B34,"-") -> 19 | C35: Model | D35: -1.65 | E35: =E34*D35/100+E34 -> 1254762.8 | J35: =$A35 -> 37103 | K35: -0.98539293 | L35: =L34*K35/100+L34 -> 839736.4 | P35: =$A35 -> 37103 | Q35: -0.10469571 | R35: =R34*Q35/100+R34 -> 941132.93 | W35: =$A35 -> 37103 | X35: -0.39044209 | Y35: =Y34*X35/100+Y34 -> 1287741.1
A36: 37134 | B36: =IF(A36>A35,1+B35,"-") -> 20 | C36: Model | D36: -0.23 | E36: =E35*D36/100+E35 -> 1251876.9 | J36: =$A36 -> 37134 | K36: -6.259903 | L36: =L35*K36/100+L35 -> 787169.71 | P36: =$A36 -> 37134 | Q36: -4.1201586 | R36: =R35*Q36/100+R35 -> 902356.76 | W36: =$A36 -> 37134 | X36: 0.053862557 | Y36: =Y35*X36/100+Y35 -> 1288434.7
A37: 37164 | B37: =IF(A37>A36,1+B36,"-") -> 21 | C37: Model | D37: -3.34 | E37: =E36*D37/100+E36 -> 1210064.2 | G37: =(E37/E34-1)*100 -> -5.1535398 | J37: =$A37 -> 37164 | K37: -8.0765443 | L37: =L36*K37/100+L36 -> 723593.6 | N37: =(L37/L34-1)*100 -> -14.679968 | P37: =$A37 -> 37164 | Q37: -3.6734538 | R37: =R36*Q37/100+R36 -> 869209.1 | T37: =(R37/R34-1)*100 -> -7.738955 | W37: =$A37 -> 37164 | X37: -4.6035036 | Y37: =Y36*X37/100+Y36 -> 1229121.5 | AA37: =(Y37/Y34-1)*100 -> -4.9247893
A38: 37195 | B38: =IF(A38>A37,1+B37,"-") -> 22 | C38: Model | D38: -0.02 | E38: =E37*D38/100+E37 -> 1209822.2 | J38: =$A38 -> 37195 | K38: 1.9053654 | L38: =L37*K38/100+L37 -> 737380.7 | P38: =$A38 -> 37195 | Q38: -0.19510438 | R38: =R37*Q38/100+R37 -> 867513.23 | W38: =$A38 -> 37195 | X38: -0.78952634 | Y38: =Y37*X38/100+Y37 -> 1219417.3
A39: 37225 | B39: =IF(A39>A38,1+B38,"-") -> 23 | C39: Model | D39: 4.74 | E39: =E38*D39/100+E38 -> 1267167.7 | J39: =$A39 -> 37225 | K39: 7.6715489 | L39: =L38*K39/100+L38 -> 793949.23 | P39: =$A39 -> 37225 | Q39: 4.7526157 | R39: =R38*Q39/100+R38 -> 908742.8 | W39: =$A39 -> 37225 | X39: 3.395764 | Y39: =Y38*X39/100+Y38 -> 1260825.8
A40: 37256 | B40: =IF(A40>A39,1+B39,"-") -> 24 | C40: Model | D40: 4.02 | E40: =E39*D40/100+E39 -> 1318107.9 | F40: =(E40-E28)/E28*100 -> 12.976851 | G40: =(E40/E37-1)*100 -> 8.9287579 | J40: =$A40 -> 37256 | K40: 0.87621202 | L40: =L39*K40/100+L39 -> 800905.9 | M40: =(L40-L28)/L28*100 -> -11.890217 | N40: =(L40/L37-1)*100 -> 10.684492 | P40: =$A40 -> 37256 | Q40: 1.2979157 | R40: =R39*Q40/100+R39 -> 920537.52 | S40: =(R40-R28)/R28*100 -> -7.7390972 | T40: =(R40/R37-1)*100 -> 5.9051868 | W40: =$A40 -> 37256 | X40: 3.5005376 | Y40: =Y39*X40/100+Y39 -> 1304961.5 | AA40: =(Y40/Y37-1)*100 -> 6.1702586
A41: 37287 | B41: =IF(A41>A40,1+B40,"-") -> 25 | C41: Model | D41: -1.85 | E41: =E40*D41/100+E40 -> 1293722.9 | J41: =$A41 -> 37287 | K41: -1.4591355 | L41: =L40*K41/100+L40 -> 789219.6 | P41: =$A41 -> 37287 | Q41: -0.83238713 | R41: =R40*Q41/100+R40 -> 912875.08 | W41: =$A41 -> 37287 | X41: -0.24498138 | Y41: =Y40*X41/100+Y40 -> 1301764.6
A42: 37315 | B42: =IF(A42>A41,1+B41,"-") -> 26 | C42: Model | D42: 1.34 | E42: =E41*D42/100+E41 -> 1311058.8 | J42: =$A42 -> 37315 | K42: -1.9299633 | L42: =L41*K42/100+L41 -> 773987.95 | P42: =$A42 -> 37315 | Q42: 1.1064504 | R42: =R41*Q42/100+R41 -> 922975.59 | W42: =$A42 -> 37315 | X42: 2.6350525 | Y42: =Y41*X42/100+Y41 -> 1336066.8
...

Sheet LC (Net)
C1: Large Cap (Net) | J1: S&P 500® Index | P1: Russell Defensive® Index | W1: S&P 500 Low Volatility Total Return Index
D4: Return | E4: Relative Return | F4: Beta | G4: Alpha | H4: stdevp | K4: Return | L4: Beta | M4: stdevp | Q4: Return | R4: Relative Return | S4: Beta | T4: Alpha | U4: stdevp | X4: Return | Y4: Relative Return | Z4: Beta | AA4: stdevp
B5: 12 | C5: YTD | D5: {=IFERROR((GEOMEAN(1+OFFSET(D$16,MAX($B$16:$B$506)-$B$5+1,0,$B$5,1)/100)^$B$5-1)*100,"N/A")} -> 9.0771338 | E5: =IFERROR(D5-$K5,"N/A") -> -8.7828501 | F5: =IFERROR(SLOPE(OFFSET(D$16,MAX($B$16:$B$506)-$B$5+1,0,$B$5,1),OFFSET($K$16,MAX($B$16:$B$506)-$B$5+1,0,$B$5,1)),"N/A") -> 0.30071459 | G5: {=IFERROR(INTERCEPT(OFFSET(D$16,MAX($B$16:$B$506)-$B$5+1,0,$B$5,1),OFFSET($K$16,MAX($B$16:$B$506)-$B$5+1,0,$B$5,1))*12,"N/A")} -> 3.8005156 | H5: =IFERROR(STDEVP(OFFSET(D$16,MAX($B$16:$B$506)-$B$5+1,0,$B$5,1))*SQRT(12),"N/A") -> 6.7137267 | J5: YTD | K5: {=IFERROR((GEOMEAN(1+OFFSET(K$16,MAX($B$16:$B$506)-$B$5+1,0,$B$5,1)/100)^$B$5-1)*100,"N/A")} -> 17.859984 | L5: =IFERROR(SLOPE(OFFSET(K$16,MAX($B$16:$B$506)-$B$5+1,0,$B$5,1),OFFSET($K$16,MAX($B$16:$B$506)-$B$5+1,0,$B$5,1)),"N/A") -> 1 | M5: =IFERROR(STDEVP(OFFSET(K$16,MAX($B$16:$B$506)-$B$5+1,0,$B$5,1))*SQRT(12),"N/A") -> 10.521019 | P5: YTD | Q5: {=IFERROR((GEOMEAN(1+OFFSET(Q$16,MAX($B$16:$B$506)-$B$5+1,0,$B$5,1)/100)^$B$5-1)*100,"N/A")} -> 12.246788 | R5: =IFERROR(Q5-$K5,"N/A") -> -5.6131961 | S5: =IFERROR(SLOPE(OFFSET(Q$16,MAX($B$16:$B$506)-$B$5+1,0,$B$5,1),OFFSET($K$16,MAX($B$16:$B$506)-$B$5+1,0,$B$5,1)),"N/A") -> 0.57084148 | T5: {=IFERROR(INTERCEPT(OFFSET(Q$16,MAX($B$16:$B$506)-$B$5+1,0,$B$5,1),OFFSET($K$16,MAX($B$16:$B$506)-$B$5+1,0,$B$5,1))*12,"N/A")} -> 2.1012202 | U5: =IFERROR(STDEVP(OFFSET(Q$16,MAX($B$16:$B$506)-$B$5+1,0,$B$5,1))*SQRT(12),"N/A") -> 7.1053408 | W5: YTD | X5: {=IFERROR((GEOMEAN(1+OFFSET(X$16,MAX($B$16:$B$506)-$B$5+1,0,$B$5,1)/100)^$B$5-1)*100,"N/A")} -> 4.3575279 | Y5: =IFERROR(X5-$K6,"N/A") -> -13.502456 | Z5: =IFERROR(SLOPE(OFFSET(X$16,MAX($B$16:$B$506)-$B$5+1,0,$B$5,1),OFFSET($K$16,MAX($B$16:$B$506)-$B$5+1,0,$B$5,1)),"N/A") -> -0.080393747 | AA5: =IFERROR(STDEVP(OFFSET(X$16,MAX($B$16:$B$506)-$B$5+1,0,$B$5,1))*SQRT(12),"N/A") -> 8.2295016
C6: One Year | D6: {=IFERROR((GEOMEAN(1+OFFSET(D$16,MAX($B$16:$B$506)-11,0,12,1)/100)^12-1)*100,"N/A")} -> 9.0771338 | E6: =IFERROR(D6-$K6,"N/A") -> -8.7828501 | F6: =IFERROR(SLOPE(OFFSET(D$16,MAX($B$16:$B$506)-11,0,12,1),OFFSET($K$16,MAX($B$16:$B$506)-11,0,12,1)),"N/A") -> 0.30071459 | G6: =IFERROR(INTERCEPT(OFFSET(D$16,MAX($B$16:$B$506)-11,0,12,1),OFFSET($K$16,MAX($B$16:$B$506)-11,0,12,1))*12,"N/A") -> 3.8005156 | H6: =IFERROR(STDEVP(OFFSET(D$16,MAX($B$16:$B$506)-11,0,12,1))*SQRT(12),"N/A") -> 6.7137267 | J6: One Year | K6: {=IFERROR((GEOMEAN(1+OFFSET(K$16,MAX($B$16:$B$506)-11,0,12,1)/100)^12-1)*100,"N/A")} -> 17.859984 | L6: =IFERROR(SLOPE(OFFSET(K$16,MAX($B$16:$B$506)-11,0,12,1),OFFSET($K$16,MAX($B$16:$B$506)-11,0,12,1)),"N/A") -> 1 | M6: =IFERROR(STDEVP(OFFSET(K$16,MAX($B$16:$B$506)-11,0,12,1))*SQRT(12),"N/A") -> 10.521019 | P6: One Year | Q6: {=IFERROR((GEOMEAN(1+OFFSET(Q$16,MAX($B$16:$B$506)-11,0,12,1)/100)^12-1)*100,"N/A")} -> 12.246788 | R6: =IFERROR(Q6-$K6,"N/A") -> -5.6131961 | S6: =IFERROR(SLOPE(OFFSET(Q$16,MAX($B$16:$B$506)-11,0,12,1),OFFSET($K$16,MAX($B$16:$B$506)-11,0,12,1)),"N/A") -> 0.57084148 | T6: =IFERROR(INTERCEPT(OFFSET(Q$16,MAX($B$16:$B$506)-11,0,12,1),OFFSET($K$16,MAX($B$16:$B$506)-11,0,12,1))*12,"N/A") -> 2.1012202 | U6: =IFERROR(STDEVP(OFFSET(Q$16,MAX($B$16:$B$506)-11,0,12,1))*SQRT(12),"N/A") -> 7.1053408 | W6: One Year | X6: {=IFERROR((GEOMEAN(1+OFFSET(X$16,MAX($B$16:$B$506)-11,0,12,1)/100)^12-1)*100,"N/A")} -> 4.3575279 | Y6: =IFERROR(X6-$K7,"N/A") -> -17.018744 | Z6: =IFERROR(SLOPE(OFFSET(X$16,MAX($B$16:$B$506)-11,0,12,1),OFFSET($K$16,MAX($B$16:$B$506)-11,0,12,1)),"N/A") -> -0.080393747 | AA6: =IFERROR(STDEVP(OFFSET(X$16,MAX($B$16:$B$506)-11,0,12,1))*SQRT(12),"N/A") -> 8.2295016
C7: Two Year | D7: {=IFERROR((GEOMEAN(1+OFFSET(D$16,MAX($B$16:$B$506)-23,0,24,1)/100)^12-1)*100,"N/A")} -> 13.990405 | E7: =IFERROR(D7-$K7,"N/A") -> -7.3858675 | F7: =IFERROR(SLOPE(OFFSET(D$16,MAX($B$16:$B$506)-23,0,24,1),OFFSET($K$16,MAX($B$16:$B$506)-23,0,24,1)),"N/A") -> 0.67863175 | G7: =IFERROR(INTERCEPT(OFFSET(D$16,MAX($B$16:$B$506)-23,0,24,1),OFFSET($K$16,MAX($B$16:$B$506)-23,0,24,1))*12,"N/A") -> 0.037018484 | H7: =IFERROR(STDEVP(OFFSET(D$16,MAX($B$16:$B$506)-23,0,24,1))*SQRT(12),"N/A") -> 9.9401748 | J7: Two Year | K7: {=IFERROR((GEOMEAN(1+OFFSET(K$16,MAX($B$16:$B$506)-23,0,24,1)/100)^12-1)*100,"N/A")} -> 21.376272 | L7: =IFERROR(SLOPE(OFFSET(K$16,MAX($B$16:$B$506)-23,0,24,1),OFFSET($K$16,MAX($B$16:$B$506)-23,0,24,1)),"N/A") -> 1 | M7: =IFERROR(STDEVP(OFFSET(K$16,MAX($B$16:$B$506)-23,0,24,1))*SQRT(12),"N/A") -> 10.408855 | P7: Two Year | Q7: {=IFERROR((GEOMEAN(1+OFFSET(Q$16,MAX($B$16:$B$506)-23,0,24,1)/100)^12-1)*100,"N/A")} -> 15.342648 | R7: =IFERROR(Q7-$K7,"N/A") -> -6.0336236 | S7: =IFERROR(SLOPE(OFFSET(Q$16,MAX($B$16:$B$506)-23,0,24,1),OFFSET($K$16,MAX($B$16:$B$506)-23,0,24,1)),"N/A") -> 0.70297198 | T7: =IFERROR(INTERCEPT(OFFSET(Q$16,MAX($B$16:$B$506)-23,0,24,1),OFFSET($K$16,MAX($B$16:$B$506)-23,0,24,1))*12,"N/A") -> 0.58014032 | U7: =IFERROR(STDEVP(OFFSET(Q$16,MAX($B$16:$B$506)-23,0,24,1))*SQRT(12),"N/A") -> 8.1174348 | W7: Two Year | X7: {=IFERROR((GEOMEAN(1+OFFSET(X$16,MAX($B$16:$B$506)-23,0,24,1)/100)^12-1)*100,"N/A")} -> 9.1946034 | Y7: =IFERROR(X7-$K8,"N/A") -> -13.787786 | Z7: =IFERROR(SLOPE(OFFSET(X$16,MAX($B$16:$B$506)-23,0,24,1),OFFSET($K$16,MAX($B$16:$B$506)-23,0,24,1)),"N/A") -> 0.36734111 | AA7: =IFERROR(STDEVP(OFFSET(X$16,MAX($B$16:$B$506)-23,0,24,1))*SQRT(12),"N/A") -> 10.053997
C8: Three Year | D8: {=IFERROR((GEOMEAN(1+OFFSET(D$16,MAX($B$16:$B$506)-35,0,36,1)/100)^12-1)*100,"N/A")} -> 12.883268 | E8: =IFERROR(D8-$K8,"N/A") -> -10.099121 | F8: =IFERROR(SLOPE(OFFSET(D$16,MAX($B$16:$B$506)-35,0,36,1),OFFSET($K$16,MAX($B$16:$B$506)-35,0,36,1)),"N/A") -> 0.68622583 | G8: =IFERROR(INTERCEPT(OFFSET(D$16,MAX($B$16:$B$506)-35,0,36,1),OFFSET($K$16,MAX($B$16:$B$506)-35,0,36,1))*12,"N/A") -> -2.0963514 | H8: =IFERROR(STDEVP(OFFSET(D$16,MAX($B$16:$B$506)-35,0,36,1))*SQRT(12),"N/A") -> 10.189435 | J8: Three Year | K8: {=IFERROR((GEOMEAN(1+OFFSET(K$16,MAX($B$16:$B$506)-35,0,36,1)/100)^12-1)*100,"N/A")} -> 22.982389 | L8: =IFERROR(SLOPE(OFFSET(K$16,MAX($B$16:$B$506)-35,0,36,1),OFFSET($K$16,MAX($B$16:$B$506)-35,0,36,1)),"N/A") -> 1 | M8: =IFERROR(STDEVP(OFFSET(K$16,MAX($B$16:$B$506)-35,0,36,1))*SQRT(12),"N/A") -> 11.787719 | P8: Three Year | Q8: {=IFERROR((GEOMEAN(1+OFFSET(Q$16,MAX($B$16:$B$506)-35,0,36,1)/100)^12-1)*100,"N/A")} -> 16.938916 | R8: =IFERROR(Q8-$K8,"N/A") -> -6.0434732 | S8: =IFERROR(SLOPE(OFFSET(Q$16,MAX($B$16:$B$506)-35,0,36,1),OFFSET($K$16,MAX($B$16:$B$506)-35,0,36,1)),"N/A") -> 0.74561056 | T8: =IFERROR(INTERCEPT(OFFSET(Q$16,MAX($B$16:$B$506)-35,0,36,1),OFFSET($K$16,MAX($B$16:$B$506)-35,0,36,1))*12,"N/A") -> 0.12908565 | U8: =IFERROR(STDEVP(OFFSET(Q$16,MAX($B$16:$B$506)-35,0,36,1))*SQRT(12),"N/A") -> 9.5089491 | W8: Three Year | X8: {=IFERROR((GEOMEAN(1+OFFSET(X$16,MAX($B$16:$B$506)-35,0,36,1)/100)^12-1)*100,"N/A")} -> 6.2917988 | Y8: =IFERROR(X8-$K9,"N/A") -> -4.7936672 | Z8: =IFERROR(SLOPE(OFFSET(X$16,MAX($B$16:$B$506)-35,0,36,1),OFFSET($K$16,MAX($B$16:$B$506)-35,0,36,1)),"N/A") -> 0.48989091 | AA8: =IFERROR(STDEVP(OFFSET(X$16,MAX($B$16:$B$506)-35,0,36,1))*SQRT(12),"N/A") -> 10.468154
C9: Four Year | D9: {=IFERROR((GEOMEAN(1+OFFSET(D$16,MAX($B$16:$B$506)-47,0,48,1)/100)^12-1)*100,"N/A")} -> 6.1061404 | E9: =IFERROR(D9-$K9,"N/A") -> -4.9793256 | F9: =IFERROR(SLOPE(OFFSET(D$16,MAX($B$16:$B$506)-47,0,48,1),OFFSET($K$16,MAX($B$16:$B$506)-47,0,48,1)),"N/A") -> 0.74087069 | G9: =IFERROR(INTERCEPT(OFFSET(D$16,MAX($B$16:$B$506)-47,0,48,1),OFFSET($K$16,MAX($B$16:$B$506)-47,0,48,1))*12,"N/A") -> -1.9109021 | H9: =IFERROR(STDEVP(OFFSET(D$16,MAX($B$16:$B$506)-47,0,48,1))*SQRT(12),"N/A") -> 13.419106 | J9: Four Year | K9: {=IFERROR((GEOMEAN(1+OFFSET(K$16,MAX($B$16:$B$506)-47,0,48,1)/100)^12-1)*100,"N/A")} -> 11.085466 | L9: =IFERROR(SLOPE(OFFSET(K$16,MAX($B$16:$B$506)-47,0,48,1),OFFSET($K$16,MAX($B$16:$B$506)-47,0,48,1)),"N/A") -> 1 | M9: =IFERROR(STDEVP(OFFSET(K$16,MAX($B$16:$B$506)-47,0,48,1))*SQRT(12),"N/A") -> 15.787972 | P9: Four Year | Q9: {=IFERROR((GEOMEAN(1+OFFSET(Q$16,MAX($B$16:$B$506)-47,0,48,1)/100)^12-1)*100,"N/A")} -> 7.5142335 | R9: =IFERROR(Q9-$K9,"N/A") -> -3.5712325 | S9: =IFERROR(SLOPE(OFFSET(Q$16,MAX($B$16:$B$506)-47,0,48,1),OFFSET($K$16,MAX($B$16:$B$506)-47,0,48,1)),"N/A") -> 0.81284932 | T9: =IFERROR(INTERCEPT(OFFSET(Q$16,MAX($B$16:$B$506)-47,0,48,1),OFFSET($K$16,MAX($B$16:$B$506)-47,0,48,1))*12,"N/A") -> -1.4322126 | U9: =IFERROR(STDEVP(OFFSET(Q$16,MAX($B$16:$B$506)-47,0,48,1))*SQRT(12),"N/A") -> 13.386429 | W9: Four Year | X9: {=IFERROR((GEOMEAN(1+OFFSET(X$16,MAX($B$16:$B$506)-47,0,48,1)/100)^12-1)*100,"N/A")} -> 3.4615128 | Y9: =IFERROR(X9-$K10,"N/A") -> -10.938723 | Z9: =IFERROR(SLOPE(OFFSET(X$16,MAX($B$16:$B$506)-47,0,48,1),OFFSET($K$16,MAX($B$16:$B$506)-47,0,48,1)),"N/A") -> 0.55345764 | AA9: =IFERROR(STDEVP(OFFSET(X$16,MAX($B$16:$B$506)-47,0,48,1))*SQRT(12),"N/A") -> 12.138203
C10: Five Year | D10: {=IFERROR((GEOMEAN(1+OFFSET(D$16,MAX($B$16:$B$506)-59,0,60,1)/100)^12-1)*100,"N/A")} -> 8.3141643 | E10: =IFERROR(D10-$K10,"N/A") -> -6.0860714 | F10: =IFERROR(SLOPE(OFFSET(D$16,MAX($B$16:$B$506)-59,0,60,1),OFFSET($K$16,MAX($B$16:$B$506)-59,0,60,1)),"N/A") -> 0.77985611 | G10: =IFERROR(INTERCEPT(OFFSET(D$16,MAX($B$16:$B$506)-59,0,60,1),OFFSET($K$16,MAX($B$16:$B$506)-59,0,60,1))*12,"N/A") -> -2.5350069 | H10: =IFERROR(STDEVP(OFFSET(D$16,MAX($B$16:$B$506)-59,0,60,1))*SQRT(12),"N/A") -> 13.298803 | J10: Five Year | K10: {=IFERROR((GEOMEAN(1+OFFSET(K$16,MAX($B$16:$B$506)-59,0,60,1)/100)^12-1)*100,"N/A")} -> 14.400236 | L10: =IFERROR(SLOPE(OFFSET(K$16,MAX($B$16:$B$506)-59,0,60,1),OFFSET($K$16,MAX($B$16:$B$506)-59,0,60,1)),"N/A") -> 1 | M10: =IFERROR(STDEVP(OFFSET(K$16,MAX($B$16:$B$506)-59,0,60,1))*SQRT(12),"N/A") -> 14.98254 | P10: Five Year | Q10: {=IFERROR((GEOMEAN(1+OFFSET(Q$16,MAX($B$16:$B$506)-59,0,60,1)/100)^12-1)*100,"N/A")} -> 11.138063 | R10: =IFERROR(Q10-$K10,"N/A") -> -3.2621723 | S10: =IFERROR(SLOPE(OFFSET(Q$16,MAX($B$16:$B$506)-59,0,60,1),OFFSET($K$16,MAX($B$16:$B$506)-59,0,60,1)),"N/A") -> 0.84847872 | T10: =IFERROR(INTERCEPT(OFFSET(Q$16,MAX($B$16:$B$506)-59,0,60,1),OFFSET($K$16,MAX($B$16:$B$506)-59,0,60,1))*12,"N/A") -> -0.93936988 | U10: =IFERROR(STDEVP(OFFSET(Q$16,MAX($B$16:$B$506)-59,0,60,1))*SQRT(12),"N/A") -> 13.30768 | W10: Five Year | X10: {=IFERROR((GEOMEAN(1+OFFSET(X$16,MAX($B$16:$B$506)-59,0,60,1)/100)^12-1)*100,"N/A")} -> 7.349583 | Y10: =IFERROR(X10-$K11,"N/A") -> -7.4537143 | Z10: =IFERROR(SLOPE(OFFSET(X$16,MAX($B$16:$B$506)-59,0,60,1),OFFSET($K$16,MAX($B$16:$B$506)-59,0,60,1)),"N/A") -> 0.61101938 | AA10: =IFERROR(STDEVP(OFFSET(X$16,MAX($B$16:$B$506)-59,0,60,1))*SQRT(12),"N/A") -> 12.625094 | AD10: =AD209/AZ209 -> 0.56806967 | AE10: =AF209/AZ209 -> 0.43193033
C11: Ten Year | D11: {=IFERROR((GEOMEAN(1+OFFSET(D$16,MAX($B$16:$B$506)-119,0,120,1)/100)^12-1)*100,"N/A")} -> 10.503037 | E11: =IFERROR(D11-$K11,"N/A") -> -4.3002605 | F11: =IFERROR(SLOPE(OFFSET(D$16,MAX($B$16:$B$506)-119,0,120,1),OFFSET($K$16,MAX($B$16:$B$506)-119,0,120,1)),"N/A") -> 0.79929338 | G11: =IFERROR(INTERCEPT(OFFSET(D$16,MAX($B$16:$B$506)-119,0,120,1),OFFSET($K$16,MAX($B$16:$B$506)-119,0,120,1))*12,"N/A") -> -1.1033388 | H11: =IFERROR(STDEVP(OFFSET(D$16,MAX($B$16:$B$506)-119,0,120,1))*SQRT(12),"N/A") -> 13.193272 | J11: Ten Year | K11: {=IFERROR((GEOMEAN(1+OFFSET(K$16,MAX($B$16:$B$506)-119,0,120,1)/100)^12-1)*100,"N/A")} -> 14.803297 | L11: =IFERROR(SLOPE(OFFSET(K$16,MAX($B$16:$B$506)-119,0,120,1),OFFSET($K$16,MAX($B$16:$B$506)-119,0,120,1)),"N/A") -> 1 | M11: =IFERROR(STDEVP(OFFSET(K$16,MAX($B$16:$B$506)-119,0,120,1))*SQRT(12),"N/A") -> 15.056111 | P11: Ten Year | Q11: {=IFERROR((GEOMEAN(1+OFFSET(Q$16,MAX($B$16:$B$506)-119,0,120,1)/100)^12-1)*100,"N/A")} -> 12.825832 | R11: =IFERROR(Q11-$K11,"N/A") -> -1.9774654 | S11: =IFERROR(SLOPE(OFFSET(Q$16,MAX($B$16:$B$506)-119,0,120,1),OFFSET($K$16,MAX($B$16:$B$506)-119,0,120,1)),"N/A") -> 0.85660272 | T11: =IFERROR(INTERCEPT(OFFSET(Q$16,MAX($B$16:$B$506)-119,0,120,1),OFFSET($K$16,MAX($B$16:$B$506)-119,0,120,1))*12,"N/A") -> 0.15423806 | U11: =IFERROR(STDEVP(OFFSET(Q$16,MAX($B$16:$B$506)-119,0,120,1))*SQRT(12),"N/A") -> 13.350051 | W11: Ten Year | X11: {=IFERROR((GEOMEAN(1+OFFSET(X$16,MAX($B$16:$B$506)-119,0,120,1)/100)^12-1)*100,"N/A")} -> 8.9173184 | Y11: =IFERROR(X11-$K12,"N/A") -> 0.85041593 | Z11: =IF(P12="N/A","N/A",IFERROR(SLOPE(OFFSET(X$16,MAX($B$16:$B$506)-119,0,120,1),OFFSET($K$16,MAX($B$16:$B$506)-119,0,120,1)),"N/A")) -> 0.6470853 | AA11: =IFERROR(STDEVP(OFFSET(X$16,MAX($B$16:$B$506)-119,0,120,1))*SQRT(12),"N/A") -> 12.473098 | AD11: =AD10*AC210 -> 1.0734499 | AE11: =AE10*AE210 -> 0.95327024 | AF11: =AD11+AE11 -> 2.0267201
C12: Model Incep. | D12: {=IFERROR((GEOMEAN(1+OFFSET(D$16,1,0,MAX($B$16:$B$506),1)/100)^12-1)*100,"N/A")} -> 11.383945 | E12: =IFERROR(D12-$K12,"N/A") -> 3.3170424 | F12: =IFERROR(SLOPE(OFFSET(D$16,1,0,MAX($B$16:$B$506),1),OFFSET($K$16,1,0,MAX($B$16:$B$506),1)),"N/A") -> 0.65286552 | G12: =IFERROR(INTERCEPT(OFFSET(D$16,1,0,MAX($B$16:$B$506),1),OFFSET($K$16,1,0,MAX($B$16:$B$506),1))*12,"N/A") -> 5.7234274 | H12: =IFERROR(STDEVP(OFFSET(D$16,1,0,MAX($B$16:$B$506),1))*SQRT(12),"N/A") -> 12.034673 | J12: Inception | K12: {=IFERROR((GEOMEAN(1+OFFSET(K$16,1,0,MAX($B$16:$B$506),1)/100)^12-1)*100,"N/A")} -> 8.0669024 | L12: =IFERROR(SLOPE(OFFSET(K$16,1,0,MAX($B$16:$B$506),1),OFFSET($K$16,1,0,MAX($B$16:$B$506),1)),"N/A") -> 1 | M12: =IFERROR(STDEVP(OFFSET(K$16,1,0,MAX($B$16:$B$506),1))*SQRT(12),"N/A") -> 15.141943 | P12: Model Incep. | Q12: {=IFERROR((GEOMEAN(1+OFFSET(Q$16,1,0,MAX($B$16:$B$506),1)/100)^12-1)*100,"N/A")} -> 7.1818795 | R12: =IFERROR(Q12-$K12,"N/A") -> -0.88502295 | S12: =IFERROR(SLOPE(OFFSET(Q$16,1,0,MAX($B$16:$B$506),1),OFFSET($K$16,1,0,MAX($B$16:$B$506),1)),"N/A") -> 0.80660002 | T12: =IFERROR(INTERCEPT(OFFSET(Q$16,1,0,MAX($B$16:$B$506),1),OFFSET($K$16,1,0,MAX($B$16:$B$506),1))*12,"N/A") -> 0.56007074 | U12: =IFERROR(STDEVP(OFFSET(Q$16,1,0,MAX($B$16:$B$506),1))*SQRT(12),"N/A") -> 12.724272 | W12: Model Incep. | X12: {=IFERROR((GEOMEAN(1+OFFSET(X$16,1,0,MAX($B$16:$B$506),1)/100)^12-1)*100,"N/A")} -> 9.3867894 | Y12: =IFERROR(X12-$K13,"N/A") -> -4.5680677 | Z12: =IFERROR(SLOPE(OFFSET(X$16,1,0,MAX($B$16:$B$506),1),OFFSET($K$16,1,0,MAX($B$16:$B$506),1)),"N/A") -> 0.58320267 | AA12: =IFERROR(STDEVP(OFFSET(X$16,1,0,MAX($B$16:$B$506),1))*SQRT(12),"N/A") -> 11.687065
C13: Feb'11 Incep. | D13: {=IFERROR((GEOMEAN(1+OFFSET(D$149,1,0,MAX($B$16:$B$506)-133,1)/100)^(MIN(COUNTA(OFFSET(D$149,1,0,MAX($B$16:$B$506)-133,1)),12))-1)*100,"N/A")} -> 11.824032 | E13: =IFERROR(D13-$K13,"N/A") -> -2.1308247 | F13: =IFERROR(SLOPE(OFFSET(D$149,1,0,MAX($B$16:$B$506)-133,1),OFFSET($K$149,1,0,MAX($B$16:$B$506)-133,1)),"N/A") -> 0.72837623 | G13: =IFERROR(INTERCEPT(OFFSET(D$149,1,0,MAX($B$16:$B$506)-133,1),OFFSET($K$149,1,0,MAX($B$16:$B$506)-133,1))*12,"N/A") -> 1.6302397 | H13: =IFERROR(STDEVP(OFFSET(D$149,1,0,MAX($B$16:$B$506)-133,1))*SQRT(12),"N/A") -> 11.703397 | J13: Feb'11 Incep. | K13: {=IFERROR((GEOMEAN(1+OFFSET(K$149,1,0,MAX($B$16:$B$506)-133,1)/100)^(MIN(COUNTA(OFFSET(K$149,1,0,MAX($B$16:$B$506)-133,1)),12))-1)*100,"N/A")} -> 13.954857 | L13: =IFERROR(SLOPE(OFFSET(K$149,1,0,MAX($B$16:$B$506)-133,1),OFFSET($K$149,1,0,MAX($B$16:$B$506)-133,1)),"N/A") -> 1 | M13: =IFERROR(STDEVP(OFFSET(K$149,1,0,MAX($B$16:$B$506)-133,1))*SQRT(12),"N/A") -> 14.03842 | P13: Feb'11 Incep. | Q13: {=IFERROR((GEOMEAN(1+OFFSET(Q$149,1,0,MAX($B$16:$B$506)-133,1)/100)^(MIN(COUNTA(OFFSET(Q$149,1,0,MAX($B$16:$B$506)-133,1)),12))-1)*100,"N/A")} -> 12.932305 | R13: =IFERROR(Q13-$K13,"N/A") -> -1.0225522 | S13: =IFERROR(SLOPE(OFFSET(Q$149,1,0,MAX($B$16:$B$506)-133,1),OFFSET($K$149,1,0,MAX($B$16:$B$506)-133,1)),"N/A") -> 0.84675574 | T13: =IFERROR(INTERCEPT(OFFSET(Q$149,1,0,MAX($B$16:$B$506)-133,1),OFFSET($K$149,1,0,MAX($B$16:$B$506)-133,1))*12,"N/A") -> 1.0242804 | U13: =IFERROR(STDEVP(OFFSET(Q$149,1,0,MAX($B$16:$B$506)-133,1))*SQRT(12),"N/A") -> 12.304197 | W13: Feb'11 Incep. | X13: {=IFERROR((GEOMEAN(1+OFFSET(X$149,1,0,MAX($B$16:$B$506)-133,1)/100)^(MIN(COUNTA(OFFSET(X$149,1,0,MAX($B$16:$B$506)-133,1)),12))-1)*100,"N/A")} -> 10.642852 | Y13: =IFERROR(X13-$K14,"N/A") -> 10.642852 | Z13: =IFERROR(SLOPE(OFFSET(X$102,1,0,MAX($B$16:$B$506)-86,1),OFFSET($K$102,1,0,MAX($B$16:$B$506)-86,1)),"N/A") -> 0.63650071 | AA13: =IFERROR(STDEVP(OFFSET(X$102,1,0,MAX($B$16:$B$506)-86,1))*SQRT(12),"N/A") -> 12.022481 | AC13: Composite Performance
AC14: SILVX | AE14: UNC LC | AG14: Asbestos | AI14: BHI Senior Living | AK14: Cynthia Simon-Skjodt | AM14: Sisters of St Benedict | AO14: French Capital Investors | AQ14: St Paul Hermitage | AS14: Tony Cercy | AU14: Leonardo Locascio | AW14: Walter Miller | AY14: Composite
A15: Date | B15: # | C15: Porfolio | D15: Net Return | E15: Growth | F15: Annual | G15: Quarterly | J15: Date | K15: Return | L15: Growth | M15: Annual | N15: Quarterly | P15: Date | Q15: Return | R15: Growth | S15: Annual | T15: Quarterly | AC15: Return | AD15: AUM | AE15: Return | AF15: AUM | AG15: Return | AH15: AUM | AI15: Return | AJ15: AUM | AK15: Return | AL15: AUM | AM15: Return | AN15: AUM | AO15: Return | AP15: AUM | AQ15: Return | AR15: AUM | AS15: Return | AT15: AUM | AU15: Return | AV15: AUM | AW15: Return | AX15: AUM | AY15: Return | AZ15: AUM
A16: 36525 | B16: 0 | E16: 1000000 | J16: =$A16 -> 36525 | L16: 1000000 | P16: =$A16 -> 36525 | R16: 1000000 | W16: =$A16 -> 36525 | Y16: 1000000
A17: 36556 | B17: =IF(A17>A16,1+B16,"-") -> 1 | C17: Model | D17: -4.22 | E17: =E16*D17/100+E16 -> 957800 | J17: =$A17 -> 36556 | K17: ='LC (Gross)'!K17 -> -5.0242437 | L17: =L16*K17/100+L16 -> 949757.56 | P17: =$A17 -> 36556 | Q17: ='LC (Gross)'!Q17 -> -3.7996474 | R17: =R16*Q17/100+R16 -> 962003.53 | W17: =$A17 -> 36556 | X17: ='LC (Gross)'!X17 -> -3.5109291 | Y17: =Y16*X17/100+Y16 -> 964890.71
A18: 36585 | B18: =IF(A18>A17,1+B17,"-") -> 2 | C18: Model | D18: -7.58 | E18: =E17*D18/100+E17 -> 885198.76 | J18: =$A18 -> 36585 | K18: ='LC (Gross)'!K18 -> -1.8937944 | L18: =L17*K18/100+L17 -> 931771.11 | P18: =$A18 -> 36585 | Q18: ='LC (Gross)'!Q18 -> -6.7517383 | R18: =R17*Q18/100+R17 -> 897051.57 | W18: =$A18 -> 36585 | X18: ='LC (Gross)'!X18 -> -10.51414 | Y18: =Y17*X18/100+Y17 -> 863440.75
A19: 36616 | B19: =IF(A19>A18,1+B18,"-") -> 3 | C19: Model | D19: 13.21 | E19: =E18*D19/100+E18 -> 1002133.5 | G19: =(E19/E16-1)*100 -> 0.21335162 | J19: =$A19 -> 36616 | K19: ='LC (Gross)'!K19 -> 9.7830709 | L19: =L18*K19/100+L18 -> 1022926.9 | N19: =(L19/L16-1)*100 -> 2.2926936 | P19: =$A19 -> 36616 | Q19: ='LC (Gross)'!Q19 -> 10.20982 | R19: =R18*Q19/100+R18 -> 988638.92 | T19: =(R19/R16-1)*100 -> -1.1361085 | W19: =$A19 -> 36616 | X19: ='LC (Gross)'!X19 -> 9.3534453 | Y19: =Y18*X19/100+Y18 -> 944202.21
A20: 36646 | B20: =IF(A20>A19,1+B19,"-") -> 4 | C20: Model | D20: 3.05 | E20: =E19*D20/100+E19 -> 1032698.6 | J20: =$A20 -> 36646 | K20: ='LC (Gross)'!K20 -> -3.0091713 | L20: =L19*K20/100+L19 -> 992145.31 | P20: =$A20 -> 36646 | Q20: ='LC (Gross)'!Q20 -> -1.0985094 | R20: =R19*Q20/100+R19 -> 977778.62 | W20: =$A20 -> 36646 | X20: ='LC (Gross)'!X20 -> 4.7344924 | Y20: =Y19*X20/100+Y19 -> 988905.39
A21: 36677 | B21: =IF(A21>A20,1+B20,"-") -> 5 | C21: Model | D21: 0.28 | E21: =E20*D21/100+E20 -> 1035590.1 | J21: =$A21 -> 36677 | K21: ='LC (Gross)'!K21 -> -2.0522676 | L21: =L20*K21/100+L20 -> 971783.84 | P21: =$A21 -> 36677 | Q21: ='LC (Gross)'!Q21 -> 1.2422987 | R21: =R20*Q21/100+R20 -> 989925.55 | W21: =$A21 -> 36677 | X21: ='LC (Gross)'!X21 -> 4.9107001 | Y21: =Y20*X21/100+Y20 -> 1037467.6
A22: 36707 | B22: =IF(A22>A21,1+B21,"-") -> 6 | C22: Model | D22: -0.53 | E22: =E21*D22/100+E21 -> 1030101.5 | G22: =(E22/E19-1)*100 -> 2.7908457 | J22: =$A22 -> 36707 | K22: ='LC (Gross)'!K22 -> 2.4652586 | L22: =L21*K22/100+L21 -> 995740.82 | N22: =(L22/L19-1)*100 -> -2.6576791 | P22: =$A22 -> 36707 | Q22: ='LC (Gross)'!Q22 -> 1.7420177 | R22: =R21*Q22/100+R21 -> 1007170.2 | T22: =(R22/R19-1)*100 -> 1.8744273 | W22: =$A22 -> 36707 | X22: ='LC (Gross)'!X22 -> -4.1760746 | Y22: =Y21*X22/100+Y21 -> 994142.15
A23: 36738 | B23: =IF(A23>A22,1+B22,"-") -> 7 | C23: Model | D23: -0.47 | E23: =E22*D23/100+E22 -> 1025260 | J23: =$A23 -> 36738 | K23: ='LC (Gross)'!K23 -> -1.5573152 | L23: =L22*K23/100+L22 -> 980234 | P23: =$A23 -> 36738 | Q23: ='LC (Gross)'!Q23 -> -1.0405934 | R23: =R22*Q23/100+R22 -> 996689.69 | W23: =$A23 -> 36738 | X23: ='LC (Gross)'!X23 -> 1.3630468 | Y23: =Y22*X23/100+Y22 -> 1007692.8
A24: 36769 | B24: =IF(A24>A23,1+B23,"-") -> 8 | C24: Model | D24: 0.2 | E24: =E23*D24/100+E23 -> 1027310.6 | J24: =$A24 -> 36769 | K24: ='LC (Gross)'!K24 -> 6.2114813 | L24: =L23*K24/100+L23 -> 1041121 | P24: =$A24 -> 36769 | Q24: ='LC (Gross)'!Q24 -> 4.1027128 | R24: =R23*Q24/100+R23 -> 1037581 | W24: =$A24 -> 36769 | X24: ='LC (Gross)'!X24 -> 7.4544539 | Y24: =Y23*X24/100+Y23 -> 1082810.8
A25: 36799 | B25: =IF(A25>A24,1+B24,"-") -> 9 | C25: Model | D25: 4.74 | E25: =E24*D25/100+E24 -> 1076005.1 | G25: =(E25/E22-1)*100 -> 4.4562174 | J25: =$A25 -> 36799 | K25: ='LC (Gross)'!K25 -> -5.2795736 | L25: =L24*K25/100+L24 -> 986154.3 | N25: =(L25/L22-1)*100 -> -0.96275291 | P25: =$A25 -> 36799 | Q25: ='LC (Gross)'!Q25 -> -2.4192023 | R25: =R24*Q25/100+R24 -> 1012479.8 | T25: =(R25/R22-1)*100 -> 0.52717843 | W25: =$A25 -> 36799 | X25: ='LC (Gross)'!X25 -> 3.158566 | Y25: =Y24*X25/100+Y24 -> 1117012.1
A26: 36830 | B26: =IF(A26>A25,1+B25,"-") -> 10 | C26: Model | D26: 1.04 | E26: =E25*D26/100+E25 -> 1087195.5 | J26: =$A26 -> 36830 | K26: ='LC (Gross)'!K26 -> -0.42330523 | L26: =L25*K26/100+L25 -> 981979.85 | P26: =$A26 -> 36830 | Q26: ='LC (Gross)'!Q26 -> 2.9561552 | R26: =R25*Q26/100+R25 -> 1042410.3 | W26: =$A26 -> 36830 | X26: ='LC (Gross)'!X26 -> 2.3517126 | Y26: =Y25*X26/100+Y25 -> 1143281
A27: 36860 | B27: =IF(A27>A26,1+B26,"-") -> 11 | C27: Model | D27: 0.83 | E27: =E26*D27/100+E26 -> 1096219.3 | J27: =$A27 -> 36860 | K27: ='LC (Gross)'!K27 -> -7.8835014 | L27: =L26*K27/100+L26 -> 904565.46 | P27: =$A27 -> 36860 | Q27: ='LC (Gross)'!Q27 -> -3.6785295 | R27: =R26*Q27/100+R26 -> 1004064.9 | W27: =$A27 -> 36860 | X27: ='LC (Gross)'!X27 -> 1.7025759 | Y27: =Y26*X27/100+Y26 -> 1162746.2
